Workbook

Sheet Grilla

Sheet Hoja2

Sheet 0-0
A1: 0 | B1: 1 | C1: 2 | D1: 3 | E1: 4 | F1: 5 | G1: 6 | H1: 7 | I1: 8 | J1: 9 | K1: 10 | L1: 11 | M1: 12
A2: * | B2: 1 | C2: 2 | D2: 3 | E2: 4 | F2: 5 | G2: 6 | H2: 7 | I2: 8 | J2: 9 | K2: 10 | L2: 11 | M2: 12
A3: A | B3: 0.109 | C3: 0.093 | D3: 0.088 | E3: 0.097 | F3: 0.134 | G3: 0.117 | H3: 0.092 | I3: 0.068 | J3: 0.054 | K3: 0.063 | L3: 0.12 | M3: 0.092
A4: B | B4: 0.129 | C4: 0.159 | D4: 0.091 | E4: 0.091 | F4: 0.152 | G4: 0.127 | H4: 0.105 | I4: 0.099 | J4: 0.064 | K4: 0.054 | L4: 0.094 | M4: 0.111
A5: C | B5: 0.132 | C5: 0.179 | D5: 0.084 | E5: 0.081 | F5: 0.103 | G5: 0.115 | H5: 0.08 | I5: 0.066 | J5: 0.094 | K5: 0.119 | L5: 0.114 | M5: 0.107
A6: D | B6: 0.165 | C6: 0.196 | D6: 0.107 | E6: 0.099 | F6: 0.127 | G6: 0.185 | H6: 0.084 | I6: 0.111 | J6: 0.083 | K6: 0.084 | L6: 0.101 | M6: 0.097
A7: E | B7: 0.128 | C7: 0.135 | D7: 0.08 | E7: 0.084 | F7: 0.109 | G7: 0.1 | H7: 0.091 | I7: 0.084 | J7: 0.068 | K7: 0.069 | L7: 0.659 | M7: 0.097
A8: F | B8: 0.108 | C8: 0.088 | D8: 0.08 | E8: 0.074 | F8: 0.096 | G8: 0.075 | H8: 0.077 | I8: 0.059 | J8: 0.05 | K8: 0.064 | L8: 0.375 | M8: 0.098
A9: G | B9: 0.143 | C9: 0.158 | D9: 0.1 | E9: 0.103 | F9: 0.113 | G9: 0.097 | H9: 0.069 | I9: 0.075 | J9: 0.116 | K9: 0.115 | L9: 0.104 | M9: 0.133
A10: H | B10: 0.2 | C10: 0.182 | D10: 0.104 | E10: 0.11 | F10: 0.199 | G10: 0.153 | H10: 0.095 | I10: 0.092 | J10: 0.096 | K10: 0.125 | L10: 0.125 | M10: 0.097

Sheet +0.0 seg
A1: 0 | B1: 1 | C1: 2 | D1: 3 | E1: 4 | F1: 5 | G1: 6 | H1: 7 | I1: 8 | J1: 9 | K1: 10 | L1: 11 | M1: 12
A2: * | B2: 1 | C2: 2 | D2: 3 | E2: 4 | F2: 5 | G2: 6 | H2: 7 | I2: 8 | J2: 9 | K2: 10 | L2: 11 | M2: 12
A3: A | B3: 0.098 | C3: 0.085 | D3: 0.073 | E3: 0.087 | F3: 0.147 | G3: 0.115 | H3: 0.083 | I3: 0.061 | J3: 0.051 | K3: 0.052 | L3: 0.12 | M3: 0.092
A4: B | B4: 0.128 | C4: 0.14 | D4: 0.076 | E4: 0.084 | F4: 0.146 | G4: 0.127 | H4: 0.091 | I4: 0.092 | J4: 0.062 | K4: 0.052 | L4: 0.094 | M4: 0.111
A5: C | B5: 0.141 | C5: 0.142 | D5: 0.08 | E5: 0.08 | F5: 0.101 | G5: 0.116 | H5: 0.075 | I5: 0.069 | J5: 0.094 | K5: 0.118 | L5: 0.114 | M5: 0.107
A6: D | B6: 0.171 | C6: 0.184 | D6: 0.082 | E6: 0.091 | F6: 0.117 | G6: 0.199 | H6: 0.068 | I6: 0.109 | J6: 0.083 | K6: 0.084 | L6: 0.101 | M6: 0.097
A7: E | B7: 0.134 | C7: 0.151 | D7: 0.08 | E7: 0.088 | F7: 0.112 | G7: 0.103 | H7: 0.094 | I7: 0.084 | J7: 0.069 | K7: 0.069 | L7: 0.643 | M7: 0.097
A8: F | B8: 0.116 | C8: 0.091 | D8: 0.079 | E8: 0.075 | F8: 0.096 | G8: 0.079 | H8: 0.076 | I8: 0.059 | J8: 0.051 | K8: 0.062 | L8: 0.369 | M8: 0.097
A9: G | B9: 0.151 | C9: 0.162 | D9: 0.1 | E9: 0.105 | F9: 0.116 | G9: 0.098 | H9: 0.07 | I9: 0.074 | J9: 0.116 | K9: 0.114 | L9: 0.104 | M9: 0.133
A10: H | B10: 0.219 | C10: 0.205 | D10: 0.105 | E10: 0.112 | F10: 0.226 | G10: 0.159 | H10: 0.097 | I10: 0.092 | J10: 0.096 | K10: 0.125 | L10: 0.125 | M10: 0.096
A14: * | B14: 1 | C14: 2 | D14: 3 | E14: 4 | F14: 5 | G14: 6 | H14: 7 | I14: 8 | J14: 9 | K14: 10 | L14: 11 | M14: 12
A15: A | B15: =B3 - B3 -> 0 | C15: =C3 - C3 -> 0 | D15: =D3 - D3 -> 0 | E15: =E3 - E3 -> 0 | F15: =F3 - F3 -> 0 | G15: =G3 - G3 -> 0 | H15: =H3 - H3 -> 0 | I15: =I3 - I3 -> 0 | ... M15: =M3 - M3 -> 0
A16: B | B16: =B4 - B4 -> 0 | C16: =C4 - C4 -> 0 | D16: =D4 - D4 -> 0 | E16: =E4 - E4 -> 0 | F16: =F4 - F4 -> 0 | G16: =G4 - G4 -> 0 | H16: =H4 - H4 -> 0 | I16: =I4 - I4 -> 0 | ... M16: =M4 - M4 -> 0
A17: C | B17: =B5 - B5 -> 0 | C17: =C5 - C5 -> 0 | D17: =D5 - D5 -> 0 | E17: =E5 - E5 -> 0 | F17: =F5 - F5 -> 0 | G17: =G5 - G5 -> 0 | H17: =H5 - H5 -> 0 | I17: =I5 - I5 -> 0 | ... M17: =M5 - M5 -> 0
A18: D | B18: =B6 - B6 -> 0 | C18: =C6 - C6 -> 0 | D18: =D6 - D6 -> 0 | E18: =E6 - E6 -> 0 | F18: =F6 - F6 -> 0 | G18: =G6 - G6 -> 0 | H18: =H6 - H6 -> 0 | I18: =I6 - I6 -> 0 | ... M18: =M6 - M6 -> 0
A19: E | B19: =B7 - B7 -> 0 | C19: =C7 - C7 -> 0 | D19: =D7 - D7 -> 0 | E19: =E7 - E7 -> 0 | F19: =F7 - F7 -> 0 | G19: =G7 - G7 -> 0 | H19: =H7 - H7 -> 0 | I19: =I7 - I7 -> 0 | ... M19: =M7 - M7 -> 0
A20: F | B20: =B8 - B8 -> 0 | C20: =C8 - C8 -> 0 | D20: =D8 - D8 -> 0 | E20: =E8 - E8 -> 0 | F20: =F8 - F8 -> 0 | G20: =G8 - G8 -> 0 | H20: =H8 - H8 -> 0 | I20: =I8 - I8 -> 0 | ... M20: =M8 - M8 -> 0
A21: G | B21: =B9 - B9 -> 0 | C21: =C9 - C9 -> 0 | D21: =D9 - D9 -> 0 | E21: =E9 - E9 -> 0 | F21: =F9 - F9 -> 0 | G21: =G9 - G9 -> 0 | H21: =H9 - H9 -> 0 | I21: =I9 - I9 -> 0 | ... M21: =M9 - M9 -> 0
A22: H | B22: =B10 - B10 -> 0 | C22: =C10 - C10 -> 0 | D22: =D10 - D10 -> 0 | E22: =E10 - E10 -> 0 | F22: =F10 - F10 -> 0 | G22: =G10 - G10 -> 0 | H22: =H10 - H10 -> 0 | I22: =I10 - I10 -> 0 | ... M22: =M10 - M10 -> 0
A25: * | B25: Mean 1-2 | C25: DE 1-2 | D25: Mean 3-4 | E25: DE 3-4 | F25: Mean 5-6 | G25: DE 5-6 | H25: Mean 7-8 | I25: DE 7-8 | J25: Mean 9-10 | K25: DE 9-10 | L25: Mean 11-12 | M25: DE 11-12
A26: A | B26: =AVERAGE(B15:C15) -> 0 | C26: =STDEV(B15:C15) -> 0 | D26: =AVERAGE(D15:E15) -> 0 | E26: =STDEV(D15:E15) -> 0 | F26: =AVERAGE(F15:G15) -> 0 | G26: =STDEV(F15:G15) -> 0 | H26: =AVERAGE(H15:I15) -> 0 | I26: =STDEV(H15:I15) -> 0 | J26: =AVERAGE(J15:K15) -> 0 | K26: =STDEV(J15:K15) -> 0 | L26: =AVERAGE(L15:M15) -> 0 | M26: =STDEV(L15:M15) -> 0
A27: B | B27: =AVERAGE(B16:C16) -> 0 | C27: =STDEV(B16:C16) -> 0 | D27: =AVERAGE(D16:E16) -> 0 | E27: =STDEV(D16:E16) -> 0 | F27: =AVERAGE(F16:G16) -> 0 | G27: =STDEV(F16:G16) -> 0 | H27: =AVERAGE(H16:I16) -> 0 | I27: =STDEV(H16:I16) -> 0 | J27: =AVERAGE(J16:K16) -> 0 | K27: =STDEV(J16:K16) -> 0 | L27: =AVERAGE(L16:M16) -> 0 | M27: =STDEV(L16:M16) -> 0
A28: C | B28: =AVERAGE(B17:C17) -> 0 | C28: =STDEV(B17:C17) -> 0 | D28: =AVERAGE(D17:E17) -> 0 | E28: =STDEV(D17:E17) -> 0 | F28: =AVERAGE(F17:G17) -> 0 | G28: =STDEV(F17:G17) -> 0 | H28: =AVERAGE(H17:I17) -> 0 | I28: =STDEV(H17:I17) -> 0 | J28: =AVERAGE(J17:K17) -> 0 | K28: =STDEV(J17:K17) -> 0 | L28: =AVERAGE(L17:M17) -> 0 | M28: =STDEV(L17:M17) -> 0
A29: D | B29: =AVERAGE(B18:C18) -> 0 | C29: =STDEV(B18:C18) -> 0 | D29: =AVERAGE(D18:E18) -> 0 | E29: =STDEV(D18:E18) -> 0 | F29: =AVERAGE(F18:G18) -> 0 | G29: =STDEV(F18:G18) -> 0 | H29: =AVERAGE(H18:I18) -> 0 | I29: =STDEV(H18:I18) -> 0 | J29: =AVERAGE(J18:K18) -> 0 | K29: =STDEV(J18:K18) -> 0 | L29: =AVERAGE(L18:M18) -> 0 | M29: =STDEV(L18:M18) -> 0
A30: E | B30: =AVERAGE(B19:C19) -> 0 | C30: =STDEV(B19:C19) -> 0 | D30: =AVERAGE(D19:E19) -> 0 | E30: =STDEV(D19:E19) -> 0 | F30: =AVERAGE(F19:G19) -> 0 | G30: =STDEV(F19:G19) -> 0 | H30: =AVERAGE(H19:I19) -> 0 | I30: =STDEV(H19:I19) -> 0 | J30: =AVERAGE(J19:K19) -> 0 | K30: =STDEV(J19:K19) -> 0 | L30: =AVERAGE(L19:M19) -> 0 | M30: =STDEV(L19:M19) -> 0
A31: F | B31: =AVERAGE(B20:C20) -> 0 | C31: =STDEV(B20:C20) -> 0 | D31: =AVERAGE(D20:E20) -> 0 | E31: =STDEV(D20:E20) -> 0 | F31: =AVERAGE(F20:G20) -> 0 | G31: =STDEV(F20:G20) -> 0 | H31: =AVERAGE(H20:I20) -> 0 | I31: =STDEV(H20:I20) -> 0 | J31: =AVERAGE(J20:K20) -> 0 | K31: =STDEV(J20:K20) -> 0 | L31: =AVERAGE(L20:M20) -> 0 | M31: =STDEV(L20:M20) -> 0
A32: G | B32: =AVERAGE(B21:C21) -> 0 | C32: =STDEV(B21:C21) -> 0 | D32: =AVERAGE(D21:E21) -> 0 | E32: =STDEV(D21:E21) -> 0 | F32: =AVERAGE(F21:G21) -> 0 | G32: =STDEV(F21:G21) -> 0 | H32: =AVERAGE(H21:I21) -> 0 | I32: =STDEV(H21:I21) -> 0 | J32: =AVERAGE(J21:K21) -> 0 | K32: =STDEV(J21:K21) -> 0 | L32: =AVERAGE(L21:M21) -> 0 | M32: =STDEV(L21:M21) -> 0
A33: H | B33: =AVERAGE(B22:C22) -> 0 | C33: =STDEV(B22:C22) -> 0 | D33: =AVERAGE(D22:E22) -> 0 | E33: =STDEV(D22:E22) -> 0 | F33: =AVERAGE(F22:G22) -> 0 | G33: =STDEV(F22:G22) -> 0 | H33: =AVERAGE(H22:I22) -> 0 | I33: =STDEV(H22:I22) -> 0 | J33: =AVERAGE(J22:K22) -> 0 | K33: =STDEV(J22:K22) -> 0 | L33: =AVERAGE(L22:M22) -> 0 | M33: =STDEV(L22:M22) -> 0

Sheet +23.0 seg
A1: 0 | B1: 1 | C1: 2 | D1: 3 | E1: 4 | F1: 5 | G1: 6 | H1: 7 | I1: 8 | J1: 9 | K1: 10 | L1: 11 | M1: 12
A2: * | B2: 1 | C2: 2 | D2: 3 | E2: 4 | F2: 5 | G2: 6 | H2: 7 | I2: 8 | J2: 9 | K2: 10 | L2: 11 | M2: 12
A3: A | B3: 0.099 | C3: 0.085 | D3: 0.074 | E3: 0.085 | F3: 0.146 | G3: 0.115 | H3: 0.082 | I3: 0.06 | J3: 0.05 | K3: 0.05 | L3: 0.12 | M3: 0.092
A4: B | B4: 0.128 | C4: 0.14 | D4: 0.078 | E4: 0.091 | F4: 0.148 | G4: 0.129 | H4: 0.092 | I4: 0.094 | J4: 0.062 | K4: 0.052 | L4: 0.093 | M4: 0.111
A5: C | B5: 0.141 | C5: 0.144 | D5: 0.082 | E5: 0.079 | F5: 0.101 | G5: 0.113 | H5: 0.076 | I5: 0.067 | J5: 0.094 | K5: 0.118 | L5: 0.114 | M5: 0.107
A6: D | B6: 0.172 | C6: 0.185 | D6: 0.083 | E6: 0.091 | F6: 0.118 | G6: 0.203 | H6: 0.071 | I6: 0.107 | J6: 0.084 | K6: 0.084 | L6: 0.101 | M6: 0.097
A7: E | B7: 0.136 | C7: 0.148 | D7: 0.081 | E7: 0.088 | F7: 0.113 | G7: 0.105 | H7: 0.094 | I7: 0.083 | J7: 0.069 | K7: 0.069 | L7: 0.649 | M7: 0.097
A8: F | B8: 0.121 | C8: 0.089 | D8: 0.078 | E8: 0.075 | F8: 0.098 | G8: 0.079 | H8: 0.076 | I8: 0.059 | J8: 0.05 | K8: 0.062 | L8: 0.37 | M8: 0.098
A9: G | B9: 0.153 | C9: 0.163 | D9: 0.101 | E9: 0.106 | F9: 0.117 | G9: 0.099 | H9: 0.07 | I9: 0.074 | J9: 0.116 | K9: 0.115 | L9: 0.104 | M9: 0.133
A10: H | B10: 0.221 | C10: 0.218 | D10: 0.105 | E10: 0.111 | F10: 0.231 | G10: 0.159 | H10: 0.097 | I10: 0.092 | J10: 0.096 | K10: 0.125 | L10: 0.125 | M10: 0.096
A14: * | B14: 1 | C14: 2 | D14: 3 | E14: 4 | F14: 5 | G14: 6 | H14: 7 | I14: 8 | J14: 9 | K14: 10 | L14: 11 | M14: 12
A15: A | B15: =B3 - '+0.0 seg'!$B$3 -> 0.001 | C15: =C3 - '+0.0 seg'!$C$3 -> 0 | D15: =D3 - '+0.0 seg'!$D$3 -> 0.001 | E15: =E3 - '+0.0 seg'!$E$3 -> -0.002 | F15: =F3 - '+0.0 seg'!$F$3 -> -0.001 | G15: =G3 - '+0.0 seg'!$G$3 -> 0 | H15: =H3 - '+0.0 seg'!$H$3 -> -0.001 | I15: =I3 - '+0.0 seg'!$I$3 -> -0.001 | J15: =J3 - '+0.0 seg'!$J$3 -> -0.001 | K15: =K3 - '+0.0 seg'!$K$3 -> -0.002 | L15: =L3 - '+0.0 seg'!$L$3 -> 0 | M15: =M3 - '+0.0 seg'!$M$3 -> 0
A16: B | B16: =B4 - '+0.0 seg'!$B$4 -> 0 | C16: =C4 - '+0.0 seg'!$C$4 -> 0 | D16: =D4 - '+0.0 seg'!$D$4 -> 0.002 | E16: =E4 - '+0.0 seg'!$E$4 -> 0.007 | F16: =F4 - '+0.0 seg'!$F$4 -> 0.002 | G16: =G4 - '+0.0 seg'!$G$4 -> 0.002 | H16: =H4 - '+0.0 seg'!$H$4 -> 0.001 | I16: =I4 - '+0.0 seg'!$I$4 -> 0.002 | J16: =J4 - '+0.0 seg'!$J$4 -> 0 | K16: =K4 - '+0.0 seg'!$K$4 -> 0 | L16: =L4 - '+0.0 seg'!$L$4 -> -0.001 | M16: =M4 - '+0.0 seg'!$M$4 -> 0
A17: C | B17: =B5 - '+0.0 seg'!$B$5 -> 0 | C17: =C5 - '+0.0 seg'!$C$5 -> 0.002 | D17: =D5 - '+0.0 seg'!$D$5 -> 0.002 | E17: =E5 - '+0.0 seg'!$E$5 -> -0.001 | F17: =F5 - '+0.0 seg'!$F$5 -> 0 | G17: =G5 - '+0.0 seg'!$G$5 -> -0.003 | H17: =H5 - '+0.0 seg'!$H$5 -> 0.001 | I17: =I5 - '+0.0 seg'!$I$5 -> -0.002 | J17: =J5 - '+0.0 seg'!$J$5 -> 0 | K17: =K5 - '+0.0 seg'!$K$5 -> 0 | L17: =L5 - '+0.0 seg'!$L$5 -> 0 | M17: =M5 - '+0.0 seg'!$M$5 -> 0
A18: D | B18: =B6 - '+0.0 seg'!$B$6 -> 0.001 | C18: =C6 - '+0.0 seg'!$C$6 -> 0.001 | D18: =D6 - '+0.0 seg'!$D$6 -> 0.001 | E18: =E6 - '+0.0 seg'!$E$6 -> 0 | F18: =F6 - '+0.0 seg'!$F$6 -> 0.001 | G18: =G6 - '+0.0 seg'!$G$6 -> 0.004 | H18: =H6 - '+0.0 seg'!$H$6 -> 0.003 | I18: =I6 - '+0.0 seg'!$I$6 -> -0.002 | J18: =J6 - '+0.0 seg'!$J$6 -> 0.001 | K18: =K6 - '+0.0 seg'!$K$6 -> 0 | L18: =L6 - '+0.0 seg'!$L$6 -> 0 | M18: =M6 - '+0.0 seg'!$M$6 -> 0
A19: E | B19: =B7 - '+0.0 seg'!$B$7 -> 0.002 | C19: =C7 - '+0.0 seg'!$C$7 -> -0.003 | D19: =D7 - '+0.0 seg'!$D$7 -> 0.001 | E19: =E7 - '+0.0 seg'!$E$7 -> 0 | F19: =F7 - '+0.0 seg'!$F$7 -> 0.001 | G19: =G7 - '+0.0 seg'!$G$7 -> 0.002 | H19: =H7 - '+0.0 seg'!$H$7 -> 0 | I19: =I7 - '+0.0 seg'!$I$7 -> -0.001 | J19: =J7 - '+0.0 seg'!$J$7 -> 0 | K19: =K7 - '+0.0 seg'!$K$7 -> 0 | L19: =L7 - '+0.0 seg'!$L$7 -> 0.006 | M19: =M7 - '+0.0 seg'!$M$7 -> 0
A20: F | B20: =B8 - '+0.0 seg'!$B$8 -> 0.005 | C20: =C8 - '+0.0 seg'!$C$8 -> -0.002 | D20: =D8 - '+0.0 seg'!$D$8 -> -0.001 | E20: =E8 - '+0.0 seg'!$E$8 -> 0 | F20: =F8 - '+0.0 seg'!$F$8 -> 0.002 | G20: =G8 - '+0.0 seg'!$G$8 -> 0 | H20: =H8 - '+0.0 seg'!$H$8 -> 0 | I20: =I8 - '+0.0 seg'!$I$8 -> 0 | J20: =J8 - '+0.0 seg'!$J$8 -> -0.001 | K20: =K8 - '+0.0 seg'!$K$8 -> 0 | L20: =L8 - '+0.0 seg'!$L$8 -> 0.001 | M20: =M8 - '+0.0 seg'!$M$8 -> 0.001
A21: G | B21: =B9 - '+0.0 seg'!$B$9 -> 0.002 | C21: =C9 - '+0.0 seg'!$C$9 -> 0.001 | D21: =D9 - '+0.0 seg'!$D$9 -> 0.001 | E21: =E9 - '+0.0 seg'!$E$9 -> 0.001 | F21: =F9 - '+0.0 seg'!$F$9 -> 0.001 | G21: =G9 - '+0.0 seg'!$G$9 -> 0.001 | H21: =H9 - '+0.0 seg'!$H$9 -> 0 | I21: =I9 - '+0.0 seg'!$I$9 -> 0 | J21: =J9 - '+0.0 seg'!$J$9 -> 0 | K21: =K9 - '+0.0 seg'!$K$9 -> 0.001 | L21: =L9 - '+0.0 seg'!$L$9 -> 0 | M21: =M9 - '+0.0 seg'!$M$9 -> 0
A22: H | B22: =B10 - '+0.0 seg'!$B$10 -> 0.002 | C22: =C10 - '+0.0 seg'!$C$10 -> 0.013 | D22: =D10 - '+0.0 seg'!$D$10 -> 0 | E22: =E10 - '+0.0 seg'!$E$10 -> -0.001 | F22: =F10 - '+0.0 seg'!$F$10 -> 0.005 | G22: =G10 - '+0.0 seg'!$G$10 -> 0 | H22: =H10 - '+0.0 seg'!$H$10 -> 0 | I22: =I10 - '+0.0 seg'!$I$10 -> 0 | J22: =J10 - '+0.0 seg'!$J$10 -> 0 | K22: =K10 - '+0.0 seg'!$K$10 -> 0 | L22: =L10 - '+0.0 seg'!$L$10 -> 0 | M22: =M10 - '+0.0 seg'!$M$10 -> 0
A25: * | B25: Mean 1-2 | C25: DE 1-2 | D25: Mean 3-4 | E25: DE 3-4 | F25: Mean 5-6 | G25: DE 5-6 | H25: Mean 7-8 | I25: DE 7-8 | J25: Mean 9-10 | K25: DE 9-10 | L25: Mean 11-12 | M25: DE 11-12
A26: A | B26: =AVERAGE(B15:C15) -> 0.0005 | C26: =STDEV(B15:C15) -> 0.00070710678 | D26: =AVERAGE(D15:E15) -> -0.0005 | E26: =STDEV(D15:E15) -> 0.0021213203 | F26: =AVERAGE(F15:G15) -> -0.0005 | G26: =STDEV(F15:G15) -> 0.00070710678 | H26: =AVERAGE(H15:I15) -> -0.001 | I26: =STDEV(H15:I15) -> 0 | J26: =AVERAGE(J15:K15) -> -0.0015 | K26: =STDEV(J15:K15) -> 0.00070710678 | L26: =AVERAGE(L15:M15) -> 0 | M26: =STDEV(L15:M15) -> 0
A27: B | B27: =AVERAGE(B16:C16) -> 0 | C27: =STDEV(B16:C16) -> 0 | D27: =AVERAGE(D16:E16) -> 0.0045 | E27: =STDEV(D16:E16) -> 0.0035355339 | F27: =AVERAGE(F16:G16) -> 0.002 | G27: =STDEV(F16:G16) -> 0 | H27: =AVERAGE(H16:I16) -> 0.0015 | I27: =STDEV(H16:I16) -> 0.00070710678 | J27: =AVERAGE(J16:K16) -> 0 | K27: =STDEV(J16:K16) -> 0 | L27: =AVERAGE(L16:M16) -> -0.0005 | M27: =STDEV(L16:M16) -> 0.00070710678
A28: C | B28: =AVERAGE(B17:C17) -> 0.001 | C28: =STDEV(B17:C17) -> 0.0014142136 | D28: =AVERAGE(D17:E17) -> 0.0005 | E28: =STDEV(D17:E17) -> 0.0021213203 | F28: =AVERAGE(F17:G17) -> -0.0015 | G28: =STDEV(F17:G17) -> 0.0021213203 | H28: =AVERAGE(H17:I17) -> -0.0005 | I28: =STDEV(H17:I17) -> 0.0021213203 | J28: =AVERAGE(J17:K17) -> 0 | K28: =STDEV(J17:K17) -> 0 | L28: =AVERAGE(L17:M17) -> 0 | M28: =STDEV(L17:M17) -> 0
A29: D | B29: =AVERAGE(B18:C18) -> 0.001 | C29: =STDEV(B18:C18) -> 1.9626156e-17 | D29: =AVERAGE(D18:E18) -> 0.0005 | E29: =STDEV(D18:E18) -> 0.00070710678 | F29: =AVERAGE(F18:G18) -> 0.0025 | G29: =STDEV(F18:G18) -> 0.0021213203 | H29: =AVERAGE(H18:I18) -> 0.0005 | I29: =STDEV(H18:I18) -> 0.0035355339 | J29: =AVERAGE(J18:K18) -> 0.0005 | K29: =STDEV(J18:K18) -> 0.00070710678 | L29: =AVERAGE(L18:M18) -> 0 | M29: =STDEV(L18:M18) -> 0
A30: E | B30: =AVERAGE(B19:C19) -> -0.0005 | C30: =STDEV(B19:C19) -> 0.0035355339 | D30: =AVERAGE(D19:E19) -> 0.0005 | E30: =STDEV(D19:E19) -> 0.00070710678 | F30: =AVERAGE(F19:G19) -> 0.0015 | G30: =STDEV(F19:G19) -> 0.00070710678 | H30: =AVERAGE(H19:I19) -> -0.0005 | I30: =STDEV(H19:I19) -> 0.00070710678 | J30: =AVERAGE(J19:K19) -> 0 | K30: =STDEV(J19:K19) -> 0 | L30: =AVERAGE(L19:M19) -> 0.003 | M30: =STDEV(L19:M19) -> 0.0042426407
A31: F | B31: =AVERAGE(B20:C20) -> 0.0015 | C31: =STDEV(B20:C20) -> 0.0049497475 | D31: =AVERAGE(D20:E20) -> -0.0005 | E31: =STDEV(D20:E20) -> 0.00070710678 | F31: =AVERAGE(F20:G20) -> 0.001 | G31: =STDEV(F20:G20) -> 0.0014142136 | H31: =AVERAGE(H20:I20) -> 0 | I31: =STDEV(H20:I20) -> 0 | J31: =AVERAGE(J20:K20) -> -0.0005 | K31: =STDEV(J20:K20) -> 0.00070710678 | L31: =AVERAGE(L20:M20) -> 0.001 | M31: =STDEV(L20:M20) -> 0
A32: G | B32: =AVERAGE(B21:C21) -> 0.0015 | C32: =STDEV(B21:C21) -> 0.00070710678 | D32: =AVERAGE(D21:E21) -> 0.001 | E32: =STDEV(D21:E21) -> 0 | F32: =AVERAGE(F21:G21) -> 0.001 | G32: =STDEV(F21:G21) -> 0 | H32: =AVERAGE(H21:I21) -> 0 | I32: =STDEV(H21:I21) -> 0 | J32: =AVERAGE(J21:K21) -> 0.0005 | K32: =STDEV(J21:K21) -> 0.00070710678 | L32: =AVERAGE(L21:M21) -> 0 | M32: =STDEV(L21:M21) -> 0
A33: H | B33: =AVERAGE(B22:C22) -> 0.0075 | C33: =STDEV(B22:C22) -> 0.0077781746 | D33: =AVERAGE(D22:E22) -> -0.0005 | E33: =STDEV(D22:E22) -> 0.00070710678 | F33: =AVERAGE(F22:G22) -> 0.0025 | G33: =STDEV(F22:G22) -> 0.0035355339 | H33: =AVERAGE(H22:I22) -> 0 | I33: =STDEV(H22:I22) -> 0 | J33: =AVERAGE(J22:K22) -> 0 | K33: =STDEV(J22:K22) -> 0 | L33: =AVERAGE(L22:M22) -> 0 | M33: =STDEV(L22:M22) -> 0

Sheet +42.0 seg
A1: 0 | B1: 1 | C1: 2 | D1: 3 | E1: 4 | F1: 5 | G1: 6 | H1: 7 | I1: 8 | J1: 9 | K1: 10 | L1: 11 | M1: 12
A2: * | B2: 1 | C2: 2 | D2: 3 | E2: 4 | F2: 5 | G2: 6 | H2: 7 | I2: 8 | J2: 9 | K2: 10 | L2: 11 | M2: 12
A3: A | B3: 0.099 | C3: 0.085 | D3: 0.075 | E3: 0.09 | F3: 0.142 | G3: 0.116 | H3: 0.082 | I3: 0.061 | J3: 0.05 | K3: 0.048 | L3: 0.12 | M3: 0.092
A4: B | B4: 0.128 | C4: 0.14 | D4: 0.079 | E4: 0.092 | F4: 0.148 | G4: 0.128 | H4: 0.094 | I4: 0.095 | J4: 0.062 | K4: 0.052 | L4: 0.093 | M4: 0.111
A5: C | B5: 0.141 | C5: 0.144 | D5: 0.082 | E5: 0.08 | F5: 0.101 | G5: 0.112 | H5: 0.077 | I5: 0.066 | J5: 0.094 | K5: 0.118 | L5: 0.114 | M5: 0.107
A6: D | B6: 0.173 | C6: 0.185 | D6: 0.083 | E6: 0.091 | F6: 0.118 | G6: 0.204 | H6: 0.07 | I6: 0.108 | J6: 0.083 | K6: 0.084 | L6: 0.101 | M6: 0.097
A7: E | B7: 0.136 | C7: 0.149 | D7: 0.081 | E7: 0.089 | F7: 0.114 | G7: 0.106 | H7: 0.097 | I7: 0.082 | J7: 0.069 | K7: 0.069 | L7: 0.649 | M7: 0.097
A8: F | B8: 0.123 | C8: 0.091 | D8: 0.078 | E8: 0.075 | F8: 0.098 | G8: 0.08 | H8: 0.078 | I8: 0.058 | J8: 0.05 | K8: 0.061 | L8: 0.37 | M8: 0.098
A9: G | B9: 0.152 | C9: 0.164 | D9: 0.101 | E9: 0.106 | F9: 0.117 | G9: 0.101 | H9: 0.07 | I9: 0.074 | J9: 0.116 | K9: 0.115 | L9: 0.104 | M9: 0.133
A10: H | B10: 0.21 | C10: 0.226 | D10: 0.105 | E10: 0.111 | F10: 0.234 | G10: 0.16 | H10: 0.097 | I10: 0.092 | J10: 0.096 | K10: 0.125 | L10: 0.125 | M10: 0.096
A14: * | B14: 1 | C14: 2 | D14: 3 | E14: 4 | F14: 5 | G14: 6 | H14: 7 | I14: 8 | J14: 9 | K14: 10 | L14: 11 | M14: 12
A15: A | B15: =B3 - '+0.0 seg'!$B$3 -> 0.001 | C15: =C3 - '+0.0 seg'!$C$3 -> 0 | D15: =D3 - '+0.0 seg'!$D$3 -> 0.002 | E15: =E3 - '+0.0 seg'!$E$3 -> 0.003 | F15: =F3 - '+0.0 seg'!$F$3 -> -0.005 | G15: =G3 - '+0.0 seg'!$G$3 -> 0.001 | H15: =H3 - '+0.0 seg'!$H$3 -> -0.001 | I15: =I3 - '+0.0 seg'!$I$3 -> 0 | J15: =J3 - '+0.0 seg'!$J$3 -> -0.001 | K15: =K3 - '+0.0 seg'!$K$3 -> -0.004 | L15: =L3 - '+0.0 seg'!$L$3 -> 0 | M15: =M3 - '+0.0 seg'!$M$3 -> 0
A16: B | B16: =B4 - '+0.0 seg'!$B$4 -> 0 | C16: =C4 - '+0.0 seg'!$C$4 -> 0 | D16: =D4 - '+0.0 seg'!$D$4 -> 0.003 | E16: =E4 - '+0.0 seg'!$E$4 -> 0.008 | F16: =F4 - '+0.0 seg'!$F$4 -> 0.002 | G16: =G4 - '+0.0 seg'!$G$4 -> 0.001 | H16: =H4 - '+0.0 seg'!$H$4 -> 0.003 | I16: =I4 - '+0.0 seg'!$I$4 -> 0.003 | J16: =J4 - '+0.0 seg'!$J$4 -> 0 | K16: =K4 - '+0.0 seg'!$K$4 -> 0 | L16: =L4 - '+0.0 seg'!$L$4 -> -0.001 | M16: =M4 - '+0.0 seg'!$M$4 -> 0
A17: C | B17: =B5 - '+0.0 seg'!$B$5 -> 0 | C17: =C5 - '+0.0 seg'!$C$5 -> 0.002 | D17: =D5 - '+0.0 seg'!$D$5 -> 0.002 | E17: =E5 - '+0.0 seg'!$E$5 -> 0 | F17: =F5 - '+0.0 seg'!$F$5 -> 0 | G17: =G5 - '+0.0 seg'!$G$5 -> -0.004 | H17: =H5 - '+0.0 seg'!$H$5 -> 0.002 | I17: =I5 - '+0.0 seg'!$I$5 -> -0.003 | J17: =J5 - '+0.0 seg'!$J$5 -> 0 | K17: =K5 - '+0.0 seg'!$K$5 -> 0 | L17: =L5 - '+0.0 seg'!$L$5 -> 0 | M17: =M5 - '+0.0 seg'!$M$5 -> 0
A18: D | B18: =B6 - '+0.0 seg'!$B$6 -> 0.002 | C18: =C6 - '+0.0 seg'!$C$6 -> 0.001 | D18: =D6 - '+0.0 seg'!$D$6 -> 0.001 | E18: =E6 - '+0.0 seg'!$E$6 -> 0 | F18: =F6 - '+0.0 seg'!$F$6 -> 0.001 | G18: =G6 - '+0.0 seg'!$G$6 -> 0.005 | H18: =H6 - '+0.0 seg'!$H$6 -> 0.002 | I18: =I6 - '+0.0 seg'!$I$6 -> -0.001 | J18: =J6 - '+0.0 seg'!$J$6 -> 0 | K18: =K6 - '+0.0 seg'!$K$6 -> 0 | L18: =L6 - '+0.0 seg'!$L$6 -> 0 | M18: =M6 - '+0.0 seg'!$M$6 -> 0
A19: E | B19: =B7 - '+0.0 seg'!$B$7 -> 0.002 | C19: =C7 - '+0.0 seg'!$C$7 -> -0.002 | D19: =D7 - '+0.0 seg'!$D$7 -> 0.001 | E19: =E7 - '+0.0 seg'!$E$7 -> 0.001 | F19: =F7 - '+0.0 seg'!$F$7 -> 0.002 | G19: =G7 - '+0.0 seg'!$G$7 -> 0.003 | H19: =H7 - '+0.0 seg'!$H$7 -> 0.003 | I19: =I7 - '+0.0 seg'!$I$7 -> -0.002 | J19: =J7 - '+0.0 seg'!$J$7 -> 0 | K19: =K7 - '+0.0 seg'!$K$7 -> 0 | L19: =L7 - '+0.0 seg'!$L$7 -> 0.006 | M19: =M7 - '+0.0 seg'!$M$7 -> 0
A20: F | B20: =B8 - '+0.0 seg'!$B$8 -> 0.007 | C20: =C8 - '+0.0 seg'!$C$8 -> 0 | D20: =D8 - '+0.0 seg'!$D$8 -> -0.001 | E20: =E8 - '+0.0 seg'!$E$8 -> 0 | F20: =F8 - '+0.0 seg'!$F$8 -> 0.002 | G20: =G8 - '+0.0 seg'!$G$8 -> 0.001 | H20: =H8 - '+0.0 seg'!$H$8 -> 0.002 | I20: =I8 - '+0.0 seg'!$I$8 -> -0.001 | J20: =J8 - '+0.0 seg'!$J$8 -> -0.001 | K20: =K8 - '+0.0 seg'!$K$8 -> -0.001 | L20: =L8 - '+0.0 seg'!$L$8 -> 0.001 | M20: =M8 - '+0.0 seg'!$M$8 -> 0.001
A21: G | B21: =B9 - '+0.0 seg'!$B$9 -> 0.001 | C21: =C9 - '+0.0 seg'!$C$9 -> 0.002 | D21: =D9 - '+0.0 seg'!$D$9 -> 0.001 | E21: =E9 - '+0.0 seg'!$E$9 -> 0.001 | F21: =F9 - '+0.0 seg'!$F$9 -> 0.001 | G21: =G9 - '+0.0 seg'!$G$9 -> 0.003 | H21: =H9 - '+0.0 seg'!$H$9 -> 0 | I21: =I9 - '+0.0 seg'!$I$9 -> 0 | J21: =J9 - '+0.0 seg'!$J$9 -> 0 | K21: =K9 - '+0.0 seg'!$K$9 -> 0.001 | L21: =L9 - '+0.0 seg'!$L$9 -> 0 | M21: =M9 - '+0.0 seg'!$M$9 -> 0
A22: H | B22: =B10 - '+0.0 seg'!$B$10 -> -0.009 | C22: =C10 - '+0.0 seg'!$C$10 -> 0.021 | D22: =D10 - '+0.0 seg'!$D$10 -> 0 | E22: =E10 - '+0.0 seg'!$E$10 -> -0.001 | F22: =F10 - '+0.0 seg'!$F$10 -> 0.008 | G22: =G10 - '+0.0 seg'!$G$10 -> 0.001 | H22: =H10 - '+0.0 seg'!$H$10 -> 0 | I22: =I10 - '+0.0 seg'!$I$10 -> 0 | J22: =J10 - '+0.0 seg'!$J$10 -> 0 | K22: =K10 - '+0.0 seg'!$K$10 -> 0 | L22: =L10 - '+0.0 seg'!$L$10 -> 0 | M22: =M10 - '+0.0 seg'!$M$10 -> 0
A25: * | B25: Mean 1-2 | C25: DE 1-2 | D25: Mean 3-4 | E25: DE 3-4 | F25: Mean 5-6 | G25: DE 5-6 | H25: Mean 7-8 | I25: DE 7-8 | J25: Mean 9-10 | K25: DE 9-10 | L25: Mean 11-12 | M25: DE 11-12
A26: A | B26: =AVERAGE(B15:C15) -> 0.0005 | C26: =STDEV(B15:C15) -> 0.00070710678 | D26: =AVERAGE(D15:E15) -> 0.0025 | E26: =STDEV(D15:E15) -> 0.00070710678 | F26: =AVERAGE(F15:G15) -> -0.002 | G26: =STDEV(F15:G15) -> 0.0042426407 | H26: =AVERAGE(H15:I15) -> -0.0005 | I26: =STDEV(H15:I15) -> 0.00070710678 | J26: =AVERAGE(J15:K15) -> -0.0025 | K26: =STDEV(J15:K15) -> 0.0021213203 | L26: =AVERAGE(L15:M15) -> 0 | M26: =STDEV(L15:M15) -> 0
A27: B | B27: =AVERAGE(B16:C16) -> 0 | C27: =STDEV(B16:C16) -> 0 | D27: =AVERAGE(D16:E16) -> 0.0055 | E27: =STDEV(D16:E16) -> 0.0035355339 | F27: =AVERAGE(F16:G16) -> 0.0015 | G27: =STDEV(F16:G16) -> 0.00070710678 | H27: =AVERAGE(H16:I16) -> 0.003 | I27: =STDEV(H16:I16) -> 0 | J27: =AVERAGE(J16:K16) -> 0 | K27: =STDEV(J16:K16) -> 0 | L27: =AVERAGE(L16:M16) -> -0.0005 | M27: =STDEV(L16:M16) -> 0.00070710678
A28: C | B28: =AVERAGE(B17:C17) -> 0.001 | C28: =STDEV(B17:C17) -> 0.0014142136 | D28: =AVERAGE(D17:E17) -> 0.001 | E28: =STDEV(D17:E17) -> 0.0014142136 | F28: =AVERAGE(F17:G17) -> -0.002 | G28: =STDEV(F17:G17) -> 0.0028284271 | H28: =AVERAGE(H17:I17) -> -0.0005 | I28: =STDEV(H17:I17) -> 0.0035355339 | J28: =AVERAGE(J17:K17) -> 0 | K28: =STDEV(J17:K17) -> 0 | L28: =AVERAGE(L17:M17) -> 0 | M28: =STDEV(L17:M17) -> 0
A29: D | B29: =AVERAGE(B18:C18) -> 0.0015 | C29: =STDEV(B18:C18) -> 0.00070710678 | D29: =AVERAGE(D18:E18) -> 0.0005 | E29: =STDEV(D18:E18) -> 0.00070710678 | F29: =AVERAGE(F18:G18) -> 0.003 | G29: =STDEV(F18:G18) -> 0.0028284271 | H29: =AVERAGE(H18:I18) -> 0.0005 | I29: =STDEV(H18:I18) -> 0.0021213203 | J29: =AVERAGE(J18:K18) -> 0 | K29: =STDEV(J18:K18) -> 0 | L29: =AVERAGE(L18:M18) -> 0 | M29: =STDEV(L18:M18) -> 0
A30: E | B30: =AVERAGE(B19:C19) -> 0 | C30: =STDEV(B19:C19) -> 0.0028284271 | D30: =AVERAGE(D19:E19) -> 0.001 | E30: =STDEV(D19:E19) -> 0 | F30: =AVERAGE(F19:G19) -> 0.0025 | G30: =STDEV(F19:G19) -> 0.00070710678 | H30: =AVERAGE(H19:I19) -> 0.0005 | I30: =STDEV(H19:I19) -> 0.0035355339 | J30: =AVERAGE(J19:K19) -> 0 | K30: =STDEV(J19:K19) -> 0 | L30: =AVERAGE(L19:M19) -> 0.003 | M30: =STDEV(L19:M19) -> 0.0042426407
A31: F | B31: =AVERAGE(B20:C20) -> 0.0035 | C31: =STDEV(B20:C20) -> 0.0049497475 | D31: =AVERAGE(D20:E20) -> -0.0005 | E31: =STDEV(D20:E20) -> 0.00070710678 | F31: =AVERAGE(F20:G20) -> 0.0015 | G31: =STDEV(F20:G20) -> 0.00070710678 | H31: =AVERAGE(H20:I20) -> 0.0005 | I31: =STDEV(H20:I20) -> 0.0021213203 | J31: =AVERAGE(J20:K20) -> -0.001 | K31: =STDEV(J20:K20) -> 4.9065389e-18 | L31: =AVERAGE(L20:M20) -> 0.001 | M31: =STDEV(L20:M20) -> 0
A32: G | B32: =AVERAGE(B21:C21) -> 0.0015 | C32: =STDEV(B21:C21) -> 0.00070710678 | D32: =AVERAGE(D21:E21) -> 0.001 | E32: =STDEV(D21:E21) -> 0 | F32: =AVERAGE(F21:G21) -> 0.002 | G32: =STDEV(F21:G21) -> 0.0014142136 | H32: =AVERAGE(H21:I21) -> 0 | I32: =STDEV(H21:I21) -> 0 | J32: =AVERAGE(J21:K21) -> 0.0005 | K32: =STDEV(J21:K21) -> 0.00070710678 | L32: =AVERAGE(L21:M21) -> 0 | M32: =STDEV(L21:M21) -> 0
A33: H | B33: =AVERAGE(B22:C22) -> 0.006 | C33: =STDEV(B22:C22) -> 0.021213203 | D33: =AVERAGE(D22:E22) -> -0.0005 | E33: =STDEV(D22:E22) -> 0.00070710678 | F33: =AVERAGE(F22:G22) -> 0.0045 | G33: =STDEV(F22:G22) -> 0.0049497475 | H33: =AVERAGE(H22:I22) -> 0 | I33: =STDEV(H22:I22) -> 0 | J33: =AVERAGE(J22:K22) -> 0 | K33: =STDEV(J22:K22) -> 0 | L33: =AVERAGE(L22:M22) -> 0 | M33: =STDEV(L22:M22) -> 0

Sheet +61.0 seg
A1: 0 | B1: 1 | C1: 2 | D1: 3 | E1: 4 | F1: 5 | G1: 6 | H1: 7 | I1: 8 | J1: 9 | K1: 10 | L1: 11 | M1: 12
A2: * | B2: 1 | C2: 2 | D2: 3 | E2: 4 | F2: 5 | G2: 6 | H2: 7 | I2: 8 | J2: 9 | K2: 10 | L2: 11 | M2: 12
A3: A | B3: 0.098 | C3: 0.085 | D3: 0.075 | E3: 0.089 | F3: 0.143 | G3: 0.116 | H3: 0.083 | I3: 0.061 | J3: 0.051 | K3: 0.048 | L3: 0.12 | M3: 0.092
A4: B | B4: 0.128 | C4: 0.14 | D4: 0.079 | E4: 0.088 | F4: 0.15 | G4: 0.129 | H4: 0.095 | I4: 0.095 | J4: 0.062 | K4: 0.053 | L4: 0.093 | M4: 0.111
A5: C | B5: 0.141 | C5: 0.145 | D5: 0.084 | E5: 0.081 | F5: 0.102 | G5: 0.11 | H5: 0.077 | I5: 0.066 | J5: 0.094 | K5: 0.118 | L5: 0.114 | M5: 0.107
A6: D | B6: 0.173 | C6: 0.186 | D6: 0.084 | E6: 0.091 | F6: 0.119 | G6: 0.205 | H6: 0.07 | I6: 0.111 | J6: 0.083 | K6: 0.084 | L6: 0.101 | M6: 0.097
A7: E | B7: 0.135 | C7: 0.148 | D7: 0.083 | E7: 0.089 | F7: 0.116 | G7: 0.108 | H7: 0.096 | I7: 0.082 | J7: 0.069 | K7: 0.069 | L7: 0.648 | M7: 0.097
A8: F | B8: 0.122 | C8: 0.091 | D8: 0.077 | E8: 0.075 | F8: 0.098 | G8: 0.08 | H8: 0.077 | I8: 0.058 | J8: 0.05 | K8: 0.062 | L8: 0.369 | M8: 0.098
A9: G | B9: 0.152 | C9: 0.165 | D9: 0.102 | E9: 0.106 | F9: 0.118 | G9: 0.101 | H9: 0.07 | I9: 0.074 | J9: 0.116 | K9: 0.115 | L9: 0.104 | M9: 0.133
A10: H | B10: 0.207 | C10: 0.223 | D10: 0.104 | E10: 0.111 | F10: 0.236 | G10: 0.161 | H10: 0.097 | I10: 0.093 | J10: 0.096 | K10: 0.125 | L10: 0.125 | M10: 0.096
A14: * | B14: 1 | C14: 2 | D14: 3 | E14: 4 | F14: 5 | G14: 6 | H14: 7 | I14: 8 | J14: 9 | K14: 10 | L14: 11 | M14: 12
A15: A | B15: =B3 - '+0.0 seg'!$B$3 -> 0 | C15: =C3 - '+0.0 seg'!$C$3 -> 0 | D15: =D3 - '+0.0 seg'!$D$3 -> 0.002 | E15: =E3 - '+0.0 seg'!$E$3 -> 0.002 | F15: =F3 - '+0.0 seg'!$F$3 -> -0.004 | G15: =G3 - '+0.0 seg'!$G$3 -> 0.001 | H15: =H3 - '+0.0 seg'!$H$3 -> 0 | I15: =I3 - '+0.0 seg'!$I$3 -> 0 | J15: =J3 - '+0.0 seg'!$J$3 -> 0 | K15: =K3 - '+0.0 seg'!$K$3 -> -0.004 | L15: =L3 - '+0.0 seg'!$L$3 -> 0 | M15: =M3 - '+0.0 seg'!$M$3 -> 0
A16: B | B16: =B4 - '+0.0 seg'!$B$4 -> 0 | C16: =C4 - '+0.0 seg'!$C$4 -> 0 | D16: =D4 - '+0.0 seg'!$D$4 -> 0.003 | E16: =E4 - '+0.0 seg'!$E$4 -> 0.004 | F16: =F4 - '+0.0 seg'!$F$4 -> 0.004 | G16: =G4 - '+0.0 seg'!$G$4 -> 0.002 | H16: =H4 - '+0.0 seg'!$H$4 -> 0.004 | I16: =I4 - '+0.0 seg'!$I$4 -> 0.003 | J16: =J4 - '+0.0 seg'!$J$4 -> 0 | K16: =K4 - '+0.0 seg'!$K$4 -> 0.001 | L16: =L4 - '+0.0 seg'!$L$4 -> -0.001 | M16: =M4 - '+0.0 seg'!$M$4 -> 0
A17: C | B17: =B5 - '+0.0 seg'!$B$5 -> 0 | C17: =C5 - '+0.0 seg'!$C$5 -> 0.003 | D17: =D5 - '+0.0 seg'!$D$5 -> 0.004 | E17: =E5 - '+0.0 seg'!$E$5 -> 0.001 | F17: =F5 - '+0.0 seg'!$F$5 -> 0.001 | G17: =G5 - '+0.0 seg'!$G$5 -> -0.006 | H17: =H5 - '+0.0 seg'!$H$5 -> 0.002 | I17: =I5 - '+0.0 seg'!$I$5 -> -0.003 | J17: =J5 - '+0.0 seg'!$J$5 -> 0 | K17: =K5 - '+0.0 seg'!$K$5 -> 0 | L17: =L5 - '+0.0 seg'!$L$5 -> 0 | M17: =M5 - '+0.0 seg'!$M$5 -> 0
A18: D | B18: =B6 - '+0.0 seg'!$B$6 -> 0.002 | C18: =C6 - '+0.0 seg'!$C$6 -> 0.002 | D18: =D6 - '+0.0 seg'!$D$6 -> 0.002 | E18: =E6 - '+0.0 seg'!$E$6 -> 0 | F18: =F6 - '+0.0 seg'!$F$6 -> 0.002 | G18: =G6 - '+0.0 seg'!$G$6 -> 0.006 | H18: =H6 - '+0.0 seg'!$H$6 -> 0.002 | I18: =I6 - '+0.0 seg'!$I$6 -> 0.002 | J18: =J6 - '+0.0 seg'!$J$6 -> 0 | K18: =K6 - '+0.0 seg'!$K$6 -> 0 | L18: =L6 - '+0.0 seg'!$L$6 -> 0 | M18: =M6 - '+0.0 seg'!$M$6 -> 0
A19: E | B19: =B7 - '+0.0 seg'!$B$7 -> 0.001 | C19: =C7 - '+0.0 seg'!$C$7 -> -0.003 | D19: =D7 - '+0.0 seg'!$D$7 -> 0.003 | E19: =E7 - '+0.0 seg'!$E$7 -> 0.001 | F19: =F7 - '+0.0 seg'!$F$7 -> 0.004 | G19: =G7 - '+0.0 seg'!$G$7 -> 0.005 | H19: =H7 - '+0.0 seg'!$H$7 -> 0.002 | I19: =I7 - '+0.0 seg'!$I$7 -> -0.002 | J19: =J7 - '+0.0 seg'!$J$7 -> 0 | K19: =K7 - '+0.0 seg'!$K$7 -> 0 | L19: =L7 - '+0.0 seg'!$L$7 -> 0.005 | M19: =M7 - '+0.0 seg'!$M$7 -> 0
A20: F | B20: =B8 - '+0.0 seg'!$B$8 -> 0.006 | C20: =C8 - '+0.0 seg'!$C$8 -> 0 | D20: =D8 - '+0.0 seg'!$D$8 -> -0.002 | E20: =E8 - '+0.0 seg'!$E$8 -> 0 | F20: =F8 - '+0.0 seg'!$F$8 -> 0.002 | G20: =G8 - '+0.0 seg'!$G$8 -> 0.001 | H20: =H8 - '+0.0 seg'!$H$8 -> 0.001 | I20: =I8 - '+0.0 seg'!$I$8 -> -0.001 | J20: =J8 - '+0.0 seg'!$J$8 -> -0.001 | K20: =K8 - '+0.0 seg'!$K$8 -> 0 | L20: =L8 - '+0.0 seg'!$L$8 -> 0 | M20: =M8 - '+0.0 seg'!$M$8 -> 0.001
A21: G | B21: =B9 - '+0.0 seg'!$B$9 -> 0.001 | C21: =C9 - '+0.0 seg'!$C$9 -> 0.003 | D21: =D9 - '+0.0 seg'!$D$9 -> 0.002 | E21: =E9 - '+0.0 seg'!$E$9 -> 0.001 | F21: =F9 - '+0.0 seg'!$F$9 -> 0.002 | G21: =G9 - '+0.0 seg'!$G$9 -> 0.003 | H21: =H9 - '+0.0 seg'!$H$9 -> 0 | I21: =I9 - '+0.0 seg'!$I$9 -> 0 | J21: =J9 - '+0.0 seg'!$J$9 -> 0 | K21: =K9 - '+0.0 seg'!$K$9 -> 0.001 | L21: =L9 - '+0.0 seg'!$L$9 -> 0 | M21: =M9 - '+0.0 seg'!$M$9 -> 0
A22: H | B22: =B10 - '+0.0 seg'!$B$10 -> -0.012 | C22: =C10 - '+0.0 seg'!$C$10 -> 0.018 | D22: =D10 - '+0.0 seg'!$D$10 -> -0.001 | E22: =E10 - '+0.0 seg'!$E$10 -> -0.001 | F22: =F10 - '+0.0 seg'!$F$10 -> 0.01 | G22: =G10 - '+0.0 seg'!$G$10 -> 0.002 | H22: =H10 - '+0.0 seg'!$H$10 -> 0 | I22: =I10 - '+0.0 seg'!$I$10 -> 0.001 | J22: =J10 - '+0.0 seg'!$J$10 -> 0 | K22: =K10 - '+0.0 seg'!$K$10 -> 0 | L22: =L10 - '+0.0 seg'!$L$10 -> 0 | M22: =M10 - '+0.0 seg'!$M$10 -> 0
A25: * | B25: Mean 1-2 | C25: DE 1-2 | D25: Mean 3-4 | E25: DE 3-4 | F25: Mean 5-6 | G25: DE 5-6 | H25: Mean 7-8 | I25: DE 7-8 | J25: Mean 9-10 | K25: DE 9-10 | L25: Mean 11-12 | M25: DE 11-12
A26: A | B26: =AVERAGE(B15:C15) -> 0 | C26: =STDEV(B15:C15) -> 0 | D26: =AVERAGE(D15:E15) -> 0.002 | E26: =STDEV(D15:E15) -> 0 | F26: =AVERAGE(F15:G15) -> -0.0015 | G26: =STDEV(F15:G15) -> 0.0035355339 | H26: =AVERAGE(H15:I15) -> 0 | I26: =STDEV(H15:I15) -> 0 | J26: =AVERAGE(J15:K15) -> -0.002 | K26: =STDEV(J15:K15) -> 0.0028284271 | L26: =AVERAGE(L15:M15) -> 0 | M26: =STDEV(L15:M15) -> 0
A27: B | B27: =AVERAGE(B16:C16) -> 0 | C27: =STDEV(B16:C16) -> 0 | D27: =AVERAGE(D16:E16) -> 0.0035 | E27: =STDEV(D16:E16) -> 0.00070710678 | F27: =AVERAGE(F16:G16) -> 0.003 | G27: =STDEV(F16:G16) -> 0.0014142136 | H27: =AVERAGE(H16:I16) -> 0.0035 | I27: =STDEV(H16:I16) -> 0.00070710678 | J27: =AVERAGE(J16:K16) -> 0.0005 | K27: =STDEV(J16:K16) -> 0.00070710678 | L27: =AVERAGE(L16:M16) -> -0.0005 | M27: =STDEV(L16:M16) -> 0.00070710678
A28: C | B28: =AVERAGE(B17:C17) -> 0.0015 | C28: =STDEV(B17:C17) -> 0.0021213203 | D28: =AVERAGE(D17:E17) -> 0.0025 | E28: =STDEV(D17:E17) -> 0.0021213203 | F28: =AVERAGE(F17:G17) -> -0.0025 | G28: =STDEV(F17:G17) -> 0.0049497475 | H28: =AVERAGE(H17:I17) -> -0.0005 | I28: =STDEV(H17:I17) -> 0.0035355339 | J28: =AVERAGE(J17:K17) -> 0 | K28: =STDEV(J17:K17) -> 0 | L28: =AVERAGE(L17:M17) -> 0 | M28: =STDEV(L17:M17) -> 0
A29: D | B29: =AVERAGE(B18:C18) -> 0.002 | C29: =STDEV(B18:C18) -> 1.9626156e-17 | D29: =AVERAGE(D18:E18) -> 0.001 | E29: =STDEV(D18:E18) -> 0.0014142136 | F29: =AVERAGE(F18:G18) -> 0.004 | G29: =STDEV(F18:G18) -> 0.0028284271 | H29: =AVERAGE(H18:I18) -> 0.002 | I29: =STDEV(H18:I18) -> 0 | J29: =AVERAGE(J18:K18) -> 0 | K29: =STDEV(J18:K18) -> 0 | L29: =AVERAGE(L18:M18) -> 0 | M29: =STDEV(L18:M18) -> 0
A30: E | B30: =AVERAGE(B19:C19) -> -0.001 | C30: =STDEV(B19:C19) -> 0.0028284271 | D30: =AVERAGE(D19:E19) -> 0.002 | E30: =STDEV(D19:E19) -> 0.0014142136 | F30: =AVERAGE(F19:G19) -> 0.0045 | G30: =STDEV(F19:G19) -> 0.00070710678 | H30: =AVERAGE(H19:I19) -> 0 | I30: =STDEV(H19:I19) -> 0.0028284271 | J30: =AVERAGE(J19:K19) -> 0 | K30: =STDEV(J19:K19) -> 0 | L30: =AVERAGE(L19:M19) -> 0.0025 | M30: =STDEV(L19:M19) -> 0.0035355339
A31: F | B31: =AVERAGE(B20:C20) -> 0.003 | C31: =STDEV(B20:C20) -> 0.0042426407 | D31: =AVERAGE(D20:E20) -> -0.001 | E31: =STDEV(D20:E20) -> 0.0014142136 | F31: =AVERAGE(F20:G20) -> 0.0015 | G31: =STDEV(F20:G20) -> 0.00070710678 | H31: =AVERAGE(H20:I20) -> 3.469447e-18 | I31: =STDEV(H20:I20) -> 0.0014142136 | J31: =AVERAGE(J20:K20) -> -0.0005 | K31: =STDEV(J20:K20) -> 0.00070710678 | L31: =AVERAGE(L20:M20) -> 0.0005 | M31: =STDEV(L20:M20) -> 0.00070710678
A32: G | B32: =AVERAGE(B21:C21) -> 0.002 | C32: =STDEV(B21:C21) -> 0.0014142136 | D32: =AVERAGE(D21:E21) -> 0.0015 | E32: =STDEV(D21:E21) -> 0.00070710678 | F32: =AVERAGE(F21:G21) -> 0.0025 | G32: =STDEV(F21:G21) -> 0.00070710678 | H32: =AVERAGE(H21:I21) -> 0 | I32: =STDEV(H21:I21) -> 0 | J32: =AVERAGE(J21:K21) -> 0.0005 | K32: =STDEV(J21:K21) -> 0.00070710678 | L32: =AVERAGE(L21:M21) -> 0 | M32: =STDEV(L21:M21) -> 0
A33: H | B33: =AVERAGE(B22:C22) -> 0.003 | C33: =STDEV(B22:C22) -> 0.021213203 | D33: =AVERAGE(D22:E22) -> -0.001 | E33: =STDEV(D22:E22) -> 0 | F33: =AVERAGE(F22:G22) -> 0.006 | G33: =STDEV(F22:G22) -> 0.0056568542 | H33: =AVERAGE(H22:I22) -> 0.0005 | I33: =STDEV(H22:I22) -> 0.00070710678 | J33: =AVERAGE(J22:K22) -> 0 | K33: =STDEV(J22:K22) -> 0 | L33: =AVERAGE(L22:M22) -> 0 | M33: =STDEV(L22:M22) -> 0

Sheet +81.0 seg
A1: 0 | B1: 1 | C1: 2 | D1: 3 | E1: 4 | F1: 5 | G1: 6 | H1: 7 | I1: 8 | J1: 9 | K1: 10 | L1: 11 | M1: 12
A2: * | B2: 1 | C2: 2 | D2: 3 | E2: 4 | F2: 5 | G2: 6 | H2: 7 | I2: 8 | J2: 9 | K2: 10 | L2: 11 | M2: 12
A3: A | B3: 0.099 | C3: 0.086 | D3: 0.076 | E3: 0.091 | F3: 0.143 | G3: 0.117 | H3: 0.083 | I3: 0.061 | J3: 0.05 | K3: 0.048 | L3: 0.12 | M3: 0.092
A4: B | B4: 0.129 | C4: 0.141 | D4: 0.079 | E4: 0.087 | F4: 0.15 | G4: 0.129 | H4: 0.096 | I4: 0.095 | J4: 0.061 | K4: 0.053 | L4: 0.093 | M4: 0.111
A5: C | B5: 0.142 | C5: 0.146 | D5: 0.084 | E5: 0.08 | F5: 0.102 | G5: 0.109 | H5: 0.078 | I5: 0.064 | J5: 0.093 | K5: 0.118 | L5: 0.114 | M5: 0.107
A6: D | B6: 0.174 | C6: 0.186 | D6: 0.083 | E6: 0.091 | F6: 0.119 | G6: 0.206 | H6: 0.07 | I6: 0.109 | J6: 0.083 | K6: 0.084 | L6: 0.101 | M6: 0.097
A7: E | B7: 0.136 | C7: 0.15 | D7: 0.082 | E7: 0.09 | F7: 0.116 | G7: 0.109 | H7: 0.099 | I7: 0.08 | J7: 0.068 | K7: 0.069 | L7: 0.653 | M7: 0.097
A8: F | B8: 0.121 | C8: 0.092 | D8: 0.076 | E8: 0.076 | F8: 0.099 | G8: 0.08 | H8: 0.078 | I8: 0.058 | J8: 0.05 | K8: 0.062 | L8: 0.37 | M8: 0.098
A9: G | B9: 0.153 | C9: 0.166 | D9: 0.102 | E9: 0.106 | F9: 0.118 | G9: 0.102 | H9: 0.071 | I9: 0.075 | J9: 0.116 | K9: 0.115 | L9: 0.104 | M9: 0.133
A10: H | B10: 0.225 | C10: 0.219 | D10: 0.104 | E10: 0.111 | F10: 0.238 | G10: 0.162 | H10: 0.098 | I10: 0.093 | J10: 0.096 | K10: 0.125 | L10: 0.125 | M10: 0.097
A14: * | B14: 1 | C14: 2 | D14: 3 | E14: 4 | F14: 5 | G14: 6 | H14: 7 | I14: 8 | J14: 9 | K14: 10 | L14: 11 | M14: 12
A15: A | B15: =B3 - '+0.0 seg'!$B$3 -> 0.001 | C15: =C3 - '+0.0 seg'!$C$3 -> 0.001 | D15: =D3 - '+0.0 seg'!$D$3 -> 0.003 | E15: =E3 - '+0.0 seg'!$E$3 -> 0.004 | F15: =F3 - '+0.0 seg'!$F$3 -> -0.004 | G15: =G3 - '+0.0 seg'!$G$3 -> 0.002 | H15: =H3 - '+0.0 seg'!$H$3 -> 0 | I15: =I3 - '+0.0 seg'!$I$3 -> 0 | J15: =J3 - '+0.0 seg'!$J$3 -> -0.001 | K15: =K3 - '+0.0 seg'!$K$3 -> -0.004 | L15: =L3 - '+0.0 seg'!$L$3 -> 0 | M15: =M3 - '+0.0 seg'!$M$3 -> 0
A16: B | B16: =B4 - '+0.0 seg'!$B$4 -> 0.001 | C16: =C4 - '+0.0 seg'!$C$4 -> 0.001 | D16: =D4 - '+0.0 seg'!$D$4 -> 0.003 | E16: =E4 - '+0.0 seg'!$E$4 -> 0.003 | F16: =F4 - '+0.0 seg'!$F$4 -> 0.004 | G16: =G4 - '+0.0 seg'!$G$4 -> 0.002 | H16: =H4 - '+0.0 seg'!$H$4 -> 0.005 | I16: =I4 - '+0.0 seg'!$I$4 -> 0.003 | J16: =J4 - '+0.0 seg'!$J$4 -> -0.001 | K16: =K4 - '+0.0 seg'!$K$4 -> 0.001 | L16: =L4 - '+0.0 seg'!$L$4 -> -0.001 | M16: =M4 - '+0.0 seg'!$M$4 -> 0
A17: C | B17: =B5 - '+0.0 seg'!$B$5 -> 0.001 | C17: =C5 - '+0.0 seg'!$C$5 -> 0.004 | D17: =D5 - '+0.0 seg'!$D$5 -> 0.004 | E17: =E5 - '+0.0 seg'!$E$5 -> 0 | F17: =F5 - '+0.0 seg'!$F$5 -> 0.001 | G17: =G5 - '+0.0 seg'!$G$5 -> -0.007 | H17: =H5 - '+0.0 seg'!$H$5 -> 0.003 | I17: =I5 - '+0.0 seg'!$I$5 -> -0.005 | J17: =J5 - '+0.0 seg'!$J$5 -> -0.001 | K17: =K5 - '+0.0 seg'!$K$5 -> 0 | L17: =L5 - '+0.0 seg'!$L$5 -> 0 | M17: =M5 - '+0.0 seg'!$M$5 -> 0
A18: D | B18: =B6 - '+0.0 seg'!$B$6 -> 0.003 | C18: =C6 - '+0.0 seg'!$C$6 -> 0.002 | D18: =D6 - '+0.0 seg'!$D$6 -> 0.001 | E18: =E6 - '+0.0 seg'!$E$6 -> 0 | F18: =F6 - '+0.0 seg'!$F$6 -> 0.002 | G18: =G6 - '+0.0 seg'!$G$6 -> 0.007 | H18: =H6 - '+0.0 seg'!$H$6 -> 0.002 | I18: =I6 - '+0.0 seg'!$I$6 -> 0 | J18: =J6 - '+0.0 seg'!$J$6 -> 0 | K18: =K6 - '+0.0 seg'!$K$6 -> 0 | L18: =L6 - '+0.0 seg'!$L$6 -> 0 | M18: =M6 - '+0.0 seg'!$M$6 -> 0
A19: E | B19: =B7 - '+0.0 seg'!$B$7 -> 0.002 | C19: =C7 - '+0.0 seg'!$C$7 -> -0.001 | D19: =D7 - '+0.0 seg'!$D$7 -> 0.002 | E19: =E7 - '+0.0 seg'!$E$7 -> 0.002 | F19: =F7 - '+0.0 seg'!$F$7 -> 0.004 | G19: =G7 - '+0.0 seg'!$G$7 -> 0.006 | H19: =H7 - '+0.0 seg'!$H$7 -> 0.005 | I19: =I7 - '+0.0 seg'!$I$7 -> -0.004 | J19: =J7 - '+0.0 seg'!$J$7 -> -0.001 | K19: =K7 - '+0.0 seg'!$K$7 -> 0 | L19: =L7 - '+0.0 seg'!$L$7 -> 0.01 | M19: =M7 - '+0.0 seg'!$M$7 -> 0
A20: F | B20: =B8 - '+0.0 seg'!$B$8 -> 0.005 | C20: =C8 - '+0.0 seg'!$C$8 -> 0.001 | D20: =D8 - '+0.0 seg'!$D$8 -> -0.003 | E20: =E8 - '+0.0 seg'!$E$8 -> 0.001 | F20: =F8 - '+0.0 seg'!$F$8 -> 0.003 | G20: =G8 - '+0.0 seg'!$G$8 -> 0.001 | H20: =H8 - '+0.0 seg'!$H$8 -> 0.002 | I20: =I8 - '+0.0 seg'!$I$8 -> -0.001 | J20: =J8 - '+0.0 seg'!$J$8 -> -0.001 | K20: =K8 - '+0.0 seg'!$K$8 -> 0 | L20: =L8 - '+0.0 seg'!$L$8 -> 0.001 | M20: =M8 - '+0.0 seg'!$M$8 -> 0.001
A21: G | B21: =B9 - '+0.0 seg'!$B$9 -> 0.002 | C21: =C9 - '+0.0 seg'!$C$9 -> 0.004 | D21: =D9 - '+0.0 seg'!$D$9 -> 0.002 | E21: =E9 - '+0.0 seg'!$E$9 -> 0.001 | F21: =F9 - '+0.0 seg'!$F$9 -> 0.002 | G21: =G9 - '+0.0 seg'!$G$9 -> 0.004 | H21: =H9 - '+0.0 seg'!$H$9 -> 0.001 | I21: =I9 - '+0.0 seg'!$I$9 -> 0.001 | J21: =J9 - '+0.0 seg'!$J$9 -> 0 | K21: =K9 - '+0.0 seg'!$K$9 -> 0.001 | L21: =L9 - '+0.0 seg'!$L$9 -> 0 | M21: =M9 - '+0.0 seg'!$M$9 -> 0
A22: H | B22: =B10 - '+0.0 seg'!$B$10 -> 0.006 | C22: =C10 - '+0.0 seg'!$C$10 -> 0.014 | D22: =D10 - '+0.0 seg'!$D$10 -> -0.001 | E22: =E10 - '+0.0 seg'!$E$10 -> -0.001 | F22: =F10 - '+0.0 seg'!$F$10 -> 0.012 | G22: =G10 - '+0.0 seg'!$G$10 -> 0.003 | H22: =H10 - '+0.0 seg'!$H$10 -> 0.001 | I22: =I10 - '+0.0 seg'!$I$10 -> 0.001 | J22: =J10 - '+0.0 seg'!$J$10 -> 0 | K22: =K10 - '+0.0 seg'!$K$10 -> 0 | L22: =L10 - '+0.0 seg'!$L$10 -> 0 | M22: =M10 - '+0.0 seg'!$M$10 -> 0.001
A25: * | B25: Mean 1-2 | C25: DE 1-2 | D25: Mean 3-4 | E25: DE 3-4 | F25: Mean 5-6 | G25: DE 5-6 | H25: Mean 7-8 | I25: DE 7-8 | J25: Mean 9-10 | K25: DE 9-10 | L25: Mean 11-12 | M25: DE 11-12
A26: A | B26: =AVERAGE(B15:C15) -> 0.001 | C26: =STDEV(B15:C15) -> 9.8130779e-18 | D26: =AVERAGE(D15:E15) -> 0.0035 | E26: =STDEV(D15:E15) -> 0.00070710678 | F26: =AVERAGE(F15:G15) -> -0.001 | G26: =STDEV(F15:G15) -> 0.0042426407 | H26: =AVERAGE(H15:I15) -> 0 | I26: =STDEV(H15:I15) -> 0 | J26: =AVERAGE(J15:K15) -> -0.0025 | K26: =STDEV(J15:K15) -> 0.0021213203 | L26: =AVERAGE(L15:M15) -> 0 | M26: =STDEV(L15:M15) -> 0
A27: B | B27: =AVERAGE(B16:C16) -> 0.001 | C27: =STDEV(B16:C16) -> 1.9626156e-17 | D27: =AVERAGE(D16:E16) -> 0.003 | E27: =STDEV(D16:E16) -> 9.8130779e-18 | F27: =AVERAGE(F16:G16) -> 0.003 | G27: =STDEV(F16:G16) -> 0.0014142136 | H27: =AVERAGE(H16:I16) -> 0.004 | I27: =STDEV(H16:I16) -> 0.0014142136 | J27: =AVERAGE(J16:K16) -> 0 | K27: =STDEV(J16:K16) -> 0.0014142136 | L27: =AVERAGE(L16:M16) -> -0.0005 | M27: =STDEV(L16:M16) -> 0.00070710678
A28: C | B28: =AVERAGE(B17:C17) -> 0.0025 | C28: =STDEV(B17:C17) -> 0.0021213203 | D28: =AVERAGE(D17:E17) -> 0.002 | E28: =STDEV(D17:E17) -> 0.0028284271 | F28: =AVERAGE(F17:G17) -> -0.003 | G28: =STDEV(F17:G17) -> 0.0056568542 | H28: =AVERAGE(H17:I17) -> -0.001 | I28: =STDEV(H17:I17) -> 0.0056568542 | J28: =AVERAGE(J17:K17) -> -0.0005 | K28: =STDEV(J17:K17) -> 0.00070710678 | L28: =AVERAGE(L17:M17) -> 0 | M28: =STDEV(L17:M17) -> 0
A29: D | B29: =AVERAGE(B18:C18) -> 0.0025 | C29: =STDEV(B18:C18) -> 0.00070710678 | D29: =AVERAGE(D18:E18) -> 0.0005 | E29: =STDEV(D18:E18) -> 0.00070710678 | F29: =AVERAGE(F18:G18) -> 0.0045 | G29: =STDEV(F18:G18) -> 0.0035355339 | H29: =AVERAGE(H18:I18) -> 0.001 | I29: =STDEV(H18:I18) -> 0.0014142136 | J29: =AVERAGE(J18:K18) -> 0 | K29: =STDEV(J18:K18) -> 0 | L29: =AVERAGE(L18:M18) -> 0 | M29: =STDEV(L18:M18) -> 0
A30: E | B30: =AVERAGE(B19:C19) -> 0.0005 | C30: =STDEV(B19:C19) -> 0.0021213203 | D30: =AVERAGE(D19:E19) -> 0.002 | E30: =STDEV(D19:E19) -> 0 | F30: =AVERAGE(F19:G19) -> 0.005 | G30: =STDEV(F19:G19) -> 0.0014142136 | H30: =AVERAGE(H19:I19) -> 0.0005 | I30: =STDEV(H19:I19) -> 0.006363961 | J30: =AVERAGE(J19:K19) -> -0.0005 | K30: =STDEV(J19:K19) -> 0.00070710678 | L30: =AVERAGE(L19:M19) -> 0.005 | M30: =STDEV(L19:M19) -> 0.0070710678
A31: F | B31: =AVERAGE(B20:C20) -> 0.003 | C31: =STDEV(B20:C20) -> 0.0028284271 | D31: =AVERAGE(D20:E20) -> -0.001 | E31: =STDEV(D20:E20) -> 0.0028284271 | F31: =AVERAGE(F20:G20) -> 0.002 | G31: =STDEV(F20:G20) -> 0.0014142136 | H31: =AVERAGE(H20:I20) -> 0.0005 | I31: =STDEV(H20:I20) -> 0.0021213203 | J31: =AVERAGE(J20:K20) -> -0.0005 | K31: =STDEV(J20:K20) -> 0.00070710678 | L31: =AVERAGE(L20:M20) -> 0.001 | M31: =STDEV(L20:M20) -> 0
A32: G | B32: =AVERAGE(B21:C21) -> 0.003 | C32: =STDEV(B21:C21) -> 0.0014142136 | D32: =AVERAGE(D21:E21) -> 0.0015 | E32: =STDEV(D21:E21) -> 0.00070710678 | F32: =AVERAGE(F21:G21) -> 0.003 | G32: =STDEV(F21:G21) -> 0.0014142136 | H32: =AVERAGE(H21:I21) -> 0.001 | I32: =STDEV(H21:I21) -> 9.8130779e-18 | J32: =AVERAGE(J21:K21) -> 0.0005 | K32: =STDEV(J21:K21) -> 0.00070710678 | L32: =AVERAGE(L21:M21) -> 0 | M32: =STDEV(L21:M21) -> 0
A33: H | B33: =AVERAGE(B22:C22) -> 0.01 | C33: =STDEV(B22:C22) -> 0.0056568542 | D33: =AVERAGE(D22:E22) -> -0.001 | E33: =STDEV(D22:E22) -> 0 | F33: =AVERAGE(F22:G22) -> 0.0075 | G33: =STDEV(F22:G22) -> 0.006363961 | H33: =AVERAGE(H22:I22) -> 0.001 | I33: =STDEV(H22:I22) -> 0 | J33: =AVERAGE(J22:K22) -> 0 | K33: =STDEV(J22:K22) -> 0 | L33: =AVERAGE(L22:M22) -> 0.0005 | M33: =STDEV(L22:M22) -> 0.00070710678

Sheet +101.0 seg
A1: 0 | B1: 1 | C1: 2 | D1: 3 | E1: 4 | F1: 5 | G1: 6 | H1: 7 | I1: 8 | J1: 9 | K1: 10 | L1: 11 | M1: 12
A2: * | B2: 1 | C2: 2 | D2: 3 | E2: 4 | F2: 5 | G2: 6 | H2: 7 | I2: 8 | J2: 9 | K2: 10 | L2: 11 | M2: 12
A3: A | B3: 0.101 | C3: 0.086 | D3: 0.076 | E3: 0.087 | F3: 0.144 | G3: 0.118 | H3: 0.083 | I3: 0.062 | J3: 0.054 | K3: 0.048 | L3: 0.12 | M3: 0.092
A4: B | B4: 0.129 | C4: 0.141 | D4: 0.08 | E4: 0.088 | F4: 0.151 | G4: 0.13 | H4: 0.097 | I4: 0.095 | J4: 0.061 | K4: 0.053 | L4: 0.093 | M4: 0.111
A5: C | B5: 0.142 | C5: 0.147 | D5: 0.084 | E5: 0.08 | F5: 0.103 | G5: 0.109 | H5: 0.078 | I5: 0.064 | J5: 0.094 | K5: 0.118 | L5: 0.114 | M5: 0.107
A6: D | B6: 0.174 | C6: 0.188 | D6: 0.083 | E6: 0.092 | F6: 0.12 | G6: 0.208 | H6: 0.071 | I6: 0.109 | J6: 0.083 | K6: 0.084 | L6: 0.101 | M6: 0.097
A7: E | B7: 0.136 | C7: 0.151 | D7: 0.083 | E7: 0.091 | F7: 0.117 | G7: 0.111 | H7: 0.101 | I7: 0.081 | J7: 0.069 | K7: 0.069 | L7: 0.651 | M7: 0.097
A8: F | B8: 0.121 | C8: 0.093 | D8: 0.076 | E8: 0.076 | F8: 0.1 | G8: 0.081 | H8: 0.08 | I8: 0.058 | J8: 0.05 | K8: 0.061 | L8: 0.367 | M8: 0.097
A9: G | B9: 0.154 | C9: 0.167 | D9: 0.103 | E9: 0.107 | F9: 0.119 | G9: 0.103 | H9: 0.071 | I9: 0.075 | J9: 0.116 | K9: 0.115 | L9: 0.104 | M9: 0.133
A10: H | B10: 0.21 | C10: 0.219 | D10: 0.104 | E10: 0.111 | F10: 0.241 | G10: 0.164 | H10: 0.098 | I10: 0.093 | J10: 0.096 | K10: 0.125 | L10: 0.125 | M10: 0.096
A14: * | B14: 1 | C14: 2 | D14: 3 | E14: 4 | F14: 5 | G14: 6 | H14: 7 | I14: 8 | J14: 9 | K14: 10 | L14: 11 | M14: 12
A15: A | B15: =B3 - '+0.0 seg'!$B$3 -> 0.003 | C15: =C3 - '+0.0 seg'!$C$3 -> 0.001 | D15: =D3 - '+0.0 seg'!$D$3 -> 0.003 | E15: =E3 - '+0.0 seg'!$E$3 -> 0 | F15: =F3 - '+0.0 seg'!$F$3 -> -0.003 | G15: =G3 - '+0.0 seg'!$G$3 -> 0.003 | H15: =H3 - '+0.0 seg'!$H$3 -> 0 | I15: =I3 - '+0.0 seg'!$I$3 -> 0.001 | J15: =J3 - '+0.0 seg'!$J$3 -> 0.003 | K15: =K3 - '+0.0 seg'!$K$3 -> -0.004 | L15: =L3 - '+0.0 seg'!$L$3 -> 0 | M15: =M3 - '+0.0 seg'!$M$3 -> 0
A16: B | B16: =B4 - '+0.0 seg'!$B$4 -> 0.001 | C16: =C4 - '+0.0 seg'!$C$4 -> 0.001 | D16: =D4 - '+0.0 seg'!$D$4 -> 0.004 | E16: =E4 - '+0.0 seg'!$E$4 -> 0.004 | F16: =F4 - '+0.0 seg'!$F$4 -> 0.005 | G16: =G4 - '+0.0 seg'!$G$4 -> 0.003 | H16: =H4 - '+0.0 seg'!$H$4 -> 0.006 | I16: =I4 - '+0.0 seg'!$I$4 -> 0.003 | J16: =J4 - '+0.0 seg'!$J$4 -> -0.001 | K16: =K4 - '+0.0 seg'!$K$4 -> 0.001 | L16: =L4 - '+0.0 seg'!$L$4 -> -0.001 | M16: =M4 - '+0.0 seg'!$M$4 -> 0
A17: C | B17: =B5 - '+0.0 seg'!$B$5 -> 0.001 | C17: =C5 - '+0.0 seg'!$C$5 -> 0.005 | D17: =D5 - '+0.0 seg'!$D$5 -> 0.004 | E17: =E5 - '+0.0 seg'!$E$5 -> 0 | F17: =F5 - '+0.0 seg'!$F$5 -> 0.002 | G17: =G5 - '+0.0 seg'!$G$5 -> -0.007 | H17: =H5 - '+0.0 seg'!$H$5 -> 0.003 | I17: =I5 - '+0.0 seg'!$I$5 -> -0.005 | J17: =J5 - '+0.0 seg'!$J$5 -> 0 | K17: =K5 - '+0.0 seg'!$K$5 -> 0 | L17: =L5 - '+0.0 seg'!$L$5 -> 0 | M17: =M5 - '+0.0 seg'!$M$5 -> 0
A18: D | B18: =B6 - '+0.0 seg'!$B$6 -> 0.003 | C18: =C6 - '+0.0 seg'!$C$6 -> 0.004 | D18: =D6 - '+0.0 seg'!$D$6 -> 0.001 | E18: =E6 - '+0.0 seg'!$E$6 -> 0.001 | F18: =F6 - '+0.0 seg'!$F$6 -> 0.003 | G18: =G6 - '+0.0 seg'!$G$6 -> 0.009 | H18: =H6 - '+0.0 seg'!$H$6 -> 0.003 | I18: =I6 - '+0.0 seg'!$I$6 -> 0 | J18: =J6 - '+0.0 seg'!$J$6 -> 0 | K18: =K6 - '+0.0 seg'!$K$6 -> 0 | L18: =L6 - '+0.0 seg'!$L$6 -> 0 | M18: =M6 - '+0.0 seg'!$M$6 -> 0
A19: E | B19: =B7 - '+0.0 seg'!$B$7 -> 0.002 | C19: =C7 - '+0.0 seg'!$C$7 -> 0 | D19: =D7 - '+0.0 seg'!$D$7 -> 0.003 | E19: =E7 - '+0.0 seg'!$E$7 -> 0.003 | F19: =F7 - '+0.0 seg'!$F$7 -> 0.005 | G19: =G7 - '+0.0 seg'!$G$7 -> 0.008 | H19: =H7 - '+0.0 seg'!$H$7 -> 0.007 | I19: =I7 - '+0.0 seg'!$I$7 -> -0.003 | J19: =J7 - '+0.0 seg'!$J$7 -> 0 | K19: =K7 - '+0.0 seg'!$K$7 -> 0 | L19: =L7 - '+0.0 seg'!$L$7 -> 0.008 | M19: =M7 - '+0.0 seg'!$M$7 -> 0
A20: F | B20: =B8 - '+0.0 seg'!$B$8 -> 0.005 | C20: =C8 - '+0.0 seg'!$C$8 -> 0.002 | D20: =D8 - '+0.0 seg'!$D$8 -> -0.003 | E20: =E8 - '+0.0 seg'!$E$8 -> 0.001 | F20: =F8 - '+0.0 seg'!$F$8 -> 0.004 | G20: =G8 - '+0.0 seg'!$G$8 -> 0.002 | H20: =H8 - '+0.0 seg'!$H$8 -> 0.004 | I20: =I8 - '+0.0 seg'!$I$8 -> -0.001 | J20: =J8 - '+0.0 seg'!$J$8 -> -0.001 | K20: =K8 - '+0.0 seg'!$K$8 -> -0.001 | L20: =L8 - '+0.0 seg'!$L$8 -> -0.002 | M20: =M8 - '+0.0 seg'!$M$8 -> 0
A21: G | B21: =B9 - '+0.0 seg'!$B$9 -> 0.003 | C21: =C9 - '+0.0 seg'!$C$9 -> 0.005 | D21: =D9 - '+0.0 seg'!$D$9 -> 0.003 | E21: =E9 - '+0.0 seg'!$E$9 -> 0.002 | F21: =F9 - '+0.0 seg'!$F$9 -> 0.003 | G21: =G9 - '+0.0 seg'!$G$9 -> 0.005 | H21: =H9 - '+0.0 seg'!$H$9 -> 0.001 | I21: =I9 - '+0.0 seg'!$I$9 -> 0.001 | J21: =J9 - '+0.0 seg'!$J$9 -> 0 | K21: =K9 - '+0.0 seg'!$K$9 -> 0.001 | L21: =L9 - '+0.0 seg'!$L$9 -> 0 | M21: =M9 - '+0.0 seg'!$M$9 -> 0
A22: H | B22: =B10 - '+0.0 seg'!$B$10 -> -0.009 | C22: =C10 - '+0.0 seg'!$C$10 -> 0.014 | D22: =D10 - '+0.0 seg'!$D$10 -> -0.001 | E22: =E10 - '+0.0 seg'!$E$10 -> -0.001 | F22: =F10 - '+0.0 seg'!$F$10 -> 0.015 | G22: =G10 - '+0.0 seg'!$G$10 -> 0.005 | H22: =H10 - '+0.0 seg'!$H$10 -> 0.001 | I22: =I10 - '+0.0 seg'!$I$10 -> 0.001 | J22: =J10 - '+0.0 seg'!$J$10 -> 0 | K22: =K10 - '+0.0 seg'!$K$10 -> 0 | L22: =L10 - '+0.0 seg'!$L$10 -> 0 | M22: =M10 - '+0.0 seg'!$M$10 -> 0
A25: * | B25: Mean 1-2 | C25: DE 1-2 | D25: Mean 3-4 | E25: DE 3-4 | F25: Mean 5-6 | G25: DE 5-6 | H25: Mean 7-8 | I25: DE 7-8 | J25: Mean 9-10 | K25: DE 9-10 | L25: Mean 11-12 | M25: DE 11-12
A26: A | B26: =AVERAGE(B15:C15) -> 0.002 | C26: =STDEV(B15:C15) -> 0.0014142136 | D26: =AVERAGE(D15:E15) -> 0.0015 | E26: =STDEV(D15:E15) -> 0.0021213203 | F26: =AVERAGE(F15:G15) -> -6.9388939e-18 | G26: =STDEV(F15:G15) -> 0.0042426407 | H26: =AVERAGE(H15:I15) -> 0.0005 | I26: =STDEV(H15:I15) -> 0.00070710678 | J26: =AVERAGE(J15:K15) -> -0.0005 | K26: =STDEV(J15:K15) -> 0.0049497475 | L26: =AVERAGE(L15:M15) -> 0 | M26: =STDEV(L15:M15) -> 0
A27: B | B27: =AVERAGE(B16:C16) -> 0.001 | C27: =STDEV(B16:C16) -> 1.9626156e-17 | D27: =AVERAGE(D16:E16) -> 0.004 | E27: =STDEV(D16:E16) -> 9.8130779e-18 | F27: =AVERAGE(F16:G16) -> 0.004 | G27: =STDEV(F16:G16) -> 0.0014142136 | H27: =AVERAGE(H16:I16) -> 0.0045 | I27: =STDEV(H16:I16) -> 0.0021213203 | J27: =AVERAGE(J16:K16) -> 0 | K27: =STDEV(J16:K16) -> 0.0014142136 | L27: =AVERAGE(L16:M16) -> -0.0005 | M27: =STDEV(L16:M16) -> 0.00070710678
A28: C | B28: =AVERAGE(B17:C17) -> 0.003 | C28: =STDEV(B17:C17) -> 0.0028284271 | D28: =AVERAGE(D17:E17) -> 0.002 | E28: =STDEV(D17:E17) -> 0.0028284271 | F28: =AVERAGE(F17:G17) -> -0.0025 | G28: =STDEV(F17:G17) -> 0.006363961 | H28: =AVERAGE(H17:I17) -> -0.001 | I28: =STDEV(H17:I17) -> 0.0056568542 | J28: =AVERAGE(J17:K17) -> 0 | K28: =STDEV(J17:K17) -> 0 | L28: =AVERAGE(L17:M17) -> 0 | M28: =STDEV(L17:M17) -> 0
A29: D | B29: =AVERAGE(B18:C18) -> 0.0035 | C29: =STDEV(B18:C18) -> 0.00070710678 | D29: =AVERAGE(D18:E18) -> 0.001 | E29: =STDEV(D18:E18) -> 0 | F29: =AVERAGE(F18:G18) -> 0.006 | G29: =STDEV(F18:G18) -> 0.0042426407 | H29: =AVERAGE(H18:I18) -> 0.0015 | I29: =STDEV(H18:I18) -> 0.0021213203 | J29: =AVERAGE(J18:K18) -> 0 | K29: =STDEV(J18:K18) -> 0 | L29: =AVERAGE(L18:M18) -> 0 | M29: =STDEV(L18:M18) -> 0
A30: E | B30: =AVERAGE(B19:C19) -> 0.001 | C30: =STDEV(B19:C19) -> 0.0014142136 | D30: =AVERAGE(D19:E19) -> 0.003 | E30: =STDEV(D19:E19) -> 0 | F30: =AVERAGE(F19:G19) -> 0.0065 | G30: =STDEV(F19:G19) -> 0.0021213203 | H30: =AVERAGE(H19:I19) -> 0.002 | I30: =STDEV(H19:I19) -> 0.0070710678 | J30: =AVERAGE(J19:K19) -> 0 | K30: =STDEV(J19:K19) -> 0 | L30: =AVERAGE(L19:M19) -> 0.004 | M30: =STDEV(L19:M19) -> 0.0056568542
A31: F | B31: =AVERAGE(B20:C20) -> 0.0035 | C31: =STDEV(B20:C20) -> 0.0021213203 | D31: =AVERAGE(D20:E20) -> -0.001 | E31: =STDEV(D20:E20) -> 0.0028284271 | F31: =AVERAGE(F20:G20) -> 0.003 | G31: =STDEV(F20:G20) -> 0.0014142136 | H31: =AVERAGE(H20:I20) -> 0.0015 | I31: =STDEV(H20:I20) -> 0.0035355339 | J31: =AVERAGE(J20:K20) -> -0.001 | K31: =STDEV(J20:K20) -> 4.9065389e-18 | L31: =AVERAGE(L20:M20) -> -0.001 | M31: =STDEV(L20:M20) -> 0.0014142136
A32: G | B32: =AVERAGE(B21:C21) -> 0.004 | C32: =STDEV(B21:C21) -> 0.0014142136 | D32: =AVERAGE(D21:E21) -> 0.0025 | E32: =STDEV(D21:E21) -> 0.00070710678 | F32: =AVERAGE(F21:G21) -> 0.004 | G32: =STDEV(F21:G21) -> 0.0014142136 | H32: =AVERAGE(H21:I21) -> 0.001 | I32: =STDEV(H21:I21) -> 9.8130779e-18 | J32: =AVERAGE(J21:K21) -> 0.0005 | K32: =STDEV(J21:K21) -> 0.00070710678 | L32: =AVERAGE(L21:M21) -> 0 | M32: =STDEV(L21:M21) -> 0
A33: H | B33: =AVERAGE(B22:C22) -> 0.0025 | C33: =STDEV(B22:C22) -> 0.016263456 | D33: =AVERAGE(D22:E22) -> -0.001 | E33: =STDEV(D22:E22) -> 0 | F33: =AVERAGE(F22:G22) -> 0.01 | G33: =STDEV(F22:G22) -> 0.0070710678 | H33: =AVERAGE(H22:I22) -> 0.001 | I33: =STDEV(H22:I22) -> 0 | J33: =AVERAGE(J22:K22) -> 0 | K33: =STDEV(J22:K22) -> 0 | L33: =AVERAGE(L22:M22) -> 0 | M33: =STDEV(L22:M22) -> 0

Sheet +120.0 seg
A1: 0 | B1: 1 | C1: 2 | D1: 3 | E1: 4 | F1: 5 | G1: 6 | H1: 7 | I1: 8 | J1: 9 | K1: 10 | L1: 11 | M1: 12
A2: * | B2: 1 | C2: 2 | D2: 3 | E2: 4 | F2: 5 | G2: 6 | H2: 7 | I2: 8 | J2: 9 | K2: 10 | L2: 11 | M2: 12
A3: A | B3: 0.1 | C3: 0.087 | D3: 0.077 | E3: 0.092 | F3: 0.145 | G3: 0.118 | H3: 0.083 | I3: 0.062 | J3: 0.051 | K3: 0.048 | L3: 0.12 | M3: 0.092
A4: B | B4: 0.128 | C4: 0.141 | D4: 0.078 | E4: 0.087 | F4: 0.151 | G4: 0.13 | H4: 0.096 | I4: 0.095 | J4: 0.061 | K4: 0.054 | L4: 0.093 | M4: 0.111
A5: C | B5: 0.142 | C5: 0.148 | D5: 0.084 | E5: 0.08 | F5: 0.103 | G5: 0.109 | H5: 0.078 | I5: 0.063 | J5: 0.093 | K5: 0.118 | L5: 0.114 | M5: 0.107
A6: D | B6: 0.175 | C6: 0.188 | D6: 0.083 | E6: 0.091 | F6: 0.12 | G6: 0.209 | H6: 0.072 | I6: 0.109 | J6: 0.083 | K6: 0.084 | L6: 0.101 | M6: 0.097
A7: E | B7: 0.136 | C7: 0.152 | D7: 0.083 | E7: 0.091 | F7: 0.119 | G7: 0.111 | H7: 0.101 | I7: 0.079 | J7: 0.068 | K7: 0.069 | L7: 0.649 | M7: 0.097
A8: F | B8: 0.121 | C8: 0.094 | D8: 0.076 | E8: 0.076 | F8: 0.101 | G8: 0.081 | H8: 0.079 | I8: 0.058 | J8: 0.05 | K8: 0.062 | L8: 0.368 | M8: 0.097
A9: G | B9: 0.153 | C9: 0.168 | D9: 0.103 | E9: 0.107 | F9: 0.119 | G9: 0.104 | H9: 0.071 | I9: 0.074 | J9: 0.116 | K9: 0.115 | L9: 0.104 | M9: 0.133
A10: H | B10: 0.205 | C10: 0.221 | D10: 0.104 | E10: 0.112 | F10: 0.243 | G10: 0.165 | H10: 0.098 | I10: 0.093 | J10: 0.096 | K10: 0.125 | L10: 0.125 | M10: 0.097
A14: * | B14: 1 | C14: 2 | D14: 3 | E14: 4 | F14: 5 | G14: 6 | H14: 7 | I14: 8 | J14: 9 | K14: 10 | L14: 11 | M14: 12
A15: A | B15: =B3 - '+0.0 seg'!$B$3 -> 0.002 | C15: =C3 - '+0.0 seg'!$C$3 -> 0.002 | D15: =D3 - '+0.0 seg'!$D$3 -> 0.004 | E15: =E3 - '+0.0 seg'!$E$3 -> 0.005 | F15: =F3 - '+0.0 seg'!$F$3 -> -0.002 | G15: =G3 - '+0.0 seg'!$G$3 -> 0.003 | H15: =H3 - '+0.0 seg'!$H$3 -> 0 | I15: =I3 - '+0.0 seg'!$I$3 -> 0.001 | J15: =J3 - '+0.0 seg'!$J$3 -> 0 | K15: =K3 - '+0.0 seg'!$K$3 -> -0.004 | L15: =L3 - '+0.0 seg'!$L$3 -> 0 | M15: =M3 - '+0.0 seg'!$M$3 -> 0
A16: B | B16: =B4 - '+0.0 seg'!$B$4 -> 0 | C16: =C4 - '+0.0 seg'!$C$4 -> 0.001 | D16: =D4 - '+0.0 seg'!$D$4 -> 0.002 | E16: =E4 - '+0.0 seg'!$E$4 -> 0.003 | F16: =F4 - '+0.0 seg'!$F$4 -> 0.005 | G16: =G4 - '+0.0 seg'!$G$4 -> 0.003 | H16: =H4 - '+0.0 seg'!$H$4 -> 0.005 | I16: =I4 - '+0.0 seg'!$I$4 -> 0.003 | J16: =J4 - '+0.0 seg'!$J$4 -> -0.001 | K16: =K4 - '+0.0 seg'!$K$4 -> 0.002 | L16: =L4 - '+0.0 seg'!$L$4 -> -0.001 | M16: =M4 - '+0.0 seg'!$M$4 -> 0
A17: C | B17: =B5 - '+0.0 seg'!$B$5 -> 0.001 | C17: =C5 - '+0.0 seg'!$C$5 -> 0.006 | D17: =D5 - '+0.0 seg'!$D$5 -> 0.004 | E17: =E5 - '+0.0 seg'!$E$5 -> 0 | F17: =F5 - '+0.0 seg'!$F$5 -> 0.002 | G17: =G5 - '+0.0 seg'!$G$5 -> -0.007 | H17: =H5 - '+0.0 seg'!$H$5 -> 0.003 | I17: =I5 - '+0.0 seg'!$I$5 -> -0.006 | J17: =J5 - '+0.0 seg'!$J$5 -> -0.001 | K17: =K5 - '+0.0 seg'!$K$5 -> 0 | L17: =L5 - '+0.0 seg'!$L$5 -> 0 | M17: =M5 - '+0.0 seg'!$M$5 -> 0
A18: D | B18: =B6 - '+0.0 seg'!$B$6 -> 0.004 | C18: =C6 - '+0.0 seg'!$C$6 -> 0.004 | D18: =D6 - '+0.0 seg'!$D$6 -> 0.001 | E18: =E6 - '+0.0 seg'!$E$6 -> 0 | F18: =F6 - '+0.0 seg'!$F$6 -> 0.003 | G18: =G6 - '+0.0 seg'!$G$6 -> 0.01 | H18: =H6 - '+0.0 seg'!$H$6 -> 0.004 | I18: =I6 - '+0.0 seg'!$I$6 -> 0 | J18: =J6 - '+0.0 seg'!$J$6 -> 0 | K18: =K6 - '+0.0 seg'!$K$6 -> 0 | L18: =L6 - '+0.0 seg'!$L$6 -> 0 | M18: =M6 - '+0.0 seg'!$M$6 -> 0
A19: E | B19: =B7 - '+0.0 seg'!$B$7 -> 0.002 | C19: =C7 - '+0.0 seg'!$C$7 -> 0.001 | D19: =D7 - '+0.0 seg'!$D$7 -> 0.003 | E19: =E7 - '+0.0 seg'!$E$7 -> 0.003 | F19: =F7 - '+0.0 seg'!$F$7 -> 0.007 | G19: =G7 - '+0.0 seg'!$G$7 -> 0.008 | H19: =H7 - '+0.0 seg'!$H$7 -> 0.007 | I19: =I7 - '+0.0 seg'!$I$7 -> -0.005 | J19: =J7 - '+0.0 seg'!$J$7 -> -0.001 | K19: =K7 - '+0.0 seg'!$K$7 -> 0 | L19: =L7 - '+0.0 seg'!$L$7 -> 0.006 | M19: =M7 - '+0.0 seg'!$M$7 -> 0
A20: F | B20: =B8 - '+0.0 seg'!$B$8 -> 0.005 | C20: =C8 - '+0.0 seg'!$C$8 -> 0.003 | D20: =D8 - '+0.0 seg'!$D$8 -> -0.003 | E20: =E8 - '+0.0 seg'!$E$8 -> 0.001 | F20: =F8 - '+0.0 seg'!$F$8 -> 0.005 | G20: =G8 - '+0.0 seg'!$G$8 -> 0.002 | H20: =H8 - '+0.0 seg'!$H$8 -> 0.003 | I20: =I8 - '+0.0 seg'!$I$8 -> -0.001 | J20: =J8 - '+0.0 seg'!$J$8 -> -0.001 | K20: =K8 - '+0.0 seg'!$K$8 -> 0 | L20: =L8 - '+0.0 seg'!$L$8 -> -0.001 | M20: =M8 - '+0.0 seg'!$M$8 -> 0
A21: G | B21: =B9 - '+0.0 seg'!$B$9 -> 0.002 | C21: =C9 - '+0.0 seg'!$C$9 -> 0.006 | D21: =D9 - '+0.0 seg'!$D$9 -> 0.003 | E21: =E9 - '+0.0 seg'!$E$9 -> 0.002 | F21: =F9 - '+0.0 seg'!$F$9 -> 0.003 | G21: =G9 - '+0.0 seg'!$G$9 -> 0.006 | H21: =H9 - '+0.0 seg'!$H$9 -> 0.001 | I21: =I9 - '+0.0 seg'!$I$9 -> 0 | J21: =J9 - '+0.0 seg'!$J$9 -> 0 | K21: =K9 - '+0.0 seg'!$K$9 -> 0.001 | L21: =L9 - '+0.0 seg'!$L$9 -> 0 | M21: =M9 - '+0.0 seg'!$M$9 -> 0
A22: H | B22: =B10 - '+0.0 seg'!$B$10 -> -0.014 | C22: =C10 - '+0.0 seg'!$C$10 -> 0.016 | D22: =D10 - '+0.0 seg'!$D$10 -> -0.001 | E22: =E10 - '+0.0 seg'!$E$10 -> 0 | F22: =F10 - '+0.0 seg'!$F$10 -> 0.017 | G22: =G10 - '+0.0 seg'!$G$10 -> 0.006 | H22: =H10 - '+0.0 seg'!$H$10 -> 0.001 | I22: =I10 - '+0.0 seg'!$I$10 -> 0.001 | J22: =J10 - '+0.0 seg'!$J$10 -> 0 | K22: =K10 - '+0.0 seg'!$K$10 -> 0 | L22: =L10 - '+0.0 seg'!$L$10 -> 0 | M22: =M10 - '+0.0 seg'!$M$10 -> 0.001
A25: * | B25: Mean 1-2 | C25: DE 1-2 | D25: Mean 3-4 | E25: DE 3-4 | F25: Mean 5-6 | G25: DE 5-6 | H25: Mean 7-8 | I25: DE 7-8 | J25: Mean 9-10 | K25: DE 9-10 | L25: Mean 11-12 | M25: DE 11-12
A26: A | B26: =AVERAGE(B15:C15) -> 0.002 | C26: =STDEV(B15:C15) -> 9.8130779e-18 | D26: =AVERAGE(D15:E15) -> 0.0045 | E26: =STDEV(D15:E15) -> 0.00070710678 | F26: =AVERAGE(F15:G15) -> 0.0005 | G26: =STDEV(F15:G15) -> 0.0035355339 | H26: =AVERAGE(H15:I15) -> 0.0005 | I26: =STDEV(H15:I15) -> 0.00070710678 | J26: =AVERAGE(J15:K15) -> -0.002 | K26: =STDEV(J15:K15) -> 0.0028284271 | L26: =AVERAGE(L15:M15) -> 0 | M26: =STDEV(L15:M15) -> 0
A27: B | B27: =AVERAGE(B16:C16) -> 0.0005 | C27: =STDEV(B16:C16) -> 0.00070710678 | D27: =AVERAGE(D16:E16) -> 0.0025 | E27: =STDEV(D16:E16) -> 0.00070710678 | F27: =AVERAGE(F16:G16) -> 0.004 | G27: =STDEV(F16:G16) -> 0.0014142136 | H27: =AVERAGE(H16:I16) -> 0.004 | I27: =STDEV(H16:I16) -> 0.0014142136 | J27: =AVERAGE(J16:K16) -> 0.0005 | K27: =STDEV(J16:K16) -> 0.0021213203 | L27: =AVERAGE(L16:M16) -> -0.0005 | M27: =STDEV(L16:M16) -> 0.00070710678
A28: C | B28: =AVERAGE(B17:C17) -> 0.0035 | C28: =STDEV(B17:C17) -> 0.0035355339 | D28: =AVERAGE(D17:E17) -> 0.002 | E28: =STDEV(D17:E17) -> 0.0028284271 | F28: =AVERAGE(F17:G17) -> -0.0025 | G28: =STDEV(F17:G17) -> 0.006363961 | H28: =AVERAGE(H17:I17) -> -0.0015 | I28: =STDEV(H17:I17) -> 0.006363961 | J28: =AVERAGE(J17:K17) -> -0.0005 | K28: =STDEV(J17:K17) -> 0.00070710678 | L28: =AVERAGE(L17:M17) -> 0 | M28: =STDEV(L17:M17) -> 0
A29: D | B29: =AVERAGE(B18:C18) -> 0.004 | C29: =STDEV(B18:C18) -> 1.9626156e-17 | D29: =AVERAGE(D18:E18) -> 0.0005 | E29: =STDEV(D18:E18) -> 0.00070710678 | F29: =AVERAGE(F18:G18) -> 0.0065 | G29: =STDEV(F18:G18) -> 0.0049497475 | H29: =AVERAGE(H18:I18) -> 0.002 | I29: =STDEV(H18:I18) -> 0.0028284271 | J29: =AVERAGE(J18:K18) -> 0 | K29: =STDEV(J18:K18) -> 0 | L29: =AVERAGE(L18:M18) -> 0 | M29: =STDEV(L18:M18) -> 0
A30: E | B30: =AVERAGE(B19:C19) -> 0.0015 | C30: =STDEV(B19:C19) -> 0.00070710678 | D30: =AVERAGE(D19:E19) -> 0.003 | E30: =STDEV(D19:E19) -> 0 | F30: =AVERAGE(F19:G19) -> 0.0075 | G30: =STDEV(F19:G19) -> 0.00070710678 | H30: =AVERAGE(H19:I19) -> 0.001 | I30: =STDEV(H19:I19) -> 0.0084852814 | J30: =AVERAGE(J19:K19) -> -0.0005 | K30: =STDEV(J19:K19) -> 0.00070710678 | L30: =AVERAGE(L19:M19) -> 0.003 | M30: =STDEV(L19:M19) -> 0.0042426407
A31: F | B31: =AVERAGE(B20:C20) -> 0.004 | C31: =STDEV(B20:C20) -> 0.0014142136 | D31: =AVERAGE(D20:E20) -> -0.001 | E31: =STDEV(D20:E20) -> 0.0028284271 | F31: =AVERAGE(F20:G20) -> 0.0035 | G31: =STDEV(F20:G20) -> 0.0021213203 | H31: =AVERAGE(H20:I20) -> 0.001 | I31: =STDEV(H20:I20) -> 0.0028284271 | J31: =AVERAGE(J20:K20) -> -0.0005 | K31: =STDEV(J20:K20) -> 0.00070710678 | L31: =AVERAGE(L20:M20) -> -0.0005 | M31: =STDEV(L20:M20) -> 0.00070710678
A32: G | B32: =AVERAGE(B21:C21) -> 0.004 | C32: =STDEV(B21:C21) -> 0.0028284271 | D32: =AVERAGE(D21:E21) -> 0.0025 | E32: =STDEV(D21:E21) -> 0.00070710678 | F32: =AVERAGE(F21:G21) -> 0.0045 | G32: =STDEV(F21:G21) -> 0.0021213203 | H32: =AVERAGE(H21:I21) -> 0.0005 | I32: =STDEV(H21:I21) -> 0.00070710678 | J32: =AVERAGE(J21:K21) -> 0.0005 | K32: =STDEV(J21:K21) -> 0.00070710678 | L32: =AVERAGE(L21:M21) -> 0 | M32: =STDEV(L21:M21) -> 0
