Workbook

Sheet Grilla
C3: LL01-pH3,8 | D3: LL01-pH3,84 | E3: LL01-pH7,4 | F3: LL01-pH7,4 | G3: LL02-pH3,8 | H3: LL02-pH3,84 | I3: LL02-pH7,4 | J3: LL02-pH7,4 | K3: Blanco-pH3,8 | L3: Blanco-pH7,4
C4: 1 | D4: 2 | E4: 3 | F4: 4 | G4: 5 | H4: 6 | I4: 7 | J4: 8 | K4: 9 | L4: 10 | M4: 11 | N4: 12
B5: a | C5: 80μl buffer 3,8 5μl NP LL01 15μlH2O 50μl ABTS 1/5 50μl H2O2 2/5 | D5: 80μl buffer 3,8 5μl NP LL01 15μlH2O 50μl ABTS 1/5 50μl H2O2 2/5 | E5: 80μl buffer 7,4 5μl NP LL01 15μlH2O 50μl ABTS 1/5 50μl H2O2 2/5 | F5: 80μl buffer 7,4 5μl NP LL01 15μlH2O 50μl ABTS 1/5 50μl H2O2 2/5 | G5: 80μl buffer 3,8 5μl NP LL02 15μl H2O 50μl ABTS 1/5 50μl H2O2 2/5 | H5: 80μl buffer 3,8 5μl NP LL02 15μl H2O 50μl ABTS 1/5 50μl H2O2 2/5 | I5: 80μl buffer 7,4 5μl NP LL02 15μl H2O 50μl ABTS 1/5 50μl H2O2 2/5 | J5: 80μl buffer 7,4 5μl NP LL02 15μl H2O 50μl ABTS 1/5 50μl H2O2 2/5 | K5: 80μl buffer 3,8 20μlH2O 50μl ABTS 1/5 50μl H2O2 2/5 | L5: 80μl buffer 7,4 20μlH2O 50μl ABTS 1/5 50μl H2O2 2/5
B6: b | C6: 80μl buffer 3,8 10μl NP LL01 10μlH2O 50μl ABTS 1/10 50μl H2O2 2/10 | D6: 80μl buffer 3,8 10μl NP LL01 10μlH2O 50μl ABTS 1/10 50μl H2O2 2/10 | E6: 80μl buffer 7,4 10μl NP LL01 10μlH2O 50μl ABTS 1/10 50μl H2O2 2/10 | F6: 80μl buffer 7,4 10μl NP LL01 10μlH2O 50μl ABTS 1/10 50μl H2O2 2/10 | G6: 80μl buffer 3,8 10μl NP LL02 10μl H2O 50μl ABTS 1/10 50μl H2O2 2/10 | H6: 80μl buffer 3,8 10μl NP LL02 10μl H2O 50μl ABTS 1/10 50μl H2O2 2/10 | I6: 80μl buffer 7,4 10μl NP LL02 10μl H2O 50μl ABTS 1/10 50μl H2O2 2/10 | J6: 80μl buffer 7,4 10μl NP LL02 10μl H2O 50μl ABTS 1/10 50μl H2O2 2/10 | K6: 80μl buffer 3,8 20μlH2O 50μl ABTS 1/5 50μl H2O2 2/5 | L6: 80μl buffer 7,4 20μlH2O 50μl ABTS 1/5 50μl H2O2 2/5
B7: c | C7: 80μl buffer 3,8 15μl NP LL01 5μlH2O 500μl ABTS 1/50 500μl H2O2 2/50 | D7: 80μl buffer 3,8 15μl NP LL01 5μlH2O 500μl ABTS 1/50 500μl H2O2 2/50 | E7: 80μl buffer 7,4 15μl NP LL01 5μlH2O 500μl ABTS 1/50 500μl H2O2 2/50 | F7: 80μl buffer 7,4 15μl NP LL01 5μlH2O 500μl ABTS 1/50 500μl H2O2 2/50 | G7: 80μl buffer 3,8 15μl NP LL02 5μl H2O 500μl ABTS 1/50 500μl H2O2 2/50 | H7: 80μl buffer 3,8 15μl NP LL02 5μl H2O 500μl ABTS 1/50 500μl H2O2 2/50 | I7: 80μl buffer 7,4 15μl NP LL02 5μl H2O 500μl ABTS 1/50 500μl H2O2 2/50 | J7: 80μl buffer 7,4 15μl NP LL02 5μl H2O 500μl ABTS 1/50 500μl H2O2 2/50
B8: d | C8: 80μl buffer 3,8 20μl NP LL01 0μlH2O 50μl ABTS 1/20 50μl H2O2 2/20 | D8: 80μl buffer 3,8 20μl NP LL01 0μlH2O 50μl ABTS 1/20 50μl H2O2 2/20 | E8: 80μl buffer 7,4 20μl NP LL01 0μlH2O 50μl ABTS 1/20 50μl H2O2 2/20 | F8: 80μl buffer 7,4 20μl NP LL01 0μlH2O 50μl ABTS 1/20 50μl H2O2 2/20 | G8: 80μl buffer 3,8 20μl NP LL02 0μl H2O 50μl ABTS 1/20 50μl H2O2 2/20 | H8: 80μl buffer 3,8 20μl NP LL02 0μl H2O 50μl ABTS 1/20 50μl H2O2 2/20 | I8: 80μl buffer 7,4 20μl NP LL02 0μl H2O 50μl ABTS 1/20 50μl H2O2 2/20 | J8: 80μl buffer 7,4 20μl NP LL02 0μl H2O 50μl ABTS 1/20 50μl H2O2 2/20
B9: e | C9: 130μl buffer 3,8 5μl NP LL01 15μl H2O 50μl ABTS 1/5 | D9: 130μl buffer 3,8 5μl NP LL01 15μl H2O 50μl ABTS 1/5 | E9: 130μl buffer 7,4 5μl NP LL01 15μl H2O 50μl ABTS 1/5 | F9: 130μl buffer 7,4 5μl NP LL01 15μl H2O 50μl ABTS 1/5 | G9: 130μl buffer 3,8 5μl NP LL02 15μl H2O 50μl ABTS 1/5 | H9: 130μl buffer 3,8 5μl NP LL02 15μl H2O 50μl ABTS 1/5 | I9: 130μl buffer 7,4 5μl NP LL02 15μl H2O 50μl ABTS 1/5 | J9: 130μl buffer 7,4 5μl NP LL02 15μl H2O 50μl ABTS 1/5 | K9: 130μl buffer 3,8 20μl H2O 50μl ABTS 1/5 | L9: 130μl buffer 7,4 20μl H2O 50μl ABTS 1/5
B10: f | C10: 130μl buffer 3,8 10μl NP LL01 10μl H2O 50μl ABTS 1/10 | D10: 130μl buffer 3,8 10μl NP LL01 10μl H2O 50μl ABTS 1/10 | E10: 130μl buffer 7,4 10μl NP LL01 10μl H2O 50μl ABTS 1/10 | F10: 130μl buffer 7,4 10μl NP LL01 10μl H2O 50μl ABTS 1/10 | G10: 130μl buffer 3,8 10μl NP LL02 10μl H2O 50μl ABTS 1/10 | H10: 130μl buffer 3,8 10μl NP LL02 10μl H2O 50μl ABTS 1/10 | I10: 130μl buffer 7,4 10μl NP LL02 10μl H2O 50μl ABTS 1/10 | J10: 130μl buffer 7,4 10μl NP LL02 10μl H2O 50μl ABTS 1/10 | K10: 130μl buffer 3,8 20μl H2O 50μl ABTS 1/5 | L10: 130μl buffer 7,4 20μl H2O 50μl ABTS 1/5
B11: g | C11: 130μl buffer 3,8 15μl NP LL01 5μl H2O 500μl ABTS 1/50 | D11: 130μl buffer 3,8 15μl NP LL01 5μl H2O 500μl ABTS 1/50 | E11: 130μl buffer 7,4 15μl NP LL01 5μl H2O 500μl ABTS 1/50 | F11: 130μl buffer 7,4 15μl NP LL01 5μl H2O 500μl ABTS 1/50 | G11: 130μl buffer 3,8 15μl NP LL02 5μl H2O 500μl ABTS 1/50 | H11: 130μl buffer 3,8 15μl NP LL02 5μl H2O 500μl ABTS 1/50 | I11: 130μl buffer 7,4 15μl NP LL02 5μl H2O 500μl ABTS 1/50 | J11: 130μl buffer 7,4 15μl NP LL02 5μl H2O 500μl ABTS 1/50
B12: h | C12: 130μl buffer 3,8 20μl NP LL01 0μl H2O 50μl ABTS 1/20 | D12: 130μl buffer 3,8 20μl NP LL01 0μl H2O 50μl ABTS 1/20 | E12: 130μl buffer 7,4 20μl NP LL01 0μl H2O 50μl ABTS 1/20 | F12: 130μl buffer 7,4 20μl NP LL01 0μl H2O 50μl ABTS 1/20 | G12: 130μl buffer 3,8 20μl NP LL02 0μl H2O 50μl ABTS 1/20 | H12: 130μl buffer 3,8 20μl NP LL02 0μl H2O 50μl ABTS 1/20 | I12: 130μl buffer 7,4 20μl NP LL02 0μl H2O 50μl ABTS 1/20 | J12: 130μl buffer 7,4 20μl NP LL02 0μl H2O 50μl ABTS 1/20

Sheet Análisis
B4: Tiempo | C4: A1 | D4: errA1 | E4: A3 | F4: errA3 | G4: A5 | H4: errA5 | I4: A7 | J4: errA7 | K4: Blanco 9 | L4: errA9 | O4: B1 | P4: errB1 | Q4: B3 | R4: errB3 | S4: B5 | T4: errB5 | U4: B7 | V4: errB7 | W4: Blanco A10 | X4: errA10
B5: 0 | C5: ='+0 seg'!$B$26 -> 0 | D5: ='+0 seg'!$C$26 -> 0 | E5: ='+0 seg'!$D$26 -> 0 | F5: ='+0 seg'!$E$26 -> 0 | G5: ='+0 seg'!$F$26 -> 0 | H5: ='+0 seg'!$G$26 -> 0 | I5: ='+0 seg'!$H$26 -> 0 | J5: ='+0 seg'!$I$26 -> 0 | K5: ='+0 seg'!$J$26 -> 0 | L5: ='+0 seg'!$K$26 -> 0 | O5: ='+0 seg'!$B$27 -> 0 | P5: ='+0 seg'!$C$27 -> 0 | Q5: ='+0 seg'!$D$27 -> 0 | R5: ='+0 seg'!$E$27 -> 0 | S5: ='+0 seg'!$F$27 -> 0 | T5: ='+0 seg'!$G$27 -> 0 | U5: ='+0 seg'!$H$27 -> 0 | V5: ='+0 seg'!$I$27 -> 0 | W5: ='+0 seg'!$L$26 -> 0 | X5: ='+0 seg'!$M$26 -> 0
B6: 23 | C6: ='+23 seg'!$B$26 -> 0.0005 | D6: ='+23 seg'!$C$26 -> 0.00070710678 | E6: ='+23 seg'!$D$26 -> -0.0005 | F6: ='+23 seg'!$E$26 -> 0.0021213203 | G6: ='+23 seg'!$F$26 -> -0.0005 | H6: ='+23 seg'!$G$26 -> 0.00070710678 | I6: ='+23 seg'!$H$26 -> -0.001 | J6: ='+23 seg'!$I$26 -> 0 | K6: ='+23 seg'!$J$26 -> -0.0005 | L6: ='+23 seg'!$K$26 -> 0.00070710678 | O6: ='+23 seg'!$B$27 -> 0 | P6: ='+23 seg'!$C$27 -> 0 | Q6: ='+23 seg'!$D$27 -> 0.0045 | R6: ='+23 seg'!$E$27 -> 0.0035355339 | S6: ='+23 seg'!$F$27 -> 0.002 | T6: ='+23 seg'!$G$27 -> 0 | U6: ='+23 seg'!$H$27 -> 0.0015 | V6: ='+23 seg'!$I$27 -> 0.00070710678 | W6: ='+23 seg'!$L$26 -> -0.001 | X6: ='+23 seg'!$M$26 -> 0.0014142136
B7: 42 | C7: ='+42 seg'!$B$26 -> 0.0005 | D7: ='+42 seg'!$C$26 -> 0.00070710678 | E7: ='+42 seg'!$D$26 -> 0.0025 | F7: ='+42 seg'!$E$26 -> 0.00070710678 | G7: ='+42 seg'!$F$26 -> -0.002 | H7: ='+42 seg'!$G$26 -> 0.0042426407 | I7: ='+42 seg'!$H$26 -> -0.0005 | J7: ='+42 seg'!$I$26 -> 0.00070710678 | K7: ='+42 seg'!$J$26 -> -0.0005 | L7: ='+42 seg'!$K$26 -> 0.00070710678 | O7: ='+42 seg'!$B$27 -> 0 | P7: ='+42 seg'!$C$27 -> 0 | Q7: ='+42 seg'!$D$27 -> 0.0055 | R7: ='+42 seg'!$E$27 -> 0.0035355339 | S7: ='+42 seg'!$F$27 -> 0.0015 | T7: ='+42 seg'!$G$27 -> 0.00070710678 | U7: ='+42 seg'!$H$27 -> 0.003 | V7: ='+42 seg'!$I$27 -> 0 | W7: ='+42 seg'!$L$26 -> -0.002 | X7: ='+42 seg'!$M$26 -> 0.0028284271
B8: 61 | C8: ='+61 seg'!$B$26 -> 0 | D8: ='+61 seg'!$C$26 -> 0 | E8: ='+61 seg'!$D$26 -> 0.002 | F8: ='+61 seg'!$E$26 -> 0 | G8: ='+61 seg'!$F$26 -> -0.0015 | H8: ='+61 seg'!$G$26 -> 0.0035355339 | I8: ='+61 seg'!$H$26 -> 0 | J8: ='+61 seg'!$I$26 -> 0 | K8: ='+61 seg'!$J$26 -> 0 | L8: ='+61 seg'!$K$26 -> 0 | O8: ='+61 seg'!$B$27 -> 0 | P8: ='+61 seg'!$C$27 -> 0 | Q8: ='+61 seg'!$D$27 -> 0.0035 | R8: ='+61 seg'!$E$27 -> 0.00070710678 | S8: ='+61 seg'!$F$27 -> 0.003 | T8: ='+61 seg'!$G$27 -> 0.0014142136 | U8: ='+61 seg'!$H$27 -> 0.0035 | V8: ='+61 seg'!$I$27 -> 0.00070710678 | W8: ='+61 seg'!$L$26 -> -0.0015 | X8: ='+61 seg'!$M$26 -> 0.0035355339
B9: 81 | C9: ='+81 seg'!$B$26 -> 0.001 | D9: ='+81 seg'!$C$26 -> 9.8130779e-18 | E9: ='+81 seg'!$D$26 -> 0.0035 | F9: ='+81 seg'!$E$26 -> 0.00070710678 | G9: ='+81 seg'!$F$26 -> -0.001 | H9: ='+81 seg'!$G$26 -> 0.0042426407 | I9: ='+81 seg'!$H$26 -> 0 | J9: ='+81 seg'!$I$26 -> 0 | K9: ='+81 seg'!$J$26 -> -0.001 | L9: ='+81 seg'!$K$26 -> 4.9065389e-18 | O9: ='+81 seg'!$B$27 -> 0.001 | P9: ='+81 seg'!$C$27 -> 1.9626156e-17 | Q9: ='+81 seg'!$D$27 -> 0.003 | R9: ='+81 seg'!$E$27 -> 9.8130779e-18 | S9: ='+81 seg'!$F$27 -> 0.003 | T9: ='+81 seg'!$G$27 -> 0.0014142136 | U9: ='+81 seg'!$H$27 -> 0.004 | V9: ='+81 seg'!$I$27 -> 0.0014142136 | W9: ='+81 seg'!$L$26 -> -0.0015 | X9: ='+81 seg'!$M$26 -> 0.0035355339
B10: 101 | C10: ='+101 seg'!$B$26 -> 0.002 | D10: ='+101 seg'!$C$26 -> 0.0014142136 | E10: ='+101 seg'!$D$26 -> 0.0015 | F10: ='+101 seg'!$E$26 -> 0.0021213203 | G10: ='+101 seg'!$F$26 -> -6.9388939e-18 | H10: ='+101 seg'!$G$26 -> 0.0042426407 | I10: ='+101 seg'!$H$26 -> 0.0005 | J10: ='+101 seg'!$I$26 -> 0.00070710678 | K10: ='+101 seg'!$J$26 -> 0.001 | L10: ='+101 seg'!$K$26 -> 0.0028284271 | O10: ='+101 seg'!$B$27 -> 0.001 | P10: ='+101 seg'!$C$27 -> 1.9626156e-17 | Q10: ='+101 seg'!$D$27 -> 0.004 | R10: ='+101 seg'!$E$27 -> 9.8130779e-18 | S10: ='+101 seg'!$F$27 -> 0.004 | T10: ='+101 seg'!$G$27 -> 0.0014142136 | U10: ='+101 seg'!$H$27 -> 0.0045 | V10: ='+101 seg'!$I$27 -> 0.0021213203 | W10: ='+101 seg'!$L$26 -> -0.0015 | X10: ='+101 seg'!$M$26 -> 0.0035355339
B11: 120 | C11: ='+120 seg'!$B$26 -> 0.002 | D11: ='+120 seg'!$C$26 -> 9.8130779e-18 | E11: ='+120 seg'!$D$26 -> 0.0045 | F11: ='+120 seg'!$E$26 -> 0.00070710678 | G11: ='+120 seg'!$F$26 -> 0.0005 | H11: ='+120 seg'!$G$26 -> 0.0035355339 | I11: ='+120 seg'!$H$26 -> 0.0005 | J11: ='+120 seg'!$I$26 -> 0.00070710678 | K11: ='+120 seg'!$J$26 -> -0.0005 | L11: ='+120 seg'!$K$26 -> 0.00070710678 | O11: ='+120 seg'!$B$27 -> 0.0005 | P11: ='+120 seg'!$C$27 -> 0.00070710678 | Q11: ='+120 seg'!$D$27 -> 0.0025 | R11: ='+120 seg'!$E$27 -> 0.00070710678 | S11: ='+120 seg'!$F$27 -> 0.004 | T11: ='+120 seg'!$G$27 -> 0.0014142136 | U11: ='+120 seg'!$H$27 -> 0.004 | V11: ='+120 seg'!$I$27 -> 0.0014142136 | W11: ='+120 seg'!$L$26 -> -0.001 | X11: ='+120 seg'!$M$26 -> 0.0042426407
B12: 140 | C12: ='+140 seg'!$B$26 -> 0.001 | D12: ='+140 seg'!$C$26 -> 0.0014142136 | E12: ='+140 seg'!$D$26 -> 6.9388939e-18 | F12: ='+140 seg'!$E$26 -> 0.0070710678 | G12: ='+140 seg'!$F$26 -> 0.0015 | H12: ='+140 seg'!$G$26 -> 0.0035355339 | I12: ='+140 seg'!$H$26 -> 0.0005 | J12: ='+140 seg'!$I$26 -> 0.00070710678 | K12: ='+140 seg'!$J$26 -> 0.0005 | L12: ='+140 seg'!$K$26 -> 0.00070710678 | O12: ='+140 seg'!$B$27 -> 0.001 | P12: ='+140 seg'!$C$27 -> 1.9626156e-17 | Q12: ='+140 seg'!$D$27 -> 0.003 | R12: ='+140 seg'!$E$27 -> 9.8130779e-18 | S12: ='+140 seg'!$F$27 -> 0.004 | T12: ='+140 seg'!$G$27 -> 0.0014142136 | U12: ='+140 seg'!$H$27 -> 0.0045 | V12: ='+140 seg'!$I$27 -> 0.0021213203 | W12: ='+140 seg'!$L$26 -> -0.001 | X12: ='+140 seg'!$M$26 -> 0.0042426407
B13: 158 | C13: ='+158 seg'!$B$26 -> 0.0025 | D13: ='+158 seg'!$C$26 -> 0.00070710678 | E13: ='+158 seg'!$D$26 -> 0.0065 | F13: ='+158 seg'!$E$26 -> 0.00070710678 | G13: ='+158 seg'!$F$26 -> 0.0025 | H13: ='+158 seg'!$G$26 -> 0.0035355339 | I13: ='+158 seg'!$H$26 -> 0.001 | J13: ='+158 seg'!$I$26 -> 0.0014142136 | K13: ='+158 seg'!$J$26 -> -0.0005 | L13: ='+158 seg'!$K$26 -> 0.00070710678 | O13: ='+158 seg'!$B$27 -> 0.002 | P13: ='+158 seg'!$C$27 -> 1.9626156e-17 | Q13: ='+158 seg'!$D$27 -> 0.005 | R13: ='+158 seg'!$E$27 -> 0.0014142136 | S13: ='+158 seg'!$F$27 -> 0.005 | T13: ='+158 seg'!$G$27 -> 0.0014142136 | U13: ='+158 seg'!$H$27 -> 0.0045 | V13: ='+158 seg'!$I$27 -> 0.0021213203 | W13: ='+158 seg'!$L$26 -> -0.001 | X13: ='+158 seg'!$M$26 -> 0.0042426407
B14: 178 | C14: ='+178 seg'!$B$26 -> 0.0035 | D14: ='+178 seg'!$C$26 -> 0.00070710678 | E14: ='+178 seg'!$D$26 -> 6.9388939e-18 | F14: ='+178 seg'!$E$26 -> 0.0098994949 | G14: ='+178 seg'!$F$26 -> 0.003 | H14: ='+178 seg'!$G$26 -> 0.0042426407 | I14: ='+178 seg'!$H$26 -> 0.002 | J14: ='+178 seg'!$I$26 -> 0.0014142136 | K14: ='+178 seg'!$J$26 -> -0.0005 | L14: ='+178 seg'!$K$26 -> 0.00070710678 | O14: ='+178 seg'!$B$27 -> 0.0015 | P14: ='+178 seg'!$C$27 -> 0.00070710678 | Q14: ='+178 seg'!$D$27 -> 0.004 | R14: ='+178 seg'!$E$27 -> 0.0014142136 | S14: ='+178 seg'!$F$27 -> 0.005 | T14: ='+178 seg'!$G$27 -> 0.0014142136 | U14: ='+178 seg'!$H$27 -> 0.0045 | V14: ='+178 seg'!$I$27 -> 0.0021213203 | W14: ='+178 seg'!$L$26 -> -0.001 | X14: ='+178 seg'!$M$26 -> 0.0042426407
B15: 198 | C15: ='+198 seg'!$B$26 -> 0.0035 | D15: ='+198 seg'!$C$26 -> 0.0021213203 | E15: ='+198 seg'!$D$26 -> 0.008 | F15: ='+198 seg'!$E$26 -> 0.0014142136 | G15: ='+198 seg'!$F$26 -> 0.004 | H15: ='+198 seg'!$G$26 -> 0.0042426407 | I15: ='+198 seg'!$H$26 -> 0.002 | J15: ='+198 seg'!$I$26 -> 0.0014142136 | K15: ='+198 seg'!$J$26 -> -0.0005 | L15: ='+198 seg'!$K$26 -> 0.00070710678 | O15: ='+198 seg'!$B$27 -> 0.002 | P15: ='+198 seg'!$C$27 -> 0.0014142136 | Q15: ='+198 seg'!$D$27 -> 0.0045 | R15: ='+198 seg'!$E$27 -> 0.00070710678 | S15: ='+198 seg'!$F$27 -> 0.005 | T15: ='+198 seg'!$G$27 -> 0 | U15: ='+198 seg'!$H$27 -> 0.0045 | V15: ='+198 seg'!$I$27 -> 0.0021213203 | W15: ='+198 seg'!$L$26 -> -0.001 | X15: ='+198 seg'!$M$26 -> 0.0042426407
B16: 219 | C16: ='+219 seg'!$B$26 -> 0.004 | D16: ='+219 seg'!$C$26 -> 0.0014142136 | E16: ='+219 seg'!$D$26 -> 0.006 | F16: ='+219 seg'!$E$26 -> 0.0028284271 | G16: ='+219 seg'!$F$26 -> 0.005 | H16: ='+219 seg'!$G$26 -> 0.0042426407 | I16: ='+219 seg'!$H$26 -> 0.002 | J16: ='+219 seg'!$I$26 -> 0 | K16: ='+219 seg'!$J$26 -> -0.0005 | L16: ='+219 seg'!$K$26 -> 0.00070710678 | O16: ='+219 seg'!$B$27 -> 0.0025 | P16: ='+219 seg'!$C$27 -> 0.00070710678 | Q16: ='+219 seg'!$D$27 -> 0.004 | R16: ='+219 seg'!$E$27 -> 9.8130779e-18 | S16: ='+219 seg'!$F$27 -> 0.005 | T16: ='+219 seg'!$G$27 -> 0 | U16: ='+219 seg'!$H$27 -> 0.005 | V16: ='+219 seg'!$I$27 -> 0.0028284271 | W16: ='+219 seg'!$L$26 -> -0.001 | X16: ='+219 seg'!$M$26 -> 0.0042426407
B17: 238 | C17: ='+238 seg'!$B$26 -> 0.0045 | D17: ='+238 seg'!$C$26 -> 0.00070710678 | E17: ='+238 seg'!$D$26 -> 0.006 | F17: ='+238 seg'!$E$26 -> 0.0028284271 | G17: ='+238 seg'!$F$26 -> 0.006 | H17: ='+238 seg'!$G$26 -> 0.0042426407 | I17: ='+238 seg'!$H$26 -> 0.0025 | J17: ='+238 seg'!$I$26 -> 0.00070710678 | K17: ='+238 seg'!$J$26 -> 0 | L17: ='+238 seg'!$K$26 -> 0.0014142136 | O17: ='+238 seg'!$B$27 -> 0.0035 | P17: ='+238 seg'!$C$27 -> 0.00070710678 | Q17: ='+238 seg'!$D$27 -> 0.003 | R17: ='+238 seg'!$E$27 -> 9.8130779e-18 | S17: ='+238 seg'!$F$27 -> 0.0045 | T17: ='+238 seg'!$G$27 -> 0.00070710678 | U17: ='+238 seg'!$H$27 -> 0.0045 | V17: ='+238 seg'!$I$27 -> 0.0021213203 | W17: ='+238 seg'!$L$26 -> -0.0005 | X17: ='+238 seg'!$M$26 -> 0.0049497475
B18: 260 | C18: ='+260 seg'!$B$26 -> 0.004 | D18: ='+260 seg'!$C$26 -> 0.0014142136 | E18: ='+260 seg'!$D$26 -> 0.0055 | F18: ='+260 seg'!$E$26 -> 0.0049497475 | G18: ='+260 seg'!$F$26 -> 0.0075 | H18: ='+260 seg'!$G$26 -> 0.0035355339 | I18: ='+260 seg'!$H$26 -> 0.003 | J18: ='+260 seg'!$I$26 -> 0.0014142136 | K18: ='+260 seg'!$J$26 -> -0.0005 | L18: ='+260 seg'!$K$26 -> 0.00070710678 | O18: ='+260 seg'!$B$27 -> 0.0025 | P18: ='+260 seg'!$C$27 -> 0.00070710678 | Q18: ='+260 seg'!$D$27 -> 0.0055 | R18: ='+260 seg'!$E$27 -> 0.0021213203 | S18: ='+260 seg'!$F$27 -> 0.0055 | T18: ='+260 seg'!$G$27 -> 0.00070710678 | U18: ='+260 seg'!$H$27 -> 0.0045 | V18: ='+260 seg'!$I$27 -> 0.0021213203 | W18: ='+260 seg'!$L$26 -> -0.001 | X18: ='+260 seg'!$M$26 -> 0.0042426407
B19: 279 | C19: ='+279 seg'!$B$26 -> 0.0045 | D19: ='+279 seg'!$C$26 -> 0.0021213203 | E19: ='+279 seg'!$D$26 -> 0.0025 | F19: ='+279 seg'!$E$26 -> 0.010606602 | G19: ='+279 seg'!$F$26 -> 0.008 | H19: ='+279 seg'!$G$26 -> 0.0042426407 | I19: ='+279 seg'!$H$26 -> 0.003 | J19: ='+279 seg'!$I$26 -> 0.0014142136 | K19: ='+279 seg'!$J$26 -> -0.0005 | L19: ='+279 seg'!$K$26 -> 0.00070710678 | O19: ='+279 seg'!$B$27 -> 0.0035 | P19: ='+279 seg'!$C$27 -> 0.00070710678 | Q19: ='+279 seg'!$D$27 -> 0.005 | R19: ='+279 seg'!$E$27 -> 0.0014142136 | S19: ='+279 seg'!$F$27 -> 0.0065 | T19: ='+279 seg'!$G$27 -> 0.00070710678 | U19: ='+279 seg'!$H$27 -> 0.005 | V19: ='+279 seg'!$I$27 -> 0.0028284271 | W19: ='+279 seg'!$L$26 -> -0.0005 | X19: ='+279 seg'!$M$26 -> 0.0049497475
B20: 300 | C20: ='+300 seg'!$B$26 -> 0.0055 | D20: ='+300 seg'!$C$26 -> 0.00070710678 | E20: ='+300 seg'!$D$26 -> 0.011 | F20: ='+300 seg'!$E$26 -> 0.0014142136 | G20: ='+300 seg'!$F$26 -> 0.0085 | H20: ='+300 seg'!$G$26 -> 0.0035355339 | I20: ='+300 seg'!$H$26 -> 0.003 | J20: ='+300 seg'!$I$26 -> 0.0014142136 | K20: ='+300 seg'!$J$26 -> -0.0005 | L20: ='+300 seg'!$K$26 -> 0.00070710678 | O20: ='+300 seg'!$B$27 -> 0.0055 | P20: ='+300 seg'!$C$27 -> 0.0021213203 | Q20: ='+300 seg'!$D$27 -> 0.005 | R20: ='+300 seg'!$E$27 -> 0.0014142136 | S20: ='+300 seg'!$F$27 -> 0.0065 | T20: ='+300 seg'!$G$27 -> 0.00070710678 | U20: ='+300 seg'!$H$27 -> 0.005 | V20: ='+300 seg'!$I$27 -> 0.0028284271 | W20: ='+300 seg'!$L$26 -> 3.469447e-18 | X20: ='+300 seg'!$M$26 -> 0.0042426407
B21: 326 | C21: ='+326 seg'!$B$26 -> 0.006 | D21: ='+326 seg'!$C$26 -> 0 | E21: ='+326 seg'!$D$26 -> 0.007 | F21: ='+326 seg'!$E$26 -> 0.0042426407 | G21: ='+326 seg'!$F$26 -> 0.009 | H21: ='+326 seg'!$G$26 -> 0.0042426407 | I21: ='+326 seg'!$H$26 -> 0.003 | J21: ='+326 seg'!$I$26 -> 0.0014142136 | K21: ='+326 seg'!$J$26 -> -0.0005 | L21: ='+326 seg'!$K$26 -> 0.00070710678 | O21: ='+326 seg'!$B$27 -> 0.004 | P21: ='+326 seg'!$C$27 -> 1.9626156e-17 | Q21: ='+326 seg'!$D$27 -> 0.006 | R21: ='+326 seg'!$E$27 -> 9.8130779e-18 | S21: ='+326 seg'!$F$27 -> 0.007 | T21: ='+326 seg'!$G$27 -> 0.0014142136 | U21: ='+326 seg'!$H$27 -> 0.006 | V21: ='+326 seg'!$I$27 -> 0.0028284271 | W21: ='+326 seg'!$L$26 -> 3.469447e-18 | X21: ='+326 seg'!$M$26 -> 0.0042426407
B22: 367 | C22: ='+367 seg'!$B$26 -> 0.0055 | D22: ='+367 seg'!$C$26 -> 0.00070710678 | E22: ='+367 seg'!$D$26 -> 0.01 | F22: ='+367 seg'!$E$26 -> 0 | G22: ='+367 seg'!$F$26 -> 0.0105 | H22: ='+367 seg'!$G$26 -> 0.0049497475 | I22: ='+367 seg'!$H$26 -> 0.003 | J22: ='+367 seg'!$I$26 -> 0.0014142136 | K22: ='+367 seg'!$J$26 -> 0 | L22: ='+367 seg'!$K$26 -> 0 | O22: ='+367 seg'!$B$27 -> 0.0075 | P22: ='+367 seg'!$C$27 -> 0.0049497475 | Q22: ='+367 seg'!$D$27 -> 0.0055 | R22: ='+367 seg'!$E$27 -> 0.0021213203 | S22: ='+367 seg'!$F$27 -> 0.0075 | T22: ='+367 seg'!$G$27 -> 0.00070710678 | U22: ='+367 seg'!$H$27 -> 0.006 | V22: ='+367 seg'!$I$27 -> 0.0028284271 | W22: ='+367 seg'!$L$26 -> 3.469447e-18 | X22: ='+367 seg'!$M$26 -> 0.0042426407
B23: 431 | C23: ='+431 seg'!$B$26 -> 0.0065 | D23: ='+431 seg'!$C$26 -> 0.00070710678 | E23: ='+431 seg'!$D$26 -> 0.0095 | F23: ='+431 seg'!$E$26 -> 0.0021213203 | G23: ='+431 seg'!$F$26 -> 0.011 | H23: ='+431 seg'!$G$26 -> 0.0056568542 | I23: ='+431 seg'!$H$26 -> 0.0025 | J23: ='+431 seg'!$I$26 -> 0.00070710678 | K23: ='+431 seg'!$J$26 -> -0.0005 | L23: ='+431 seg'!$K$26 -> 0.00070710678 | O23: ='+431 seg'!$B$27 -> 0.0075 | P23: ='+431 seg'!$C$27 -> 0.0049497475 | Q23: ='+431 seg'!$D$27 -> 0.006 | R23: ='+431 seg'!$E$27 -> 0.0014142136 | S23: ='+431 seg'!$F$27 -> 0.0085 | T23: ='+431 seg'!$G$27 -> 0.00070710678 | U23: ='+431 seg'!$H$27 -> 0.0065 | V23: ='+431 seg'!$I$27 -> 0.0035355339 | W23: ='+431 seg'!$L$26 -> 3.469447e-18 | X23: ='+431 seg'!$M$26 -> 0.0042426407
B24: 518 | C24: ='+518 seg'!$B$26 -> 0.007 | D24: ='+518 seg'!$C$26 -> 0 | E24: ='+518 seg'!$D$26 -> 0.009 | F24: ='+518 seg'!$E$26 -> 0.0028284271 | G24: ='+518 seg'!$F$26 -> 0.0125 | H24: ='+518 seg'!$G$26 -> 0.006363961 | I24: ='+518 seg'!$H$26 -> 0.003 | J24: ='+518 seg'!$I$26 -> 9.8130779e-18 | K24: ='+518 seg'!$J$26 -> -0.0005 | L24: ='+518 seg'!$K$26 -> 0.00070710678 | O24: ='+518 seg'!$B$27 -> 0.0055 | P24: ='+518 seg'!$C$27 -> 0.00070710678 | Q24: ='+518 seg'!$D$27 -> 0.0105 | R24: ='+518 seg'!$E$27 -> 0.0035355339 | S24: ='+518 seg'!$F$27 -> 0.01 | T24: ='+518 seg'!$G$27 -> 0.0014142136 | U24: ='+518 seg'!$H$27 -> 0.0065 | V24: ='+518 seg'!$I$27 -> 0.0035355339 | W24: ='+518 seg'!$L$26 -> 0.0005 | X24: ='+518 seg'!$M$26 -> 0.0049497475
B25: 549 | C25: ='+549 seg'!$B$26 -> 0.0075 | D25: ='+549 seg'!$C$26 -> 0.00070710678 | E25: ='+549 seg'!$D$26 -> 0.011 | F25: ='+549 seg'!$E$26 -> 0 | G25: ='+549 seg'!$F$26 -> 0.0135 | H25: ='+549 seg'!$G$26 -> 0.006363961 | I25: ='+549 seg'!$H$26 -> 0.003 | J25: ='+549 seg'!$I$26 -> 9.8130779e-18 | K25: ='+549 seg'!$J$26 -> -0.0005 | L25: ='+549 seg'!$K$26 -> 0.00070710678 | O25: ='+549 seg'!$B$27 -> 0.0095 | P25: ='+549 seg'!$C$27 -> 0.0049497475 | Q25: ='+549 seg'!$D$27 -> 0.006 | R25: ='+549 seg'!$E$27 -> 0.0028284271 | S25: ='+549 seg'!$F$27 -> 0.0115 | T25: ='+549 seg'!$G$27 -> 0.00070710678 | U25: ='+549 seg'!$H$27 -> 0.007 | V25: ='+549 seg'!$I$27 -> 0.0028284271 | W25: ='+549 seg'!$L$26 -> 0.0005 | X25: ='+549 seg'!$M$26 -> 0.0049497475
B26: 605 | C26: ='+605 seg'!$B$26 -> 0.0085 | D26: ='+605 seg'!$C$26 -> 0.00070710678 | E26: ='+605 seg'!$D$26 -> 0.0075 | F26: ='+605 seg'!$E$26 -> 0.0049497475 | G26: ='+605 seg'!$F$26 -> 0.015 | H26: ='+605 seg'!$G$26 -> 0.0056568542 | I26: ='+605 seg'!$H$26 -> 0.003 | J26: ='+605 seg'!$I$26 -> 9.8130779e-18 | K26: ='+605 seg'!$J$26 -> 0 | L26: ='+605 seg'!$K$26 -> 0.0014142136 | O26: ='+605 seg'!$B$27 -> 0.008 | P26: ='+605 seg'!$C$27 -> 0.0014142136 | Q26: ='+605 seg'!$D$27 -> 0.0055 | R26: ='+605 seg'!$E$27 -> 0.0035355339 | S26: ='+605 seg'!$F$27 -> 0.012 | T26: ='+605 seg'!$G$27 -> 0.0014142136 | U26: ='+605 seg'!$H$27 -> 0.007 | V26: ='+605 seg'!$I$27 -> 0.0028284271 | W26: ='+605 seg'!$L$26 -> 0.0005 | X26: ='+605 seg'!$M$26 -> 0.0049497475
B27: 658 | C27: ='+658 seg'!$B$26 -> 0.009 | D27: ='+658 seg'!$C$26 -> 0 | E27: ='+658 seg'!$D$26 -> 0.011 | F27: ='+658 seg'!$E$26 -> 0 | G27: ='+658 seg'!$F$26 -> 0.016 | H27: ='+658 seg'!$G$26 -> 0.0056568542 | I27: ='+658 seg'!$H$26 -> 0.0035 | J27: ='+658 seg'!$I$26 -> 0.00070710678 | K27: ='+658 seg'!$J$26 -> 0.0015 | L27: ='+658 seg'!$K$26 -> 0.0021213203 | O27: ='+658 seg'!$B$27 -> 0.008 | P27: ='+658 seg'!$C$27 -> 0.0014142136 | Q27: ='+658 seg'!$D$27 -> 0.0085 | R27: ='+658 seg'!$E$27 -> 0.0049497475 | S27: ='+658 seg'!$F$27 -> 0.013 | T27: ='+658 seg'!$G$27 -> 0.0014142136 | U27: ='+658 seg'!$H$27 -> 0.0075 | V27: ='+658 seg'!$I$27 -> 0.0035355339 | W27: ='+658 seg'!$L$26 -> 0.0005 | X27: ='+658 seg'!$M$26 -> 0.0049497475
B32: Tiempo | C32: C1 | D32: errC1 | E32: C3 | F32: errC3 | G32: C5 | H32: errC5 | I32: C7 | J32: errC7 | O32: D1 | P32: errD1 | Q32: D3 | R32: errD3 | S32: D5 | T32: errD5 | U32: D7 | V32: errD7
B33: 0 | C33: ='+0 seg'!$B$28 -> 0 | D33: ='+0 seg'!$C$28 -> 0 | E33: ='+0 seg'!$D$28 -> 0 | F33: ='+0 seg'!$E$28 -> 0 | G33: ='+0 seg'!$F$28 -> 0 | H33: ='+0 seg'!$G$28 -> 0 | I33: ='+0 seg'!$H$28 -> 0 | J33: ='+0 seg'!$I$28 -> 0 | O33: ='+0 seg'!$B$29 -> 0 | P33: ='+0 seg'!$C$29 -> 0 | Q33: ='+0 seg'!$D$29 -> 0 | R33: ='+0 seg'!$E$29 -> 0 | S33: ='+0 seg'!$F$29 -> 0 | T33: ='+0 seg'!$G$29 -> 0 | U33: ='+0 seg'!$H$29 -> 0 | V33: ='+0 seg'!$I$29 -> 0
B34: 23 | C34: ='+23 seg'!$B$28 -> 0.001 | D34: ='+23 seg'!$C$28 -> 0.0014142136 | E34: ='+23 seg'!$D$28 -> 0.0005 | F34: ='+23 seg'!$E$28 -> 0.0021213203 | G34: ='+23 seg'!$F$28 -> -0.0015 | H34: ='+23 seg'!$G$28 -> 0.0021213203 | I34: ='+23 seg'!$H$28 -> -0.0005 | J34: ='+23 seg'!$I$28 -> 0.0021213203 | O34: ='+23 seg'!$B$29 -> 0.001 | P34: ='+23 seg'!$C$29 -> 1.9626156e-17 | Q34: ='+23 seg'!$D$29 -> 0.0005 | R34: ='+23 seg'!$E$29 -> 0.00070710678 | S34: ='+23 seg'!$F$29 -> 0.0025 | T34: ='+23 seg'!$G$29 -> 0.0021213203 | U34: ='+23 seg'!$H$29 -> 0.0005 | V34: ='+23 seg'!$I$29 -> 0.0035355339
B35: 42 | C35: ='+42 seg'!$B$28 -> 0.001 | D35: ='+42 seg'!$C$28 -> 0.0014142136 | E35: ='+42 seg'!$D$28 -> 0.001 | F35: ='+42 seg'!$E$28 -> 0.0014142136 | G35: ='+42 seg'!$F$28 -> -0.002 | H35: ='+42 seg'!$G$28 -> 0.0028284271 | I35: ='+42 seg'!$H$28 -> -0.0005 | J35: ='+42 seg'!$I$28 -> 0.0035355339 | O35: ='+42 seg'!$B$29 -> 0.0015 | P35: ='+42 seg'!$C$29 -> 0.00070710678 | Q35: ='+42 seg'!$D$29 -> 0.0005 | R35: ='+42 seg'!$E$29 -> 0.00070710678 | S35: ='+42 seg'!$F$29 -> 0.003 | T35: ='+42 seg'!$G$29 -> 0.0028284271 | U35: ='+42 seg'!$H$29 -> 0.0005 | V35: ='+42 seg'!$I$29 -> 0.0021213203
B36: 61 | C36: ='+61 seg'!$B$28 -> 0.0015 | D36: ='+61 seg'!$C$28 -> 0.0021213203 | E36: ='+61 seg'!$D$28 -> 0.0025 | F36: ='+61 seg'!$E$28 -> 0.0021213203 | G36: ='+61 seg'!$F$28 -> -0.0025 | H36: ='+61 seg'!$G$28 -> 0.0049497475 | I36: ='+61 seg'!$H$28 -> -0.0005 | J36: ='+61 seg'!$I$28 -> 0.0035355339 | O36: ='+61 seg'!$B$29 -> 0.002 | P36: ='+61 seg'!$C$29 -> 1.9626156e-17 | Q36: ='+61 seg'!$D$29 -> 0.001 | R36: ='+61 seg'!$E$29 -> 0.0014142136 | S36: ='+61 seg'!$F$29 -> 0.004 | T36: ='+61 seg'!$G$29 -> 0.0028284271 | U36: ='+61 seg'!$H$29 -> 0.002 | V36: ='+61 seg'!$I$29 -> 0
B37: 81 | C37: ='+81 seg'!$B$28 -> 0.0025 | D37: ='+81 seg'!$C$28 -> 0.0021213203 | E37: ='+81 seg'!$D$28 -> 0.002 | F37: ='+81 seg'!$E$28 -> 0.0028284271 | G37: ='+81 seg'!$F$28 -> -0.003 | H37: ='+81 seg'!$G$28 -> 0.0056568542 | I37: ='+81 seg'!$H$28 -> -0.001 | J37: ='+81 seg'!$I$28 -> 0.0056568542 | O37: ='+81 seg'!$B$29 -> 0.0025 | P37: ='+81 seg'!$C$29 -> 0.00070710678 | Q37: ='+81 seg'!$D$29 -> 0.0005 | R37: ='+81 seg'!$E$29 -> 0.00070710678 | S37: ='+81 seg'!$F$29 -> 0.0045 | T37: ='+81 seg'!$G$29 -> 0.0035355339 | U37: ='+81 seg'!$H$29 -> 0.001 | V37: ='+81 seg'!$I$29 -> 0.0014142136
B38: 101 | C38: ='+101 seg'!$B$28 -> 0.003 | D38: ='+101 seg'!$C$28 -> 0.0028284271 | E38: ='+101 seg'!$D$28 -> 0.002 | F38: ='+101 seg'!$E$28 -> 0.0028284271 | G38: ='+101 seg'!$F$28 -> -0.0025 | H38: ='+101 seg'!$G$28 -> 0.006363961 | I38: ='+101 seg'!$H$28 -> -0.001 | J38: ='+101 seg'!$I$28 -> 0.0056568542 | O38: ='+101 seg'!$B$29 -> 0.0035 | P38: ='+101 seg'!$C$29 -> 0.00070710678 | Q38: ='+101 seg'!$D$29 -> 0.001 | R38: ='+101 seg'!$E$29 -> 0 | S38: ='+101 seg'!$F$29 -> 0.006 | T38: ='+101 seg'!$G$29 -> 0.0042426407 | U38: ='+101 seg'!$H$29 -> 0.0015 | V38: ='+101 seg'!$I$29 -> 0.0021213203
B39: 120 | C39: ='+120 seg'!$B$28 -> 0.0035 | D39: ='+120 seg'!$C$28 -> 0.0035355339 | E39: ='+120 seg'!$D$28 -> 0.002 | F39: ='+120 seg'!$E$28 -> 0.0028284271 | G39: ='+120 seg'!$F$28 -> -0.0025 | H39: ='+120 seg'!$G$28 -> 0.006363961 | I39: ='+120 seg'!$H$28 -> -0.0015 | J39: ='+120 seg'!$I$28 -> 0.006363961 | O39: ='+120 seg'!$B$29 -> 0.004 | P39: ='+120 seg'!$C$29 -> 1.9626156e-17 | Q39: ='+120 seg'!$D$29 -> 0.0005 | R39: ='+120 seg'!$E$29 -> 0.00070710678 | S39: ='+120 seg'!$F$29 -> 0.0065 | T39: ='+120 seg'!$G$29 -> 0.0049497475 | U39: ='+120 seg'!$H$29 -> 0.002 | V39: ='+120 seg'!$I$29 -> 0.0028284271
B40: 140 | C40: ='+140 seg'!$B$28 -> 0.0045 | D40: ='+140 seg'!$C$28 -> 0.0035355339 | E40: ='+140 seg'!$D$28 -> 0.0015 | F40: ='+140 seg'!$E$28 -> 0.0035355339 | G40: ='+140 seg'!$F$28 -> -0.002 | H40: ='+140 seg'!$G$28 -> 0.0070710678 | I40: ='+140 seg'!$H$28 -> -0.0005 | J40: ='+140 seg'!$I$28 -> 0.0077781746 | O40: ='+140 seg'!$B$29 -> 0.0055 | P40: ='+140 seg'!$C$29 -> 0.00070710678 | Q40: ='+140 seg'!$D$29 -> 0.0005 | R40: ='+140 seg'!$E$29 -> 0.00070710678 | S40: ='+140 seg'!$F$29 -> 0.007 | T40: ='+140 seg'!$G$29 -> 0.0056568542 | U40: ='+140 seg'!$H$29 -> 0.002 | V40: ='+140 seg'!$I$29 -> 0.0014142136
B41: 158 | C41: ='+158 seg'!$B$28 -> 0.0045 | D41: ='+158 seg'!$C$28 -> 0.0035355339 | E41: ='+158 seg'!$D$28 -> 0.002 | F41: ='+158 seg'!$E$28 -> 0.0042426407 | G41: ='+158 seg'!$F$28 -> -0.002 | H41: ='+158 seg'!$G$28 -> 0.0070710678 | I41: ='+158 seg'!$H$28 -> -0.0005 | J41: ='+158 seg'!$I$28 -> 0.0077781746 | O41: ='+158 seg'!$B$29 -> 0.0055 | P41: ='+158 seg'!$C$29 -> 0.00070710678 | Q41: ='+158 seg'!$D$29 -> 0.001 | R41: ='+158 seg'!$E$29 -> 0 | S41: ='+158 seg'!$F$29 -> 0.0075 | T41: ='+158 seg'!$G$29 -> 0.006363961 | U41: ='+158 seg'!$H$29 -> 0.0015 | V41: ='+158 seg'!$I$29 -> 0.0021213203
B42: 178 | C42: ='+178 seg'!$B$28 -> 0.005 | D42: ='+178 seg'!$C$28 -> 0.0042426407 | E42: ='+178 seg'!$D$28 -> 0.0015 | F42: ='+178 seg'!$E$28 -> 0.0035355339 | G42: ='+178 seg'!$F$28 -> -0.0015 | H42: ='+178 seg'!$G$28 -> 0.0077781746 | I42: ='+178 seg'!$H$28 -> -0.001 | J42: ='+178 seg'!$I$28 -> 0.0084852814 | O42: ='+178 seg'!$B$29 -> 0.0075 | P42: ='+178 seg'!$C$29 -> 0.0021213203 | Q42: ='+178 seg'!$D$29 -> 0.0005 | R42: ='+178 seg'!$E$29 -> 0.00070710678 | S42: ='+178 seg'!$F$29 -> 0.009 | T42: ='+178 seg'!$G$29 -> 0.0056568542 | U42: ='+178 seg'!$H$29 -> 0.003 | V42: ='+178 seg'!$I$29 -> 0.0028284271
B43: 198 | C43: ='+198 seg'!$B$28 -> 0.0055 | D43: ='+198 seg'!$C$28 -> 0.0049497475 | E43: ='+198 seg'!$D$28 -> 0.0015 | F43: ='+198 seg'!$E$28 -> 0.0035355339 | G43: ='+198 seg'!$F$28 -> -0.001 | H43: ='+198 seg'!$G$28 -> 0.0070710678 | I43: ='+198 seg'!$H$28 -> -0.001 | J43: ='+198 seg'!$I$28 -> 0.0084852814 | O43: ='+198 seg'!$B$29 -> 0.006 | P43: ='+198 seg'!$C$29 -> 1.9626156e-17 | Q43: ='+198 seg'!$D$29 -> 0.0005 | R43: ='+198 seg'!$E$29 -> 0.00070710678 | S43: ='+198 seg'!$F$29 -> 0.0095 | T43: ='+198 seg'!$G$29 -> 0.006363961 | U43: ='+198 seg'!$H$29 -> 0.0025 | V43: ='+198 seg'!$I$29 -> 0.0021213203
B44: 219 | C44: ='+219 seg'!$B$28 -> 0.0055 | D44: ='+219 seg'!$C$28 -> 0.0049497475 | E44: ='+219 seg'!$D$28 -> 0.0015 | F44: ='+219 seg'!$E$28 -> 0.0035355339 | G44: ='+219 seg'!$F$28 -> -0.0005 | H44: ='+219 seg'!$G$28 -> 0.0077781746 | I44: ='+219 seg'!$H$28 -> 0 | J44: ='+219 seg'!$I$28 -> 0.0084852814 | O44: ='+219 seg'!$B$29 -> 0.007 | P44: ='+219 seg'!$C$29 -> 1.9626156e-17 | Q44: ='+219 seg'!$D$29 -> 0.0005 | R44: ='+219 seg'!$E$29 -> 0.00070710678 | S44: ='+219 seg'!$F$29 -> 0.0105 | T44: ='+219 seg'!$G$29 -> 0.006363961 | U44: ='+219 seg'!$H$29 -> 0.002 | V44: ='+219 seg'!$I$29 -> 0.0014142136
B45: 238 | C45: ='+238 seg'!$B$28 -> 0.0055 | D45: ='+238 seg'!$C$28 -> 0.0049497475 | E45: ='+238 seg'!$D$28 -> 0.002 | F45: ='+238 seg'!$E$28 -> 0.0042426407 | G45: ='+238 seg'!$F$28 -> -0.0005 | H45: ='+238 seg'!$G$28 -> 0.0077781746 | I45: ='+238 seg'!$H$28 -> -0.001 | J45: ='+238 seg'!$I$28 -> 0.0084852814 | O45: ='+238 seg'!$B$29 -> 0.009 | P45: ='+238 seg'!$C$29 -> 0.0028284271 | Q45: ='+238 seg'!$D$29 -> 0.0005 | R45: ='+238 seg'!$E$29 -> 0.00070710678 | S45: ='+238 seg'!$F$29 -> 0.011 | T45: ='+238 seg'!$G$29 -> 0.0070710678 | U45: ='+238 seg'!$H$29 -> 0.002 | V45: ='+238 seg'!$I$29 -> 0
B46: 260 | C46: ='[1]+280 seg'!$B$28 -> #REF! | D46: ='+260 seg'!$C$28 -> 0.0056568542 | E46: ='+260 seg'!$D$28 -> 0.0025 | F46: ='+260 seg'!$E$28 -> 0.0035355339 | G46: ='+260 seg'!$F$28 -> -6.9388939e-18 | H46: ='+260 seg'!$G$28 -> 0.0070710678 | I46: ='+260 seg'!$H$28 -> -0.0005 | J46: ='+260 seg'!$I$28 -> 0.0091923882 | O46: ='+260 seg'!$B$29 -> 0.009 | P46: ='+260 seg'!$C$29 -> 0.0014142136 | Q46: ='+260 seg'!$D$29 -> 0.0015 | R46: ='+260 seg'!$E$29 -> 0.00070710678 | S46: ='+260 seg'!$F$29 -> 0.012 | T46: ='+260 seg'!$G$29 -> 0.0070710678 | U46: ='+260 seg'!$H$29 -> 0.0025 | V46: ='+260 seg'!$I$29 -> 0.00070710678
B47: 279 | C47: ='+279 seg'!$B$28 -> 0.0065 | D47: ='+279 seg'!$C$28 -> 0.0049497475 | E47: ='+279 seg'!$D$28 -> 0.002 | F47: ='+279 seg'!$E$28 -> 0.0042426407 | G47: ='+279 seg'!$F$28 -> 0.0005 | H47: ='+279 seg'!$G$28 -> 0.0077781746 | I47: ='+279 seg'!$H$28 -> -0.0005 | J47: ='+279 seg'!$I$28 -> 0.0091923882 | O47: ='+279 seg'!$B$29 -> 0.01 | P47: ='+279 seg'!$C$29 -> 0.0028284271 | Q47: ='+279 seg'!$D$29 -> 0.0015 | R47: ='+279 seg'!$E$29 -> 0.00070710678 | S47: ='+279 seg'!$F$29 -> 0.0135 | T47: ='+279 seg'!$G$29 -> 0.0077781746 | U47: ='+279 seg'!$H$29 -> 0.0025 | V47: ='+279 seg'!$I$29 -> 0.00070710678
...

Sheet 0-0
A1: 0 | B1: 1 | C1: 2 | D1: 3 | E1: 4 | F1: 5 | G1: 6 | H1: 7 | I1: 8 | J1: 9 | K1: 10 | L1: 11 | M1: 12
A2: * | B2: 1 | C2: 2 | D2: 3 | E2: 4 | F2: 5 | G2: 6 | H2: 7 | I2: 8 | J2: 9 | K2: 10 | L2: 11 | M2: 12
A3: A | B3: 0.109 | C3: 0.093 | D3: 0.088 | E3: 0.097 | F3: 0.134 | G3: 0.117 | H3: 0.092 | I3: 0.068 | J3: 0.054 | K3: 0.063 | L3: 0.12 | M3: 0.092
A4: B | B4: 0.129 | C4: 0.159 | D4: 0.091 | E4: 0.091 | F4: 0.152 | G4: 0.127 | H4: 0.105 | I4: 0.099 | J4: 0.064 | K4: 0.054 | L4: 0.094 | M4: 0.111
A5: C | B5: 0.132 | C5: 0.179 | D5: 0.084 | E5: 0.081 | F5: 0.103 | G5: 0.115 | H5: 0.08 | I5: 0.066 | J5: 0.094 | K5: 0.119 | L5: 0.114 | M5: 0.107
A6: D | B6: 0.165 | C6: 0.196 | D6: 0.107 | E6: 0.099 | F6: 0.127 | G6: 0.185 | H6: 0.084 | I6: 0.111 | J6: 0.083 | K6: 0.084 | L6: 0.101 | M6: 0.097
A7: E | B7: 0.128 | C7: 0.135 | D7: 0.08 | E7: 0.084 | F7: 0.109 | G7: 0.1 | H7: 0.091 | I7: 0.084 | J7: 0.068 | K7: 0.069 | L7: 0.659 | M7: 0.097
A8: F | B8: 0.108 | C8: 0.088 | D8: 0.08 | E8: 0.074 | F8: 0.096 | G8: 0.075 | H8: 0.077 | I8: 0.059 | J8: 0.05 | K8: 0.064 | L8: 0.375 | M8: 0.098
A9: G | B9: 0.143 | C9: 0.158 | D9: 0.1 | E9: 0.103 | F9: 0.113 | G9: 0.097 | H9: 0.069 | I9: 0.075 | J9: 0.116 | K9: 0.115 | L9: 0.104 | M9: 0.133
A10: H | B10: 0.2 | C10: 0.182 | D10: 0.104 | E10: 0.11 | F10: 0.199 | G10: 0.153 | H10: 0.095 | I10: 0.092 | J10: 0.096 | K10: 0.125 | L10: 0.125 | M10: 0.097

Sheet +0 seg
A1: 0 | B1: 1 | C1: 2 | D1: 3 | E1: 4 | F1: 5 | G1: 6 | H1: 7 | I1: 8 | J1: 9 | K1: 10 | L1: 11 | M1: 12
A2: * | B2: 1 | C2: 2 | D2: 3 | E2: 4 | F2: 5 | G2: 6 | H2: 7 | I2: 8 | J2: 9 | K2: 10 | L2: 11 | M2: 12
A3: A | B3: 0.098 | C3: 0.085 | D3: 0.073 | E3: 0.087 | F3: 0.147 | G3: 0.115 | H3: 0.083 | I3: 0.061 | J3: 0.051 | K3: 0.052 | L3: 0.12 | M3: 0.092
A4: B | B4: 0.128 | C4: 0.14 | D4: 0.076 | E4: 0.084 | F4: 0.146 | G4: 0.127 | H4: 0.091 | I4: 0.092 | J4: 0.062 | K4: 0.052 | L4: 0.094 | M4: 0.111
A5: C | B5: 0.141 | C5: 0.142 | D5: 0.08 | E5: 0.08 | F5: 0.101 | G5: 0.116 | H5: 0.075 | I5: 0.069 | J5: 0.094 | K5: 0.118 | L5: 0.114 | M5: 0.107
A6: D | B6: 0.171 | C6: 0.184 | D6: 0.082 | E6: 0.091 | F6: 0.117 | G6: 0.199 | H6: 0.068 | I6: 0.109 | J6: 0.083 | K6: 0.084 | L6: 0.101 | M6: 0.097
A7: E | B7: 0.134 | C7: 0.151 | D7: 0.08 | E7: 0.088 | F7: 0.112 | G7: 0.103 | H7: 0.094 | I7: 0.084 | J7: 0.069 | K7: 0.069 | L7: 0.643 | M7: 0.097
A8: F | B8: 0.116 | C8: 0.091 | D8: 0.079 | E8: 0.075 | F8: 0.096 | G8: 0.079 | H8: 0.076 | I8: 0.059 | J8: 0.051 | K8: 0.062 | L8: 0.369 | M8: 0.097
A9: G | B9: 0.151 | C9: 0.162 | D9: 0.1 | E9: 0.105 | F9: 0.116 | G9: 0.098 | H9: 0.07 | I9: 0.074 | J9: 0.116 | K9: 0.114 | L9: 0.104 | M9: 0.133
A10: H | B10: 0.219 | C10: 0.205 | D10: 0.105 | E10: 0.112 | F10: 0.226 | G10: 0.159 | H10: 0.097 | I10: 0.092 | J10: 0.096 | K10: 0.125 | L10: 0.125 | M10: 0.096
A14: * | B14: 1 | C14: 2 | D14: 3 | E14: 4 | F14: 5 | G14: 6 | H14: 7 | I14: 8 | J14: 9 | K14: 10 | L14: 11 | M14: 12
A15: A | B15: =B3 - B3 -> 0 | C15: =C3 - C3 -> 0 | D15: =D3 - D3 -> 0 | E15: =E3 - E3 -> 0 | F15: =F3 - F3 -> 0 | G15: =G3 - G3 -> 0 | H15: =H3 - H3 -> 0 | I15: =I3 - I3 -> 0 | ... M15: =M3 - M3 -> 0
A16: B | B16: =B4 - B4 -> 0 | C16: =C4 - C4 -> 0 | D16: =D4 - D4 -> 0 | E16: =E4 - E4 -> 0 | F16: =F4 - F4 -> 0 | G16: =G4 - G4 -> 0 | H16: =H4 - H4 -> 0 | I16: =I4 - I4 -> 0 | ... M16: =M4 - M4 -> 0
A17: C | B17: =B5 - B5 -> 0 | C17: =C5 - C5 -> 0 | D17: =D5 - D5 -> 0 | E17: =E5 - E5 -> 0 | F17: =F5 - F5 -> 0 | G17: =G5 - G5 -> 0 | H17: =H5 - H5 -> 0 | I17: =I5 - I5 -> 0 | ... M17: =M5 - M5 -> 0
A18: D | B18: =B6 - B6 -> 0 | C18: =C6 - C6 -> 0 | D18: =D6 - D6 -> 0 | E18: =E6 - E6 -> 0 | F18: =F6 - F6 -> 0 | G18: =G6 - G6 -> 0 | H18: =H6 - H6 -> 0 | I18: =I6 - I6 -> 0 | ... M18: =M6 - M6 -> 0
A19: E | B19: =B7 - B7 -> 0 | C19: =C7 - C7 -> 0 | D19: =D7 - D7 -> 0 | E19: =E7 - E7 -> 0 | F19: =F7 - F7 -> 0 | G19: =G7 - G7 -> 0 | H19: =H7 - H7 -> 0 | I19: =I7 - I7 -> 0 | ... M19: =M7 - M7 -> 0
A20: F | B20: =B8 - B8 -> 0 | C20: =C8 - C8 -> 0 | D20: =D8 - D8 -> 0 | E20: =E8 - E8 -> 0 | F20: =F8 - F8 -> 0 | G20: =G8 - G8 -> 0 | H20: =H8 - H8 -> 0 | I20: =I8 - I8 -> 0 | ... M20: =M8 - M8 -> 0
A21: G | B21: =B9 - B9 -> 0 | C21: =C9 - C9 -> 0 | D21: =D9 - D9 -> 0 | E21: =E9 - E9 -> 0 | F21: =F9 - F9 -> 0 | G21: =G9 - G9 -> 0 | H21: =H9 - H9 -> 0 | I21: =I9 - I9 -> 0 | ... M21: =M9 - M9 -> 0
A22: H | B22: =B10 - B10 -> 0 | C22: =C10 - C10 -> 0 | D22: =D10 - D10 -> 0 | E22: =E10 - E10 -> 0 | F22: =F10 - F10 -> 0 | G22: =G10 - G10 -> 0 | H22: =H10 - H10 -> 0 | I22: =I10 - I10 -> 0 | ... M22: =M10 - M10 -> 0
A25: * | B25: Mean 1-2 | C25: DE 1-2 | D25: Mean 3-4 | E25: DE 3-4 | F25: Mean 5-6 | G25: DE 5-6 | H25: Mean 7-8 | I25: DE 7-8 | J25: Mean 9 | K25: DE 9 | L25: Mean 10 | M25: DE 10
A26: A | B26: =AVERAGE(B15:C15) -> 0 | C26: =STDEV(B15:C15) -> 0 | D26: =AVERAGE(D15:E15) -> 0 | E26: =STDEV(D15:E15) -> 0 | F26: =AVERAGE(F15:G15) -> 0 | G26: =STDEV(F15:G15) -> 0 | H26: =AVERAGE(H15:I15) -> 0 | I26: =STDEV(H15:I15) -> 0 | J26: =AVERAGE(J15:J16) -> 0 | K26: =STDEV(J15:J16) -> 0 | L26: =AVERAGE(K15:K16) -> 0 | M26: =STDEV(K15:K16) -> 0
A27: B | B27: =AVERAGE(B16:C16) -> 0 | C27: =STDEV(B16:C16) -> 0 | D27: =AVERAGE(D16:E16) -> 0 | E27: =STDEV(D16:E16) -> 0 | F27: =AVERAGE(F16:G16) -> 0 | G27: =STDEV(F16:G16) -> 0 | H27: =AVERAGE(H16:I16) -> 0 | I27: =STDEV(H16:I16) -> 0
A28: C | B28: =AVERAGE(B17:C17) -> 0 | C28: =STDEV(B17:C17) -> 0 | D28: =AVERAGE(D17:E17) -> 0 | E28: =STDEV(D17:E17) -> 0 | F28: =AVERAGE(F17:G17) -> 0 | G28: =STDEV(F17:G17) -> 0 | H28: =AVERAGE(H17:I17) -> 0 | I28: =STDEV(H17:I17) -> 0
A29: D | B29: =AVERAGE(B18:C18) -> 0 | C29: =STDEV(B18:C18) -> 0 | D29: =AVERAGE(D18:E18) -> 0 | E29: =STDEV(D18:E18) -> 0 | F29: =AVERAGE(F18:G18) -> 0 | G29: =STDEV(F18:G18) -> 0 | H29: =AVERAGE(H18:I18) -> 0 | I29: =STDEV(H18:I18) -> 0
A30: E | B30: =AVERAGE(B19:C19) -> 0 | C30: =STDEV(B19:C19) -> 0 | D30: =AVERAGE(D19:E19) -> 0 | E30: =STDEV(D19:E19) -> 0 | F30: =AVERAGE(F19:G19) -> 0 | G30: =STDEV(F19:G19) -> 0 | H30: =AVERAGE(H19:I19) -> 0 | I30: =STDEV(H19:I19) -> 0 | J30: =AVERAGE(J19:J20) -> 0 | K30: =STDEV(J19:J20) -> 0 | L30: =AVERAGE(K19:K20) -> 0 | M30: =STDEV(K19:K20) -> 0
A31: F | B31: =AVERAGE(B20:C20) -> 0 | C31: =STDEV(B20:C20) -> 0 | D31: =AVERAGE(D20:E20) -> 0 | E31: =STDEV(D20:E20) -> 0 | F31: =AVERAGE(F20:G20) -> 0 | G31: =STDEV(F20:G20) -> 0 | H31: =AVERAGE(H20:I20) -> 0 | I31: =STDEV(H20:I20) -> 0
A32: G | B32: =AVERAGE(B21:C21) -> 0 | C32: =STDEV(B21:C21) -> 0 | D32: =AVERAGE(D21:E21) -> 0 | E32: =STDEV(D21:E21) -> 0 | F32: =AVERAGE(F21:G21) -> 0 | G32: =STDEV(F21:G21) -> 0 | H32: =AVERAGE(H21:I21) -> 0 | I32: =STDEV(H21:I21) -> 0
A33: H | B33: =AVERAGE(B22:C22) -> 0 | C33: =STDEV(B22:C22) -> 0 | D33: =AVERAGE(D22:E22) -> 0 | E33: =STDEV(D22:E22) -> 0 | F33: =AVERAGE(F22:G22) -> 0 | G33: =STDEV(F22:G22) -> 0 | H33: =AVERAGE(H22:I22) -> 0 | I33: =STDEV(H22:I22) -> 0

Sheet +23 seg
A1: 0 | B1: 1 | C1: 2 | D1: 3 | E1: 4 | F1: 5 | G1: 6 | H1: 7 | I1: 8 | J1: 9 | K1: 10 | L1: 11 | M1: 12
A2: * | B2: 1 | C2: 2 | D2: 3 | E2: 4 | F2: 5 | G2: 6 | H2: 7 | I2: 8 | J2: 9 | K2: 10 | L2: 11 | M2: 12
A3: A | B3: 0.099 | C3: 0.085 | D3: 0.074 | E3: 0.085 | F3: 0.146 | G3: 0.115 | H3: 0.082 | I3: 0.06 | J3: 0.05 | K3: 0.05 | L3: 0.12 | M3: 0.092
A4: B | B4: 0.128 | C4: 0.14 | D4: 0.078 | E4: 0.091 | F4: 0.148 | G4: 0.129 | H4: 0.092 | I4: 0.094 | J4: 0.062 | K4: 0.052 | L4: 0.093 | M4: 0.111
A5: C | B5: 0.141 | C5: 0.144 | D5: 0.082 | E5: 0.079 | F5: 0.101 | G5: 0.113 | H5: 0.076 | I5: 0.067 | J5: 0.094 | K5: 0.118 | L5: 0.114 | M5: 0.107
A6: D | B6: 0.172 | C6: 0.185 | D6: 0.083 | E6: 0.091 | F6: 0.118 | G6: 0.203 | H6: 0.071 | I6: 0.107 | J6: 0.084 | K6: 0.084 | L6: 0.101 | M6: 0.097
A7: E | B7: 0.136 | C7: 0.148 | D7: 0.081 | E7: 0.088 | F7: 0.113 | G7: 0.105 | H7: 0.094 | I7: 0.083 | J7: 0.069 | K7: 0.069 | L7: 0.649 | M7: 0.097
A8: F | B8: 0.121 | C8: 0.089 | D8: 0.078 | E8: 0.075 | F8: 0.098 | G8: 0.079 | H8: 0.076 | I8: 0.059 | J8: 0.05 | K8: 0.062 | L8: 0.37 | M8: 0.098
A9: G | B9: 0.153 | C9: 0.163 | D9: 0.101 | E9: 0.106 | F9: 0.117 | G9: 0.099 | H9: 0.07 | I9: 0.074 | J9: 0.116 | K9: 0.115 | L9: 0.104 | M9: 0.133
A10: H | B10: 0.221 | C10: 0.218 | D10: 0.105 | E10: 0.111 | F10: 0.231 | G10: 0.159 | H10: 0.097 | I10: 0.092 | J10: 0.096 | K10: 0.125 | L10: 0.125 | M10: 0.096
A14: * | B14: 1 | C14: 2 | D14: 3 | E14: 4 | F14: 5 | G14: 6 | H14: 7 | I14: 8 | J14: 9 | K14: 10 | L14: 11 | M14: 12
A15: A | B15: =B3 - '+0 seg'!$B$3 -> 0.001 | C15: =C3 - '+0 seg'!$C$3 -> 0 | D15: =D3 - '+0 seg'!$D$3 -> 0.001 | E15: =E3 - '+0 seg'!$E$3 -> -0.002 | F15: =F3 - '+0 seg'!$F$3 -> -0.001 | G15: =G3 - '+0 seg'!$G$3 -> 0 | H15: =H3 - '+0 seg'!$H$3 -> -0.001 | I15: =I3 - '+0 seg'!$I$3 -> -0.001 | J15: =J3 - '+0 seg'!$J$3 -> -0.001 | K15: =K3 - '+0 seg'!$K$3 -> -0.002 | L15: =L3 - '+0 seg'!$L$3 -> 0 | M15: =M3 - '+0 seg'!$M$3 -> 0
A16: B | B16: =B4 - '+0 seg'!$B$4 -> 0 | C16: =C4 - '+0 seg'!$C$4 -> 0 | D16: =D4 - '+0 seg'!$D$4 -> 0.002 | E16: =E4 - '+0 seg'!$E$4 -> 0.007 | F16: =F4 - '+0 seg'!$F$4 -> 0.002 | G16: =G4 - '+0 seg'!$G$4 -> 0.002 | H16: =H4 - '+0 seg'!$H$4 -> 0.001 | I16: =I4 - '+0 seg'!$I$4 -> 0.002 | J16: =J4 - '+0 seg'!$J$4 -> 0 | K16: =K4 - '+0 seg'!$K$4 -> 0 | L16: =L4 - '+0 seg'!$L$4 -> -0.001 | M16: =M4 - '+0 seg'!$M$4 -> 0
A17: C | B17: =B5 - '+0 seg'!$B$5 -> 0 | C17: =C5 - '+0 seg'!$C$5 -> 0.002 | D17: =D5 - '+0 seg'!$D$5 -> 0.002 | E17: =E5 - '+0 seg'!$E$5 -> -0.001 | F17: =F5 - '+0 seg'!$F$5 -> 0 | G17: =G5 - '+0 seg'!$G$5 -> -0.003 | H17: =H5 - '+0 seg'!$H$5 -> 0.001 | I17: =I5 - '+0 seg'!$I$5 -> -0.002 | J17: =J5 - '+0 seg'!$J$5 -> 0 | K17: =K5 - '+0 seg'!$K$5 -> 0 | L17: =L5 - '+0 seg'!$L$5 -> 0 | M17: =M5 - '+0 seg'!$M$5 -> 0
A18: D | B18: =B6 - '+0 seg'!$B$6 -> 0.001 | C18: =C6 - '+0 seg'!$C$6 -> 0.001 | D18: =D6 - '+0 seg'!$D$6 -> 0.001 | E18: =E6 - '+0 seg'!$E$6 -> 0 | F18: =F6 - '+0 seg'!$F$6 -> 0.001 | G18: =G6 - '+0 seg'!$G$6 -> 0.004 | H18: =H6 - '+0 seg'!$H$6 -> 0.003 | I18: =I6 - '+0 seg'!$I$6 -> -0.002 | J18: =J6 - '+0 seg'!$J$6 -> 0.001 | K18: =K6 - '+0 seg'!$K$6 -> 0 | L18: =L6 - '+0 seg'!$L$6 -> 0 | M18: =M6 - '+0 seg'!$M$6 -> 0
A19: E | B19: =B7 - '+0 seg'!$B$7 -> 0.002 | C19: =C7 - '+0 seg'!$C$7 -> -0.003 | D19: =D7 - '+0 seg'!$D$7 -> 0.001 | E19: =E7 - '+0 seg'!$E$7 -> 0 | F19: =F7 - '+0 seg'!$F$7 -> 0.001 | G19: =G7 - '+0 seg'!$G$7 -> 0.002 | H19: =H7 - '+0 seg'!$H$7 -> 0 | I19: =I7 - '+0 seg'!$I$7 -> -0.001 | J19: =J7 - '+0 seg'!$J$7 -> 0 | K19: =K7 - '+0 seg'!$K$7 -> 0 | L19: =L7 - '+0 seg'!$L$7 -> 0.006 | M19: =M7 - '+0 seg'!$M$7 -> 0
A20: F | B20: =B8 - '+0 seg'!$B$8 -> 0.005 | C20: =C8 - '+0 seg'!$C$8 -> -0.002 | D20: =D8 - '+0 seg'!$D$8 -> -0.001 | E20: =E8 - '+0 seg'!$E$8 -> 0 | F20: =F8 - '+0 seg'!$F$8 -> 0.002 | G20: =G8 - '+0 seg'!$G$8 -> 0 | H20: =H8 - '+0 seg'!$H$8 -> 0 | I20: =I8 - '+0 seg'!$I$8 -> 0 | J20: =J8 - '+0 seg'!$J$8 -> -0.001 | K20: =K8 - '+0 seg'!$K$8 -> 0 | L20: =L8 - '+0 seg'!$L$8 -> 0.001 | M20: =M8 - '+0 seg'!$M$8 -> 0.001
A21: G | B21: =B9 - '+0 seg'!$B$9 -> 0.002 | C21: =C9 - '+0 seg'!$C$9 -> 0.001 | D21: =D9 - '+0 seg'!$D$9 -> 0.001 | E21: =E9 - '+0 seg'!$E$9 -> 0.001 | F21: =F9 - '+0 seg'!$F$9 -> 0.001 | G21: =G9 - '+0 seg'!$G$9 -> 0.001 | H21: =H9 - '+0 seg'!$H$9 -> 0 | I21: =I9 - '+0 seg'!$I$9 -> 0 | J21: =J9 - '+0 seg'!$J$9 -> 0 | K21: =K9 - '+0 seg'!$K$9 -> 0.001 | L21: =L9 - '+0 seg'!$L$9 -> 0 | M21: =M9 - '+0 seg'!$M$9 -> 0
A22: H | B22: =B10 - '+0 seg'!$B$10 -> 0.002 | C22: =C10 - '+0 seg'!$C$10 -> 0.013 | D22: =D10 - '+0 seg'!$D$10 -> 0 | E22: =E10 - '+0 seg'!$E$10 -> -0.001 | F22: =F10 - '+0 seg'!$F$10 -> 0.005 | G22: =G10 - '+0 seg'!$G$10 -> 0 | H22: =H10 - '+0 seg'!$H$10 -> 0 | I22: =I10 - '+0 seg'!$I$10 -> 0 | J22: =J10 - '+0 seg'!$J$10 -> 0 | K22: =K10 - '+0 seg'!$K$10 -> 0 | L22: =L10 - '+0 seg'!$L$10 -> 0 | M22: =M10 - '+0 seg'!$M$10 -> 0
A25: * | B25: Mean 1-2 | C25: DE 1-2 | D25: Mean 3-4 | E25: DE 3-4 | F25: Mean 5-6 | G25: DE 5-6 | H25: Mean 7-8 | I25: DE 7-8 | J25: Mean 9 | K25: DE 9 | L25: Mean 10 | M25: DE 10
A26: A | B26: =AVERAGE(B15:C15) -> 0.0005 | C26: =STDEV(B15:C15) -> 0.00070710678 | D26: =AVERAGE(D15:E15) -> -0.0005 | E26: =STDEV(D15:E15) -> 0.0021213203 | F26: =AVERAGE(F15:G15) -> -0.0005 | G26: =STDEV(F15:G15) -> 0.00070710678 | H26: =AVERAGE(H15:I15) -> -0.001 | I26: =STDEV(H15:I15) -> 0 | J26: =AVERAGE(J15:J16) -> -0.0005 | K26: =STDEV(J15:J16) -> 0.00070710678 | L26: =AVERAGE(K15:K16) -> -0.001 | M26: =STDEV(K15:K16) -> 0.0014142136
A27: B | B27: =AVERAGE(B16:C16) -> 0 | C27: =STDEV(B16:C16) -> 0 | D27: =AVERAGE(D16:E16) -> 0.0045 | E27: =STDEV(D16:E16) -> 0.0035355339 | F27: =AVERAGE(F16:G16) -> 0.002 | G27: =STDEV(F16:G16) -> 0 | H27: =AVERAGE(H16:I16) -> 0.0015 | I27: =STDEV(H16:I16) -> 0.00070710678
A28: C | B28: =AVERAGE(B17:C17) -> 0.001 | C28: =STDEV(B17:C17) -> 0.0014142136 | D28: =AVERAGE(D17:E17) -> 0.0005 | E28: =STDEV(D17:E17) -> 0.0021213203 | F28: =AVERAGE(F17:G17) -> -0.0015 | G28: =STDEV(F17:G17) -> 0.0021213203 | H28: =AVERAGE(H17:I17) -> -0.0005 | I28: =STDEV(H17:I17) -> 0.0021213203
A29: D | B29: =AVERAGE(B18:C18) -> 0.001 | C29: =STDEV(B18:C18) -> 1.9626156e-17 | D29: =AVERAGE(D18:E18) -> 0.0005 | E29: =STDEV(D18:E18) -> 0.00070710678 | F29: =AVERAGE(F18:G18) -> 0.0025 | G29: =STDEV(F18:G18) -> 0.0021213203 | H29: =AVERAGE(H18:I18) -> 0.0005 | I29: =STDEV(H18:I18) -> 0.0035355339
A30: E | B30: =AVERAGE(B19:C19) -> -0.0005 | C30: =STDEV(B19:C19) -> 0.0035355339 | D30: =AVERAGE(D19:E19) -> 0.0005 | E30: =STDEV(D19:E19) -> 0.00070710678 | F30: =AVERAGE(F19:G19) -> 0.0015 | G30: =STDEV(F19:G19) -> 0.00070710678 | H30: =AVERAGE(H19:I19) -> -0.0005 | I30: =STDEV(H19:I19) -> 0.00070710678 | J30: =AVERAGE(J19:J20) -> -0.0005 | K30: =STDEV(J19:J20) -> 0.00070710678 | L30: =AVERAGE(K19:K20) -> 0 | M30: =STDEV(K19:K20) -> 0
A31: F | B31: =AVERAGE(B20:C20) -> 0.0015 | C31: =STDEV(B20:C20) -> 0.0049497475 | D31: =AVERAGE(D20:E20) -> -0.0005 | E31: =STDEV(D20:E20) -> 0.00070710678 | F31: =AVERAGE(F20:G20) -> 0.001 | G31: =STDEV(F20:G20) -> 0.0014142136 | H31: =AVERAGE(H20:I20) -> 0 | I31: =STDEV(H20:I20) -> 0
A32: G | B32: =AVERAGE(B21:C21) -> 0.0015 | C32: =STDEV(B21:C21) -> 0.00070710678 | D32: =AVERAGE(D21:E21) -> 0.001 | E32: =STDEV(D21:E21) -> 0 | F32: =AVERAGE(F21:G21) -> 0.001 | G32: =STDEV(F21:G21) -> 0 | H32: =AVERAGE(H21:I21) -> 0 | I32: =STDEV(H21:I21) -> 0
A33: H | B33: =AVERAGE(B22:C22) -> 0.0075 | C33: =STDEV(B22:C22) -> 0.0077781746 | D33: =AVERAGE(D22:E22) -> -0.0005 | E33: =STDEV(D22:E22) -> 0.00070710678 | F33: =AVERAGE(F22:G22) -> 0.0025 | G33: =STDEV(F22:G22) -> 0.0035355339 | H33: =AVERAGE(H22:I22) -> 0 | I33: =STDEV(H22:I22) -> 0

Sheet +42 seg
A1: 0 | B1: 1 | C1: 2 | D1: 3 | E1: 4 | F1: 5 | G1: 6 | H1: 7 | I1: 8 | J1: 9 | K1: 10 | L1: 11 | M1: 12
A2: * | B2: 1 | C2: 2 | D2: 3 | E2: 4 | F2: 5 | G2: 6 | H2: 7 | I2: 8 | J2: 9 | K2: 10 | L2: 11 | M2: 12
A3: A | B3: 0.099 | C3: 0.085 | D3: 0.075 | E3: 0.09 | F3: 0.142 | G3: 0.116 | H3: 0.082 | I3: 0.061 | J3: 0.05 | K3: 0.048 | L3: 0.12 | M3: 0.092
A4: B | B4: 0.128 | C4: 0.14 | D4: 0.079 | E4: 0.092 | F4: 0.148 | G4: 0.128 | H4: 0.094 | I4: 0.095 | J4: 0.062 | K4: 0.052 | L4: 0.093 | M4: 0.111
A5: C | B5: 0.141 | C5: 0.144 | D5: 0.082 | E5: 0.08 | F5: 0.101 | G5: 0.112 | H5: 0.077 | I5: 0.066 | J5: 0.094 | K5: 0.118 | L5: 0.114 | M5: 0.107
A6: D | B6: 0.173 | C6: 0.185 | D6: 0.083 | E6: 0.091 | F6: 0.118 | G6: 0.204 | H6: 0.07 | I6: 0.108 | J6: 0.083 | K6: 0.084 | L6: 0.101 | M6: 0.097
A7: E | B7: 0.136 | C7: 0.149 | D7: 0.081 | E7: 0.089 | F7: 0.114 | G7: 0.106 | H7: 0.097 | I7: 0.082 | J7: 0.069 | K7: 0.069 | L7: 0.649 | M7: 0.097
A8: F | B8: 0.123 | C8: 0.091 | D8: 0.078 | E8: 0.075 | F8: 0.098 | G8: 0.08 | H8: 0.078 | I8: 0.058 | J8: 0.05 | K8: 0.061 | L8: 0.37 | M8: 0.098
A9: G | B9: 0.152 | C9: 0.164 | D9: 0.101 | E9: 0.106 | F9: 0.117 | G9: 0.101 | H9: 0.07 | I9: 0.074 | J9: 0.116 | K9: 0.115 | L9: 0.104 | M9: 0.133
A10: H | B10: 0.21 | C10: 0.226 | D10: 0.105 | E10: 0.111 | F10: 0.234 | G10: 0.16 | H10: 0.097 | I10: 0.092 | J10: 0.096 | K10: 0.125 | L10: 0.125 | M10: 0.096
A14: * | B14: 1 | C14: 2 | D14: 3 | E14: 4 | F14: 5 | G14: 6 | H14: 7 | I14: 8 | J14: 9 | K14: 10 | L14: 11 | M14: 12
A15: A | B15: =B3 - '+0 seg'!$B$3 -> 0.001 | C15: =C3 - '+0 seg'!$C$3 -> 0 | D15: =D3 - '+0 seg'!$D$3 -> 0.002 | E15: =E3 - '+0 seg'!$E$3 -> 0.003 | F15: =F3 - '+0 seg'!$F$3 -> -0.005 | G15: =G3 - '+0 seg'!$G$3 -> 0.001 | H15: =H3 - '+0 seg'!$H$3 -> -0.001 | I15: =I3 - '+0 seg'!$I$3 -> 0 | J15: =J3 - '+0 seg'!$J$3 -> -0.001 | K15: =K3 - '+0 seg'!$K$3 -> -0.004 | L15: =L3 - '+0 seg'!$L$3 -> 0 | M15: =M3 - '+0 seg'!$M$3 -> 0
A16: B | B16: =B4 - '+0 seg'!$B$4 -> 0 | C16: =C4 - '+0 seg'!$C$4 -> 0 | D16: =D4 - '+0 seg'!$D$4 -> 0.003 | E16: =E4 - '+0 seg'!$E$4 -> 0.008 | F16: =F4 - '+0 seg'!$F$4 -> 0.002 | G16: =G4 - '+0 seg'!$G$4 -> 0.001 | H16: =H4 - '+0 seg'!$H$4 -> 0.003 | I16: =I4 - '+0 seg'!$I$4 -> 0.003 | J16: =J4 - '+0 seg'!$J$4 -> 0 | K16: =K4 - '+0 seg'!$K$4 -> 0 | L16: =L4 - '+0 seg'!$L$4 -> -0.001 | M16: =M4 - '+0 seg'!$M$4 -> 0
A17: C | B17: =B5 - '+0 seg'!$B$5 -> 0 | C17: =C5 - '+0 seg'!$C$5 -> 0.002 | D17: =D5 - '+0 seg'!$D$5 -> 0.002 | E17: =E5 - '+0 seg'!$E$5 -> 0 | F17: =F5 - '+0 seg'!$F$5 -> 0 | G17: =G5 - '+0 seg'!$G$5 -> -0.004 | H17: =H5 - '+0 seg'!$H$5 -> 0.002 | I17: =I5 - '+0 seg'!$I$5 -> -0.003 | J17: =J5 - '+0 seg'!$J$5 -> 0 | K17: =K5 - '+0 seg'!$K$5 -> 0 | L17: =L5 - '+0 seg'!$L$5 -> 0 | M17: =M5 - '+0 seg'!$M$5 -> 0
A18: D | B18: =B6 - '+0 seg'!$B$6 -> 0.002 | C18: =C6 - '+0 seg'!$C$6 -> 0.001 | D18: =D6 - '+0 seg'!$D$6 -> 0.001 | E18: =E6 - '+0 seg'!$E$6 -> 0 | F18: =F6 - '+0 seg'!$F$6 -> 0.001 | G18: =G6 - '+0 seg'!$G$6 -> 0.005 | H18: =H6 - '+0 seg'!$H$6 -> 0.002 | I18: =I6 - '+0 seg'!$I$6 -> -0.001 | J18: =J6 - '+0 seg'!$J$6 -> 0 | K18: =K6 - '+0 seg'!$K$6 -> 0 | L18: =L6 - '+0 seg'!$L$6 -> 0 | M18: =M6 - '+0 seg'!$M$6 -> 0
A19: E | B19: =B7 - '+0 seg'!$B$7 -> 0.002 | C19: =C7 - '+0 seg'!$C$7 -> -0.002 | D19: =D7 - '+0 seg'!$D$7 -> 0.001 | E19: =E7 - '+0 seg'!$E$7 -> 0.001 | F19: =F7 - '+0 seg'!$F$7 -> 0.002 | G19: =G7 - '+0 seg'!$G$7 -> 0.003 | H19: =H7 - '+0 seg'!$H$7 -> 0.003 | I19: =I7 - '+0 seg'!$I$7 -> -0.002 | J19: =J7 - '+0 seg'!$J$7 -> 0 | K19: =K7 - '+0 seg'!$K$7 -> 0 | L19: =L7 - '+0 seg'!$L$7 -> 0.006 | M19: =M7 - '+0 seg'!$M$7 -> 0
A20: F | B20: =B8 - '+0 seg'!$B$8 -> 0.007 | C20: =C8 - '+0 seg'!$C$8 -> 0 | D20: =D8 - '+0 seg'!$D$8 -> -0.001 | E20: =E8 - '+0 seg'!$E$8 -> 0 | F20: =F8 - '+0 seg'!$F$8 -> 0.002 | G20: =G8 - '+0 seg'!$G$8 -> 0.001 | H20: =H8 - '+0 seg'!$H$8 -> 0.002 | I20: =I8 - '+0 seg'!$I$8 -> -0.001 | J20: =J8 - '+0 seg'!$J$8 -> -0.001 | K20: =K8 - '+0 seg'!$K$8 -> -0.001 | L20: =L8 - '+0 seg'!$L$8 -> 0.001 | M20: =M8 - '+0 seg'!$M$8 -> 0.001
A21: G | B21: =B9 - '+0 seg'!$B$9 -> 0.001 | C21: =C9 - '+0 seg'!$C$9 -> 0.002 | D21: =D9 - '+0 seg'!$D$9 -> 0.001 | E21: =E9 - '+0 seg'!$E$9 -> 0.001 | F21: =F9 - '+0 seg'!$F$9 -> 0.001 | G21: =G9 - '+0 seg'!$G$9 -> 0.003 | H21: =H9 - '+0 seg'!$H$9 -> 0 | I21: =I9 - '+0 seg'!$I$9 -> 0 | J21: =J9 - '+0 seg'!$J$9 -> 0 | K21: =K9 - '+0 seg'!$K$9 -> 0.001 | L21: =L9 - '+0 seg'!$L$9 -> 0 | M21: =M9 - '+0 seg'!$M$9 -> 0
A22: H | B22: =B10 - '+0 seg'!$B$10 -> -0.009 | C22: =C10 - '+0 seg'!$C$10 -> 0.021 | D22: =D10 - '+0 seg'!$D$10 -> 0 | E22: =E10 - '+0 seg'!$E$10 -> -0.001 | F22: =F10 - '+0 seg'!$F$10 -> 0.008 | G22: =G10 - '+0 seg'!$G$10 -> 0.001 | H22: =H10 - '+0 seg'!$H$10 -> 0 | I22: =I10 - '+0 seg'!$I$10 -> 0 | J22: =J10 - '+0 seg'!$J$10 -> 0 | K22: =K10 - '+0 seg'!$K$10 -> 0 | L22: =L10 - '+0 seg'!$L$10 -> 0 | M22: =M10 - '+0 seg'!$M$10 -> 0
A25: * | B25: Mean 1-2 | C25: DE 1-2 | D25: Mean 3-4 | E25: DE 3-4 | F25: Mean 5-6 | G25: DE 5-6 | H25: Mean 7-8 | I25: DE 7-8 | J25: Mean 9 | K25: DE 9 | L25: Mean 10 | M25: DE 10
A26: A | B26: =AVERAGE(B15:C15) -> 0.0005 | C26: =STDEV(B15:C15) -> 0.00070710678 | D26: =AVERAGE(D15:E15) -> 0.0025 | E26: =STDEV(D15:E15) -> 0.00070710678 | F26: =AVERAGE(F15:G15) -> -0.002 | G26: =STDEV(F15:G15) -> 0.0042426407 | H26: =AVERAGE(H15:I15) -> -0.0005 | I26: =STDEV(H15:I15) -> 0.00070710678 | J26: =AVERAGE(J15:J16) -> -0.0005 | K26: =STDEV(J15:J16) -> 0.00070710678 | L26: =AVERAGE(K15:K16) -> -0.002 | M26: =STDEV(K15:K16) -> 0.0028284271
A27: B | B27: =AVERAGE(B16:C16) -> 0 | C27: =STDEV(B16:C16) -> 0 | D27: =AVERAGE(D16:E16) -> 0.0055 | E27: =STDEV(D16:E16) -> 0.0035355339 | F27: =AVERAGE(F16:G16) -> 0.0015 | G27: =STDEV(F16:G16) -> 0.00070710678 | H27: =AVERAGE(H16:I16) -> 0.003 | I27: =STDEV(H16:I16) -> 0
A28: C | B28: =AVERAGE(B17:C17) -> 0.001 | C28: =STDEV(B17:C17) -> 0.0014142136 | D28: =AVERAGE(D17:E17) -> 0.001 | E28: =STDEV(D17:E17) -> 0.0014142136 | F28: =AVERAGE(F17:G17) -> -0.002 | G28: =STDEV(F17:G17) -> 0.0028284271 | H28: =AVERAGE(H17:I17) -> -0.0005 | I28: =STDEV(H17:I17) -> 0.0035355339
A29: D | B29: =AVERAGE(B18:C18) -> 0.0015 | C29: =STDEV(B18:C18) -> 0.00070710678 | D29: =AVERAGE(D18:E18) -> 0.0005 | E29: =STDEV(D18:E18) -> 0.00070710678 | F29: =AVERAGE(F18:G18) -> 0.003 | G29: =STDEV(F18:G18) -> 0.0028284271 | H29: =AVERAGE(H18:I18) -> 0.0005 | I29: =STDEV(H18:I18) -> 0.0021213203
A30: E | B30: =AVERAGE(B19:C19) -> 0 | C30: =STDEV(B19:C19) -> 0.0028284271 | D30: =AVERAGE(D19:E19) -> 0.001 | E30: =STDEV(D19:E19) -> 0 | F30: =AVERAGE(F19:G19) -> 0.0025 | G30: =STDEV(F19:G19) -> 0.00070710678 | H30: =AVERAGE(H19:I19) -> 0.0005 | I30: =STDEV(H19:I19) -> 0.0035355339 | J30: =AVERAGE(J19:J20) -> -0.0005 | K30: =STDEV(J19:J20) -> 0.00070710678 | L30: =AVERAGE(K19:K20) -> -0.0005 | M30: =STDEV(K19:K20) -> 0.00070710678
A31: F | B31: =AVERAGE(B20:C20) -> 0.0035 | C31: =STDEV(B20:C20) -> 0.0049497475 | D31: =AVERAGE(D20:E20) -> -0.0005 | E31: =STDEV(D20:E20) -> 0.00070710678 | F31: =AVERAGE(F20:G20) -> 0.0015 | G31: =STDEV(F20:G20) -> 0.00070710678 | H31: =AVERAGE(H20:I20) -> 0.0005 | I31: =STDEV(H20:I20) -> 0.0021213203
A32: G | B32: =AVERAGE(B21:C21) -> 0.0015 | C32: =STDEV(B21:C21) -> 0.00070710678 | D32: =AVERAGE(D21:E21) -> 0.001 | E32: =STDEV(D21:E21) -> 0 | F32: =AVERAGE(F21:G21) -> 0.002 | G32: =STDEV(F21:G21) -> 0.0014142136 | H32: =AVERAGE(H21:I21) -> 0 | I32: =STDEV(H21:I21) -> 0
A33: H | B33: =AVERAGE(B22:C22) -> 0.006 | C33: =STDEV(B22:C22) -> 0.021213203 | D33: =AVERAGE(D22:E22) -> -0.0005 | E33: =STDEV(D22:E22) -> 0.00070710678 | F33: =AVERAGE(F22:G22) -> 0.0045 | G33: =STDEV(F22:G22) -> 0.0049497475 | H33: =AVERAGE(H22:I22) -> 0 | I33: =STDEV(H22:I22) -> 0

Sheet +61 seg
A1: 0 | B1: 1 | C1: 2 | D1: 3 | E1: 4 | F1: 5 | G1: 6 | H1: 7 | I1: 8 | J1: 9 | K1: 10 | L1: 11 | M1: 12
A2: * | B2: 1 | C2: 2 | D2: 3 | E2: 4 | F2: 5 | G2: 6 | H2: 7 | I2: 8 | J2: 9 | K2: 10 | L2: 11 | M2: 12
A3: A | B3: 0.098 | C3: 0.085 | D3: 0.075 | E3: 0.089 | F3: 0.143 | G3: 0.116 | H3: 0.083 | I3: 0.061 | J3: 0.051 | K3: 0.048 | L3: 0.12 | M3: 0.092
A4: B | B4: 0.128 | C4: 0.14 | D4: 0.079 | E4: 0.088 | F4: 0.15 | G4: 0.129 | H4: 0.095 | I4: 0.095 | J4: 0.062 | K4: 0.053 | L4: 0.093 | M4: 0.111
A5: C | B5: 0.141 | C5: 0.145 | D5: 0.084 | E5: 0.081 | F5: 0.102 | G5: 0.11 | H5: 0.077 | I5: 0.066 | J5: 0.094 | K5: 0.118 | L5: 0.114 | M5: 0.107
A6: D | B6: 0.173 | C6: 0.186 | D6: 0.084 | E6: 0.091 | F6: 0.119 | G6: 0.205 | H6: 0.07 | I6: 0.111 | J6: 0.083 | K6: 0.084 | L6: 0.101 | M6: 0.097
A7: E | B7: 0.135 | C7: 0.148 | D7: 0.083 | E7: 0.089 | F7: 0.116 | G7: 0.108 | H7: 0.096 | I7: 0.082 | J7: 0.069 | K7: 0.069 | L7: 0.648 | M7: 0.097
A8: F | B8: 0.122 | C8: 0.091 | D8: 0.077 | E8: 0.075 | F8: 0.098 | G8: 0.08 | H8: 0.077 | I8: 0.058 | J8: 0.05 | K8: 0.062 | L8: 0.369 | M8: 0.098
A9: G | B9: 0.152 | C9: 0.165 | D9: 0.102 | E9: 0.106 | F9: 0.118 | G9: 0.101 | H9: 0.07 | I9: 0.074 | J9: 0.116 | K9: 0.115 | L9: 0.104 | M9: 0.133
A10: H | B10: 0.207 | C10: 0.223 | D10: 0.104 | E10: 0.111 | F10: 0.236 | G10: 0.161 | H10: 0.097 | I10: 0.093 | J10: 0.096 | K10: 0.125 | L10: 0.125 | M10: 0.096
A14: * | B14: 1 | C14: 2 | D14: 3 | E14: 4 | F14: 5 | G14: 6 | H14: 7 | I14: 8 | J14: 9 | K14: 10 | L14: 11 | M14: 12
A15: A | B15: =B3 - '+0 seg'!$B$3 -> 0 | C15: =C3 - '+0 seg'!$C$3 -> 0 | D15: =D3 - '+0 seg'!$D$3 -> 0.002 | E15: =E3 - '+0 seg'!$E$3 -> 0.002 | F15: =F3 - '+0 seg'!$F$3 -> -0.004 | G15: =G3 - '+0 seg'!$G$3 -> 0.001 | H15: =H3 - '+0 seg'!$H$3 -> 0 | I15: =I3 - '+0 seg'!$I$3 -> 0 | J15: =J3 - '+0 seg'!$J$3 -> 0 | K15: =K3 - '+0 seg'!$K$3 -> -0.004 | L15: =L3 - '+0 seg'!$L$3 -> 0 | M15: =M3 - '+0 seg'!$M$3 -> 0
A16: B | B16: =B4 - '+0 seg'!$B$4 -> 0 | C16: =C4 - '+0 seg'!$C$4 -> 0 | D16: =D4 - '+0 seg'!$D$4 -> 0.003 | E16: =E4 - '+0 seg'!$E$4 -> 0.004 | F16: =F4 - '+0 seg'!$F$4 -> 0.004 | G16: =G4 - '+0 seg'!$G$4 -> 0.002 | H16: =H4 - '+0 seg'!$H$4 -> 0.004 | I16: =I4 - '+0 seg'!$I$4 -> 0.003 | J16: =J4 - '+0 seg'!$J$4 -> 0 | K16: =K4 - '+0 seg'!$K$4 -> 0.001 | L16: =L4 - '+0 seg'!$L$4 -> -0.001 | M16: =M4 - '+0 seg'!$M$4 -> 0
A17: C | B17: =B5 - '+0 seg'!$B$5 -> 0 | C17: =C5 - '+0 seg'!$C$5 -> 0.003 | D17: =D5 - '+0 seg'!$D$5 -> 0.004 | E17: =E5 - '+0 seg'!$E$5 -> 0.001 | F17: =F5 - '+0 seg'!$F$5 -> 0.001 | G17: =G5 - '+0 seg'!$G$5 -> -0.006 | H17: =H5 - '+0 seg'!$H$5 -> 0.002 | I17: =I5 - '+0 seg'!$I$5 -> -0.003 | J17: =J5 - '+0 seg'!$J$5 -> 0 | K17: =K5 - '+0 seg'!$K$5 -> 0 | L17: =L5 - '+0 seg'!$L$5 -> 0 | M17: =M5 - '+0 seg'!$M$5 -> 0
A18: D | B18: =B6 - '+0 seg'!$B$6 -> 0.002 | C18: =C6 - '+0 seg'!$C$6 -> 0.002 | D18: =D6 - '+0 seg'!$D$6 -> 0.002 | E18: =E6 - '+0 seg'!$E$6 -> 0 | F18: =F6 - '+0 seg'!$F$6 -> 0.002 | G18: =G6 - '+0 seg'!$G$6 -> 0.006 | H18: =H6 - '+0 seg'!$H$6 -> 0.002 | I18: =I6 - '+0 seg'!$I$6 -> 0.002 | J18: =J6 - '+0 seg'!$J$6 -> 0 | K18: =K6 - '+0 seg'!$K$6 -> 0 | L18: =L6 - '+0 seg'!$L$6 -> 0 | M18: =M6 - '+0 seg'!$M$6 -> 0
A19: E | B19: =B7 - '+0 seg'!$B$7 -> 0.001 | C19: =C7 - '+0 seg'!$C$7 -> -0.003 | D19: =D7 - '+0 seg'!$D$7 -> 0.003 | E19: =E7 - '+0 seg'!$E$7 -> 0.001 | F19: =F7 - '+0 seg'!$F$7 -> 0.004 | G19: =G7 - '+0 seg'!$G$7 -> 0.005 | H19: =H7 - '+0 seg'!$H$7 -> 0.002 | I19: =I7 - '+0 seg'!$I$7 -> -0.002 | J19: =J7 - '+0 seg'!$J$7 -> 0 | K19: =K7 - '+0 seg'!$K$7 -> 0 | L19: =L7 - '+0 seg'!$L$7 -> 0.005 | M19: =M7 - '+0 seg'!$M$7 -> 0
A20: F | B20: =B8 - '+0 seg'!$B$8 -> 0.006 | C20: =C8 - '+0 seg'!$C$8 -> 0 | D20: =D8 - '+0 seg'!$D$8 -> -0.002 | E20: =E8 - '+0 seg'!$E$8 -> 0 | F20: =F8 - '+0 seg'!$F$8 -> 0.002 | G20: =G8 - '+0 seg'!$G$8 -> 0.001 | H20: =H8 - '+0 seg'!$H$8 -> 0.001 | I20: =I8 - '+0 seg'!$I$8 -> -0.001 | J20: =J8 - '+0 seg'!$J$8 -> -0.001 | K20: =K8 - '+0 seg'!$K$8 -> 0 | L20: =L8 - '+0 seg'!$L$8 -> 0 | M20: =M8 - '+0 seg'!$M$8 -> 0.001
A21: G | B21: =B9 - '+0 seg'!$B$9 -> 0.001 | C21: =C9 - '+0 seg'!$C$9 -> 0.003 | D21: =D9 - '+0 seg'!$D$9 -> 0.002 | E21: =E9 - '+0 seg'!$E$9 -> 0.001 | F21: =F9 - '+0 seg'!$F$9 -> 0.002 | G21: =G9 - '+0 seg'!$G$9 -> 0.003 | H21: =H9 - '+0 seg'!$H$9 -> 0 | I21: =I9 - '+0 seg'!$I$9 -> 0 | J21: =J9 - '+0 seg'!$J$9 -> 0 | K21: =K9 - '+0 seg'!$K$9 -> 0.001 | L21: =L9 - '+0 seg'!$L$9 -> 0 | M21: =M9 - '+0 seg'!$M$9 -> 0
A22: H | B22: =B10 - '+0 seg'!$B$10 -> -0.012 | C22: =C10 - '+0 seg'!$C$10 -> 0.018 | D22: =D10 - '+0 seg'!$D$10 -> -0.001 | E22: =E10 - '+0 seg'!$E$10 -> -0.001 | F22: =F10 - '+0 seg'!$F$10 -> 0.01 | G22: =G10 - '+0 seg'!$G$10 -> 0.002 | H22: =H10 - '+0 seg'!$H$10 -> 0 | I22: =I10 - '+0 seg'!$I$10 -> 0.001 | J22: =J10 - '+0 seg'!$J$10 -> 0 | K22: =K10 - '+0 seg'!$K$10 -> 0 | L22: =L10 - '+0 seg'!$L$10 -> 0 | M22: =M10 - '+0 seg'!$M$10 -> 0
A25: * | B25: Mean 1-2 | C25: DE 1-2 | D25: Mean 3-4 | E25: DE 3-4 | F25: Mean 5-6 | G25: DE 5-6 | H25: Mean 7-8 | I25: DE 7-8 | J25: Mean 9 | K25: DE 9 | L25: Mean 10 | M25: DE 10
A26: A | B26: =AVERAGE(B15:C15) -> 0 | C26: =STDEV(B15:C15) -> 0 | D26: =AVERAGE(D15:E15) -> 0.002 | E26: =STDEV(D15:E15) -> 0 | F26: =AVERAGE(F15:G15) -> -0.0015 | G26: =STDEV(F15:G15) -> 0.0035355339 | H26: =AVERAGE(H15:I15) -> 0 | I26: =STDEV(H15:I15) -> 0 | J26: =AVERAGE(J15:J16) -> 0 | K26: =STDEV(J15:J16) -> 0 | L26: =AVERAGE(K15:K16) -> -0.0015 | M26: =STDEV(K15:K16) -> 0.0035355339
A27: B | B27: =AVERAGE(B16:C16) -> 0 | C27: =STDEV(B16:C16) -> 0 | D27: =AVERAGE(D16:E16) -> 0.0035 | E27: =STDEV(D16:E16) -> 0.00070710678 | F27: =AVERAGE(F16:G16) -> 0.003 | G27: =STDEV(F16:G16) -> 0.0014142136 | H27: =AVERAGE(H16:I16) -> 0.0035 | I27: =STDEV(H16:I16) -> 0.00070710678
